Workbook

Sheet Datos solicitud
B3: DATOS RELATIVOS A LA SOLICITUD DE INFORME MOTIVADO
B5: RAZÓN SOCIAL ENTIDAD: | E5: Festina Lotus, S.A.
B7: NIF ENTIDAD SOLICITANTE: | E7: A08663684
B9: TÍTULO DEL PROYECTO: | E9: NUEVA APLICACION TECNOLOGICA PARA MEJORAR LA GESTION DE VENTAS Y RECURSOS EMPRESARIALES
B12: EJERCICIO FISCAL DE SOLICITUD (dd/mm/aaaa): | E12: FECHA INICIO: | F12: 45292 | G12: FECHA FIN: | H12: 45657
B14: AÑO DE INICIO DEL PROYECTO: | E14: 2023 | G14: ACRÓNIMO: | H14: APPTECNO23
B16: Nº DE EXPEDIENTE (INFORME MOTIVADO):

Sheet Instrucciones
B3: INSTRUCCIONES
B5: 1- Debe entregarse un único documento PDF que incluya, por lo menos, todas las Hojas del Formulario donde se hayan introducido datos. Las Hojas deben presentarse en el orden establecido en esta plantilla. La primera página del PDF debe ser la Hoja 'Datos solicitud' con los datos de la solicitante. No agregue al documento PDF resultante otras páginas diferentes a las expuestas en este Formulario. No es necesario que la presente Hoja con instrucciones se muestre en el PDF resultante que ha de entregarse.
B7: 2- Las Hojas 'I+D' e 'IT' deberán ser incluidas en función de la calificación que haya sido consignada en las Hojas restantes. La Hoja 'TOTAL' debe ser incluida obligatoriamente en todos los casos.
B9: 3- Para solicitudes tipo 'A' es obligatorio incluir la Hoja con la “Ficha de desviaciones” y describir aquellas desviaciones que sean superiores al 20%.
B11: 4- Para solicitudes tipo 'A' es obligatorio incluir la Hoja con el Listado de documentos justificativos de los gastos correctamente cumplimentado en cada fila/celda.
B13: 5- En cada Hoja, deben añadirse tantas filas como se consideren necesarias. En cada fila añadida deben reproducirse las Fórmulas existentes en la Hoja para que se efectúen los cálculos automáticos.
B15: 6- No deben realizarse modificaciones en las Fórmulas. Debe respetarse la estructura general del Formulario. No elimine las Filas que no utilice, deje en blanco las que no considere oportunas.
B17: 7- Los gastos reflejados en cada una de las Hojas deben guardar correspondencia entre sí.
B19: 8- Los gastos mostrados en el presente Formulario deben coincidir con los 'Gastos Presentados/Presupuestados' que se muestren en el 'Informe Técnico de la EC' y en el 'Informe Técnico XSIG (XML)' que deben acompañar a su Solicitud. Es decir, deben mostrarse los valores de los gastos presentados a Certificación, no los gastos resultantes de dicha Certificación (salvo que sean idénticos).
B21: 9- A su vez, los gastos mostrados deben coincidir con los 'Gastos Presentados/Presupuestados' que se muestren en la Memoria Técnica/Económica.
B23: 10- Deben seguirse las instrucciones concretas marcadas en fuente roja que se exponen al inicio de algunas de las Hojas del Formulario.
B25: 11- Si el proyecto tiene una duración mayor de 6 anualidades, deberán entregarse dos o más Formularios. Uno que abarque las anualidades 1-6, otro 7-12, y así sucesivamente. En estos casos, en cada Formulario deberá indicarse como 'Año de Inicio' el primero de los años empleados en ese rango. En cualquier caso, no se deben añadir/eliminar columnas.
... B39: 18- Al transformar el documento en PDF se debe asegurar que el contenido incluido en las celdas no se oculta en la transformación, ya que, en dicho caso, el documento no se considerará válido.

Sheet Personal
B4: 2.1 PERSONAL INVESTIGADOR
B6: - Para anualidades futuras, si el nombre de la persona aún no se conoce, en lugar del "NOMBRE" se reflejará el Perfil dentro del proyecto.
B8: - En la columna 'Excl I+D`se indicará si se trata o no de un investigador adscrito en exclusiva a I+D
B10: - Por cada uno de los participantes en el proyecto, se cumplimentará su correspondiente Ficha de ampliación del apartado 2.1.
B13: Código Persona | C13: Nombre | D13: Titulación | E13: Excl I+D (SÍ/NO) | F13: ='Datos solicitud'!E14 -> 2023 | K13: =F13+1 -> 2024 | P13: =K13+1 -> 2025 | U13: =P13+1 -> 2026 | Z13: =U13+1 -> 2027 | AE13: =Z13+1 -> 2028
F14: Horas imputadas I+D | G14: Coste/Gasto I+D | H14: Horas imputadas IT | I14: Coste/Gasto IT | J14: Coste/Gasto TOTAL | K14: Horas imputadas I+D | L14: Coste/Gasto I+D | M14: Horas imputadas IT | N14: Coste/Gasto IT | O14: Coste/Gasto TOTAL | P14: Horas imputadas I+D | Q14: Coste/Gasto I+D | R14: Horas imputadas IT | S14: Coste/Gasto IT | T14: Coste/Gasto TOTAL | U14: Horas imputadas I+D | V14: Coste/Gasto I+D | W14: Horas imputadas IT | X14: Coste/Gasto IT | Y14: Coste/Gasto TOTAL | Z14: Horas imputadas I+D | AA14: Coste/Gasto I+D | AB14: Horas imputadas IT | AC14: Coste/Gasto IT | AD14: Coste/Gasto TOTAL | AE14: Horas imputadas I+D | AF14: Coste/Gasto I+D | AG14: Horas imputadas IT | AH14: Coste/Gasto IT | AI14: Coste/Gasto TOTAL
B15: 1 | C15: ALEJANDRO NAVALON FERNANDEZ | D15: Licenciado en Ingenería Informática | E15: NO | J15: =G15+I15 -> 0 | M15: 980 | N15: 42747.6 | O15: =L15+N15 -> 42747.6 | T15: =Q15+S15 -> 0 | Y15: =V15+X15 -> 0 | AD15: =AA15+AC15 -> 0 | AI15: =AF15+AH15 -> 0
B16: 2 | C16: ANDRES QUESADA MOLINERO | D16: Diplomado en Ingenería Informática | E16: NO | J16: =G16+I16 -> 0 | M16: 1070 | N16: 45528.5 | O16: =L16+N16 -> 45528.5 | T16: =Q16+S16 -> 0 | Y16: =V16+X16 -> 0 | AD16: =AA16+AC16 -> 0 | AI16: =AF16+AH16 -> 0
B17: 3 | C17: CRISTIAN PALAU TARRAGO | D17: Graduado en Ingenería Informática | E17: NO | J17: =G17+I17 -> 0 | M17: 1215 | N17: 40678.2 | O17: =L17+N17 -> 40678.2 | T17: =Q17+S17 -> 0
B18: 4 | C18: DANIEL CLARES MARTIN | D18: Grado superior en aplicaciones web | E18: NO | J18: =G18+I18 -> 0 | M18: 650 | N18: 20312.5 | O18: =L18+N18 -> 20312.5 | T18: =Q18+S18 -> 0 | Y18: =V18+X18 -> 0 | AD18: =AA18+AC18 -> 0 | AI18: =AF18+AH18 -> 0
B19: 5 | C19: DANIEL GUASCH PARRA | D19: Grado superior en aplicaciones web | E19: NO | J19: =G19+I19 -> 0 | M19: 750 | N19: 25110 | O19: =L19+N19 -> 25110 | T19: =Q19+S19 -> 0
B20: 6 | C20: DAVID MARTINEZ PLANELLAS | D20: Ingeniero técnico informático | E20: NO | J20: =G20+I20 -> 0 | M20: 570 | N20: 11679.3 | O20: =L20+N20 -> 11679.3 | T20: =Q20+S20 -> 0
B21: 7 | C21: DIDAC FERRER MARDONES | D21: Grado superior en administración de sistemas | E21: NO | J21: =G21+I21 -> 0 | M21: 965 | N21: 32520.5 | O21: =L21+N21 -> 32520.5 | T21: =Q21+S21 -> 0
B22: 8 | C22: DIEGO JAVIER KORMES | D22: Licenciado en Biología | E22: NO | J22: =G22+I22 -> 0 | M22: 935 | N22: 47610.2 | O22: =L22+N22 -> 47610.2 | T22: =Q22+S22 -> 0
B23: 9 | C23: ELOI VIVAS MARTINEZ | D23: CFGS Desarrollo de Aplicaciones Multiplataforma | E23: NO | J23: =G23+I23 -> 0 | M23: 1200 | N23: 35568 | O23: =L23+N23 -> 35568 | T23: =Q23+S23 -> 0
B24: 10 | C24: ERIK MOMPEAN RUIZ | D24: Grado superior en aplicaciones multiplataforma | E24: NO | J24: =G24+I24 -> 0 | M24: 1265 | N24: 38443.35 | O24: =L24+N24 -> 38443.35 | T24: =Q24+S24 -> 0
B25: 11 | C25: EYNAR ARNEZ ANDRADE | D25: Grado superior Ingeniería Informatica | E25: NO | J25: =G25+I25 -> 0 | M25: 690 | N25: 23101.2 | O25: =L25+N25 -> 23101.2 | T25: =Q25+S25 -> 0
B26: 12 | C26: FRANCISCO JAVIE GINE VENTURA | D26: Grado superior Ingeniería Informatica | E26: NO | J26: =G26+I26 -> 0 | M26: 500 | N26: 12860 | O26: =L26+N26 -> 12860 | T26: =Q26+S26 -> 0
B27: 13 | C27: JAVIER ALEJANDRO FUENTES | D27: Diplomado en Analista de Sistemas | E27: NO | J27: =G27+I27 -> 0 | M27: 1050 | N27: 37002 | O27: =L27+N27 -> 37002 | T27: =Q27+S27 -> 0
B28: 14 | C28: JAVIER ENRIQUE PINTO GONÇALVES | D28: Graduado en Ingenería Informática | E28: NO | J28: =G28+I28 -> 0 | M28: 1005 | N28: 45667.2 | O28: =L28+N28 -> 45667.2 | T28: =Q28+S28 -> 0
B29: 15 | C29: JAVIER PILLADO DOPICO | D29: Graduado en Ingenería Informática | E29: NO | J29: =G29+I29 -> 0 | M29: 680 | N29: 28893.2 | O29: =L29+N29 -> 28893.2 | T29: =Q29+S29 -> 0
B30: 16 | C30: JEFFREY JOSE SOARES AFONSO | D30: Graduado en Ingenería Informática | E30: NO | J30: =G30+I30 -> 0 | M30: 625 | N30: 25556.25 | O30: =L30+N30 -> 25556.25 | T30: =Q30+S30 -> 0
... B35: 21 | C35: LAURA ARROYO SANCHEZ | D35: Licenciada en Ingenería Informática | E35: NO | J35: =G35+I35 -> 0 | M35: 800 | N35: 23840 | O35: =L35+N35 -> 23840 | T35: =Q35+S35 -> 0
B36: 22 | C36: LUCIANO BURGOS LOMBARDI | D36: Graduado en Física | E36: NO | J36: =G36+I36 -> 0 | M36: 430 | N36: 16946.3 | O36: =L36+N36 -> 16946.3 | T36: =Q36+S36 -> 0 | Y36: =V36+X36 -> 0 | AD36: =AA36+AC36 -> 0 | AI36: =AF36+AH36 -> 0
B37: 23 | C37: LUIS CASAMAJOR PALOMA | D37: CFGS Desarrollo de Aplicaciones Multiplataforma | E37: NO | J37: =G37+I37 -> 0 | M37: 1150 | N37: 28186.5 | O37: =L37+N37 -> 28186.5 | T37: =Q37+S37 -> 0 | Y37: =V37+X37 -> 0 | AD37: =AA37+AC37 -> 0 | AI37: =AF37+AH37 -> 0
B38: 24 | C38: MARC MATEO PRATS | D38: Grado en Ingenería Informática | E38: NO | J38: =G38+I38 -> 0 | M38: 560 | N38: 16648.8 | O38: =L38+N38 -> 16648.8 | T38: =Q38+S38 -> 0 | Y38: =V38+X38 -> 0 | AD38: =AA38+AC38 -> 0 | AI38: =AF38+AH38 -> 0
B39: 25 | C39: MARTA TOMAS PARIS | D39: Diplomado en Ingenería Informática | E39: NO | J39: =G39+I39 -> 0 | M39: 910 | N39: 33888.4 | O39: =L39+N39 -> 33888.4 | T39: =Q39+S39 -> 0 | Y39: =V39+X39 -> 0 | AD39: =AA39+AC39 -> 0 | AI39: =AF39+AH39 -> 0
B40: 26 | C40: ORIOL BERNADAS CIURANA | D40: Grado superior en aplicaciones web | E40: NO | J40: =G40+I40 -> 0 | M40: 950 | N40: 33915 | O40: =L40+N40 -> 33915 | T40: =Q40+S40 -> 0 | Y40: =V40+X40 -> 0 | AD40: =AA40+AC40 -> 0 | AI40: =AF40+AH40 -> 0
B41: 27 | C41: POL CAMPS CASTRO | D41: Grado de Ingeniería en Tecnologias Industriales | E41: NO | J41: =G41+I41 -> 0 | M41: 735 | N41: 22762.95 | O41: =L41+N41 -> 22762.95 | T41: =Q41+S41 -> 0 | Y41: =V41+X41 -> 0 | AD41: =AA41+AC41 -> 0 | AI41: =AF41+AH41 -> 0
B42: 28 | C42: RAFAEL FRIAS TORIBIO | D42: FP Administración de Sistemas | E42: NO | J42: =G42+I42 -> 0 | M42: 600 | N42: 15636 | O42: =L42+N42 -> 15636 | T42: =Q42+S42 -> 0 | Y42: =V42+X42 -> 0 | AD42: =AA42+AC42 -> 0 | AI42: =AF42+AH42 -> 0
B43: 29 | C43: VICTOR GOMEZ REYES | D43: Licenciado en Ingenería Informática | E43: NO | J43: =G43+I43 -> 0 | M43: 600 | N43: 35958 | O43: =L43+N43 -> 35958 | T43: =Q43+S43 -> 0 | Y43: =V43+X43 -> 0 | AD43: =AA43+AC43 -> 0 | AI43: =AF43+AH43 -> 0
B44: 30 | E44: NO | J44: =G44+I44 -> 0 | O44: =L44+N44 -> 0 | T44: =Q44+S44 -> 0 | Y44: =V44+X44 -> 0 | AD44: =AA44+AC44 -> 0 | AI44: =AF44+AH44 -> 0
B45: 31 | E45: NO | J45: =G45+I45 -> 0 | O45: =L45+N45 -> 0 | T45: =Q45+S45 -> 0
B46: 32 | E46: NO | J46: =G46+I46 -> 0 | O46: =L46+N46 -> 0 | T46: =Q46+S46 -> 0
B47: 33 | E47: NO | J47: =G47+I47 -> 0 | O47: =L47+N47 -> 0 | T47: =Q47+S47 -> 0
B48: 34 | C48: Personal 2023 | E48: NO | I48: 977621.55 | J48: =G48+I48 -> 977621.55 | O48: =L48+N48 -> 0 | T48: =Q48+S48 -> 0
B49: 35 | C49: Personal 2025 | E49: NO | J49: =G49+I49 -> 0 | O49: =L49+N49 -> 0 | S49: 1073309.2 | T49: =Q49+S49 -> 1073309.2
B50: 36 | E50: NO | J50: =G50+I50 -> 0 | O50: =L50+N50 -> 0 | T50: =Q50+S50 -> 0 | Y50: =V50+X50 -> 0 | AD50: =AA50+AC50 -> 0 | AI50: =AF50+AH50 -> 0
D51: TOTAL personal NO ADSCRITO EN EXCLUSIVA a Actividades de I+D | F51: =SUMIF($E15:$E50,"<>SÍ",F15:F50) -> 0 | G51: =SUMIF($E15:$E50,"<>SÍ",G15:G50) -> 0 | H51: =SUMIF($E15:$E50,"<>SÍ",H15:H49) -> 0 | I51: =SUMIF($E15:$E50,"<>SÍ",I15:I50) -> 977621.55 | J51: =G51+I51 -> 977621.55 | K51: =SUMIF($E15:$E50,"<>SÍ",K15:K50) -> 0 | L51: =SUMIF($E15:$E50,"<>SÍ",L15:L50) -> 0 | M51: =SUMIF($E15:$E50,"<>SÍ",M15:M50) -> 24590 | N51: =SUMIF($E15:$E50,"<>SÍ",N15:N50) -> 884669.6 | O51: =L51+N51 -> 884669.6 | P51: =SUMIF($E15:$E50,"<>SÍ",P15:P50) -> 0 | Q51: =SUMIF($E15:$E50,"<>SÍ",Q15:Q50) -> 0 | R51: =SUMIF($E15:$E50,"<>SÍ",R15:R50) -> 0 | S51: =SUMIF($E15:$E50,"<>SÍ",S15:S50) -> 1073309.2 | T51: =Q51+S51 -> 1073309.2 | U51: =SUMIF($E15:$E50,"<>SÍ",U15:U50) -> 0 | V51: =SUMIF($E15:$E50,"<>SÍ",V15:V50) -> 0 | W51: =SUMIF($E15:$E50,"<>SÍ",W15:W50) -> 0 | X51: =SUMIF($E15:$E50,"<>SÍ",X15:X50) -> 0 | Y51: =V51+X51 -> 0 | Z51: =SUMIF($E15:$E50,"<>SÍ",Z15:Z50) -> 0 | AA51: =SUMIF($E15:$E50,"<>SÍ",AA15:AA50) -> 0 | AB51: =SUMIF($E15:$E50,"<>SÍ",AB15:AB50) -> 0 | AC51: =SUMIF($E15:$E50,"<>SÍ",AC15:AC50) -> 0 | AD51: =AA51+AC51 -> 0 | AE51: =SUMIF($E15:$E50,"<>SÍ",AE15:AE50) -> 0 | AF51: =SUMIF($E15:$E50,"<>SÍ",AF15:AF50) -> 0 | AG51: =SUMIF($E15:$E50,"<>SÍ",AG15:AG50) -> 0 | AH51: =SUMIF($E15:$E50,"<>SÍ",AH15:AH50) -> 0 | AI51: =AF51+AH51 -> 0
D52: TOTAL personal ADSCRITO EN EXCLUSIVA a Actividades de I+D | F52: =SUMIF($E15:$E50,"SÍ",F15:F50) -> 0 | G52: =SUMIF($E15:$E50,"SÍ",G15:G50) -> 0 | J52: =G52 -> 0 | K52: =SUMIF($E15:$E50,"SÍ",K15:K50) -> 0 | L52: =SUMIF($E15:$E50,"SÍ",L15:L50) -> 0 | O52: =L52 -> 0 | P52: =SUMIF($E15:$E50,"SÍ",P15:P50) -> 0 | Q52: =SUMIF($E15:$E50,"SÍ",Q15:Q50) -> 0 | T52: =Q52 -> 0 | U52: =SUMIF($E15:$E50,"SÍ",U15:U50) -> 0 | V52: =SUMIF($E15:$E50,"SÍ",V15:V50) -> 0 | Y52: =V52 -> 0 | Z52: =SUMIF($E15:$E50,"SÍ",Z15:Z50) -> 0 | AA52: =SUMIF($E15:$E50,"SÍ",AA15:AA50) -> 0 | AD52: =AA52 -> 0 | AE52: =SUMIF($E15:$E50,"SÍ",AE15:AE50) -> 0 | AF52: =SUMIF($E15:$E50,"SÍ",AF15:AF50) -> 0 | AI52: =AF52 -> 0
...

Sheet C.Externas (OPIS)
B4: 2.2 COLABORACIONES EXTERNAS
B5: 2.2.1 Universidades, Organismos Públicos de Investigación y Centros de Innovación y Tecnología (reconocidos y registrados como tales)
B8: - Para anualidades futuras, si el nombre de la colaboración externa (Universidad, OPI o CIT) aún no se conoce, en lugar de la "ENTIDAD" se reflejará el servicio y las actividades a subcontratar.
B10: - Es obligatorio indicar la 'Tipología' de la colaboración (UNI, OPI o CIT).
B12: - Por cada una de las entidades colaboradoras, se cumplimentará/n su/s correspondiente/s Ficha/s de ampliación del apartado 2.2 y el resto de Fichas "adicionales" cuando proceda.
B15: Código Colaboración | C15: Entidad | D15: NIF | E15: Tipo | F15: =Personal!F13 -> 2023 | I15: =F15+1 -> 2024 | L15: =I15+1 -> 2025 | O15: =L15+1 -> 2026 | R15: =O15+1 -> 2027 | U15: =R15+1 -> 2028
B16: Código Recurso | C16: Nombre | F16: Coste/Gasto I+D | G16: Coste/Gasto IT | H16: Coste/Gasto TOTAL | I16: Coste/Gasto I+D | J16: Coste/Gasto IT | K16: Coste/Gasto TOTAL | L16: Coste/Gasto I+D | M16: Coste/Gasto IT | N16: Coste/Gasto TOTAL | O16: Coste/Gasto I+D | P16: Coste/Gasto IT | Q16: Coste/Gasto TOTAL | R16: Coste/Gasto I+D | S16: Coste/Gasto IT | T16: Coste/Gasto TOTAL | U16: Coste/Gasto I+D | V16: Coste/Gasto IT | W16: Coste/Gasto TOTAL
B17: 1 | H17: =SUM(F17:G17) -> 0 | K17: =SUM(I17:J17) -> 0 | N17: =SUM(L17:M17) -> 0 | Q17: =SUM(O17:P17) -> 0 | T17: =SUM(R17:S17) -> 0 | W17: =U17+V17 -> 0
B18: =B17+1 -> 2 | H18: =SUM(F18:G18) -> 0 | K18: =SUM(I18:J18) -> 0 | N18: =SUM(L18:M18) -> 0 | Q18: =SUM(O18:P18) -> 0 | T18: =SUM(R18:S18) -> 0 | W18: =U18+V18 -> 0
B19: =B18+1 -> 3 | H19: =SUM(F19:G19) -> 0 | K19: =SUM(I19:J19) -> 0 | N19: =SUM(L19:M19) -> 0 | Q19: =SUM(O19:P19) -> 0 | T19: =SUM(R19:S19) -> 0 | W19: =U19+V19 -> 0
B20: =B19+1 -> 4 | H20: =SUM(F20:G20) -> 0 | K20: =SUM(I20:J20) -> 0 | N20: =SUM(L20:M20) -> 0 | Q20: =SUM(O20:P20) -> 0 | T20: =SUM(R20:S20) -> 0 | W20: =U20+V20 -> 0
B21: =B20+1 -> 5 | H21: =SUM(F21:G21) -> 0 | K21: =SUM(I21:J21) -> 0 | N21: =SUM(L21:M21) -> 0 | Q21: =SUM(O21:P21) -> 0 | T21: =SUM(R21:S21) -> 0 | W21: =U21+V21 -> 0
B22: =B21+1 -> 6 | H22: =SUM(F22:G22) -> 0 | K22: =SUM(I22:J22) -> 0 | N22: =SUM(L22:M22) -> 0 | Q22: =SUM(O22:P22) -> 0 | T22: =SUM(R22:S22) -> 0 | W22: =U22+V22 -> 0
B23: =B22+1 -> 7 | H23: =SUM(F23:G23) -> 0 | K23: =SUM(I23:J23) -> 0 | N23: =SUM(L23:M23) -> 0 | Q23: =SUM(O23:P23) -> 0 | T23: =SUM(R23:S23) -> 0 | W23: =U23+V23 -> 0
B24: =B23+1 -> 8 | H24: =SUM(F24:G24) -> 0 | K24: =SUM(I24:J24) -> 0 | N24: =SUM(L24:M24) -> 0 | Q24: =SUM(O24:P24) -> 0 | T24: =SUM(R24:S24) -> 0 | W24: =U24+V24 -> 0
B25: =B24+1 -> 9 | H25: =SUM(F25:G25) -> 0 | K25: =SUM(I25:J25) -> 0 | N25: =SUM(L25:M25) -> 0 | Q25: =SUM(O25:P25) -> 0 | T25: =SUM(R25:S25) -> 0 | W25: =U25+V25 -> 0
B26: =B25+1 -> 10 | H26: =SUM(F26:G26) -> 0 | K26: =SUM(I26:J26) -> 0 | N26: =SUM(L26:M26) -> 0 | Q26: =SUM(O26:P26) -> 0 | T26: =SUM(R26:S26) -> 0 | W26: =U26+V26 -> 0
B27: =B26+1 -> 11 | H27: =SUM(F27:G27) -> 0 | K27: =SUM(I27:J27) -> 0 | N27: =SUM(L27:M27) -> 0 | Q27: =SUM(O27:P27) -> 0 | T27: =SUM(R27:S27) -> 0 | W27: =U27+V27 -> 0
B28: =B27+1 -> 12 | H28: =SUM(F28:G28) -> 0 | K28: =SUM(I28:J28) -> 0 | N28: =SUM(L28:M28) -> 0 | Q28: =SUM(O28:P28) -> 0 | T28: =SUM(R28:S28) -> 0 | W28: =U28+V28 -> 0
B29: =B28+1 -> 13 | H29: =SUM(F29:G29) -> 0 | K29: =SUM(I29:J29) -> 0 | N29: =SUM(L29:M29) -> 0 | Q29: =SUM(O29:P29) -> 0 | T29: =SUM(R29:S29) -> 0 | W29: =U29+V29 -> 0
... B36: =B35+1 -> 20 | H36: =SUM(F36:G36) -> 0 | K36: =SUM(I36:J36) -> 0 | N36: =SUM(L36:M36) -> 0 | Q36: =SUM(O36:P36) -> 0 | T36: =SUM(R36:S36) -> 0 | W36: =U36+V36 -> 0
C37: TOTAL COLABORACIONES EXTERNAS contratadas / encargadas a UNIVERSIDADES | E37: UNI | F37: =SUMIF($E$17:$E$36,$E37,F$17:F$36) -> 0 | G37: =SUMIF($E$17:$E$36,$E37,G$17:G$36) -> 0 | H37: =SUM(F37:G37) -> 0 | I37: =SUMIF($E$17:$E$36,$E37,I$17:I$36) -> 0 | J37: =SUMIF($E$17:$E$36,$E37,J$17:J$36) -> 0 | K37: =SUM(I37:J37) -> 0 | L37: =SUMIF($E$17:$E$36,$E37,L$17:L$36) -> 0 | M37: =SUMIF($E$17:$E$36,$E37,M$17:M$36) -> 0 | N37: =SUM(L37:M37) -> 0 | O37: =SUMIF($E$17:$E$36,$E37,O$17:O$36) -> 0 | P37: =SUMIF($E$17:$E$36,$E37,P$17:P$36) -> 0 | Q37: =SUM(O37:P37) -> 0 | R37: =SUMIF($E$17:$E$36,$E37,R$17:R$36) -> 0 | S37: =SUMIF($E$17:$E$36,$E37,S$17:S$36) -> 0 | T37: =SUM(R37:S37) -> 0 | U37: =SUMIF($E$17:$E$36,$E37,U$17:U$36) -> 0 | V37: =SUMIF($E$17:$E$36,$E37,V$17:V$36) -> 0 | W37: =SUM(U37:V37) -> 0
C38: TOTAL COLABORACIONES EXTERNAS contratadas / encargadas a ORGANISMOS PÚBLICOS DE INVESTIGACIÓN | E38: OPI | F38: =SUMIF($E$17:$E$36,$E38,F$17:F$36) -> 0 | G38: =SUMIF($E$17:$E$36,$E38,G$17:G$36) -> 0 | H38: =SUM(F38:G38) -> 0 | I38: =SUMIF($E$17:$E$36,$E38,I$17:I$36) -> 0 | J38: =SUMIF($E$17:$E$36,$E38,J$17:J$36) -> 0 | K38: =SUM(I38:J38) -> 0 | L38: =SUMIF($E$17:$E$36,$E38,L$17:L$36) -> 0 | M38: =SUMIF($E$17:$E$36,$E38,M$17:M$36) -> 0 | N38: =SUM(L38:M38) -> 0 | O38: =SUMIF($E$17:$E$36,$E38,O$17:O$36) -> 0 | P38: =SUMIF($E$17:$E$36,$E38,P$17:P$36) -> 0 | Q38: =SUM(O38:P38) -> 0 | R38: =SUMIF($E$17:$E$36,$E38,R$17:R$36) -> 0 | S38: =SUMIF($E$17:$E$36,$E38,S$17:S$36) -> 0 | T38: =SUM(R38:S38) -> 0 | U38: =SUMIF($E$17:$E$36,$E38,U$17:U$36) -> 0 | V38: =SUMIF($E$17:$E$36,$E38,V$17:V$36) -> 0 | W38: =SUM(U38:V38) -> 0
C39: TOTAL COLABORACIONES EXTERNAS contratadas / encargadas a CENTROS DE INNOVACIÓN Y TECNOLOGÍA | E39: CIT | F39: =SUMIF($E$17:$E$36,$E39,F$17:F$36) -> 0 | G39: =SUMIF($E$17:$E$36,$E39,G$17:G$36) -> 0 | H39: =SUM(F39:G39) -> 0 | I39: =SUMIF($E$17:$E$36,$E39,I$17:I$36) -> 0 | J39: =SUMIF($E$17:$E$36,$E39,J$17:J$36) -> 0 | K39: =SUM(I39:J39) -> 0 | L39: =SUMIF($E$17:$E$36,$E39,L$17:L$36) -> 0 | M39: =SUMIF($E$17:$E$36,$E39,M$17:M$36) -> 0 | N39: =SUM(L39:M39) -> 0 | O39: =SUMIF($E$17:$E$36,$E39,O$17:O$36) -> 0 | P39: =SUMIF($E$17:$E$36,$E39,P$17:P$36) -> 0 | Q39: =SUM(O39:P39) -> 0 | R39: =SUMIF($E$17:$E$36,$E39,R$17:R$36) -> 0 | S39: =SUMIF($E$17:$E$36,$E39,S$17:S$36) -> 0 | T39: =SUM(R39:S39) -> 0 | U39: =SUMIF($E$17:$E$36,$E39,U$17:U$36) -> 0 | V39: =SUMIF($E$17:$E$36,$E39,V$17:V$36) -> 0 | W39: =SUM(U39:V39) -> 0
C40: TOTAL COL. EXTERNAS CONTRATADAS /ENCARGADAS A UNIVERSIDADES, OPIs y CCTT | F40: =F37+F38+F39 -> 0 | G40: =G37+G38+G39 -> 0 | H40: =F40+G40 -> 0 | I40: =I37+I38+I39 -> 0 | J40: =J37+J38+J39 -> 0 | K40: =I40+J40 -> 0 | L40: =L37+L38+L39 -> 0 | M40: =M37+M38+M39 -> 0 | N40: =L40+M40 -> 0 | O40: =O37+O38+O39 -> 0 | P40: =P37+P38+P39 -> 0 | Q40: =O40+P40 -> 0 | R40: =R37+R38+R39 -> 0 | S40: =S37+S38+S39 -> 0 | T40: =R40+S40 -> 0 | U40: =U37+U38+U39 -> 0 | V40: =V37+V38+V39 -> 0 | W40: =U40+V40 -> 0

Sheet C.Externas (Otros)
B4: 2.2 COLABORACIONES EXTERNAS
B5: 2.2.2 Otros (Empresas Privadas, Asociaciones, etc.)
B8: - Para anualidades futuras, si el nombre de la colaboración externa (Universidad, OPI o CIT) aún no se conoce, en lugar de la "ENTIDAD" se reflejará el servicio y las actividades a subcontratar.
B10: - Por cada una de las entidades de colaboración, se cumplimentará/n su/s correspondiente/s ficha/s de ampliación del apartado 2.2 y el resto de Fichas "adicionales" cuando proceda.
B13: Código Colaboración | C13: Entidad | D13: NIF | E13: =Personal!F13 -> 2023 | H13: =E13+1 -> 2024 | K13: =H13+1 -> 2025 | N13: =K13+1 -> 2026 | Q13: =N13+1 -> 2027 | T13: =Q13+1 -> 2028
B14: Código Recurso | C14: Nombre | E14: Coste/Gasto I+D | F14: Coste/Gasto IT | G14: Coste/Gasto TOTAL | H14: Coste/Gasto I+D | I14: Coste/Gasto IT | J14: Coste/Gasto TOTAL | K14: Coste/Gasto I+D | L14: Coste/Gasto IT | M14: Coste/Gasto TOTAL | N14: Coste/Gasto I+D | O14: Coste/Gasto IT | P14: Coste/Gasto TOTAL | Q14: Coste/Gasto I+D | R14: Coste/Gasto IT | S14: Coste/Gasto TOTAL | T14: Coste/Gasto I+D | U14: Coste/Gasto IT | V14: Coste/Gasto TOTAL
B15: 1 | C15: PEDRO MORENO IZQUIERDO | D15: 47072906W | F15: 23286.28 | G15: =E15+F15 -> 23286.28 | I15: 6457.44 | J15: =SUM(H15:I15) -> 6457.44 | M15: =SUM(K15:L15) -> 0 | P15: =SUM(N15:O15) -> 0 | S15: =SUM(Q15:R15) -> 0 | V15: =SUM(T15:U15) -> 0
B16: =B15+1 -> 2 | C16: ET SYSTEMS GLOBAL STORAGE SOLUTIONS S.L | D16: B64625338 | F16: 8452.01 | G16: =E16+F16 -> 8452.01 | I16: 13873.34 | J16: =SUM(H16:I16) -> 13873.34 | M16: =SUM(K16:L16) -> 0 | P16: =SUM(N16:O16) -> 0 | S16: =SUM(Q16:R16) -> 0 | V16: =SUM(T16:U16) -> 0
B17: =B16+1 -> 3 | G17: =E17+F17 -> 0 | J17: =SUM(H17:I17) -> 0 | M17: =SUM(K17:L17) -> 0 | P17: =SUM(N17:O17) -> 0 | S17: =SUM(Q17:R17) -> 0 | V17: =SUM(T17:U17) -> 0
B18: =B17+1 -> 4 | G18: =E18+F18 -> 0 | J18: =SUM(H18:I18) -> 0 | M18: =SUM(K18:L18) -> 0 | P18: =SUM(N18:O18) -> 0 | S18: =SUM(Q18:R18) -> 0 | V18: =SUM(T18:U18) -> 0
B19: =B18+1 -> 5 | C19: Entidades Colaboradoras 2025 | L19: 24880.89 | M19: =SUM(K19:L19) -> 24880.89
B20: =B19+1 -> 6 | G20: =E20+F20 -> 0 | J20: =SUM(H20:I20) -> 0 | M20: =SUM(K20:L20) -> 0 | P20: =SUM(N20:O20) -> 0 | S20: =SUM(Q20:R20) -> 0 | V20: =SUM(T20:U20) -> 0
B21: =B20+1 -> 7 | G21: =E21+F21 -> 0 | J21: =SUM(H21:I21) -> 0 | M21: =SUM(K21:L21) -> 0 | P21: =SUM(N21:O21) -> 0 | S21: =SUM(Q21:R21) -> 0 | V21: =SUM(T21:U21) -> 0
B22: =B21+1 -> 8
B23: =B22+1 -> 9 | J23: =SUM(H23:I23) -> 0 | M23: =SUM(K23:L23) -> 0 | P23: =SUM(N23:O23) -> 0 | S23: =SUM(Q23:R23) -> 0 | V23: =SUM(T23:U23) -> 0
B24: =B23+1 -> 10 | G24: =E24+F24 -> 0 | J24: =SUM(H24:I24) -> 0 | M24: =SUM(K24:L24) -> 0 | P24: =SUM(N24:O24) -> 0 | S24: =SUM(Q24:R24) -> 0 | V24: =SUM(T24:U24) -> 0
B25: =B24+1 -> 11 | G25: =E25+F25 -> 0 | J25: =SUM(H25:I25) -> 0 | M25: =SUM(K25:L25) -> 0 | P25: =SUM(N25:O25) -> 0 | S25: =SUM(Q25:R25) -> 0 | V25: =SUM(T25:U25) -> 0
B26: =B25+1 -> 12 | G26: =E26+F26 -> 0 | J26: =SUM(H26:I26) -> 0 | M26: =SUM(K26:L26) -> 0 | P26: =SUM(N26:O26) -> 0 | S26: =SUM(Q26:R26) -> 0 | V26: =SUM(T26:U26) -> 0
B27: =B26+1 -> 13 | G27: =E27+F27 -> 0 | J27: =SUM(H27:I27) -> 0 | M27: =SUM(K27:L27) -> 0 | P27: =SUM(N27:O27) -> 0 | S27: =SUM(Q27:R27) -> 0 | V27: =SUM(T27:U27) -> 0
B28: =B27+1 -> 14 | G28: =E28+F28 -> 0 | J28: =SUM(H28:I28) -> 0 | M28: =SUM(K28:L28) -> 0 | P28: =SUM(N28:O28) -> 0 | S28: =SUM(Q28:R28) -> 0 | V28: =SUM(T28:U28) -> 0
B29: =B28+1 -> 15 | G29: =E29+F29 -> 0 | J29: =SUM(H29:I29) -> 0 | M29: =SUM(K29:L29) -> 0 | P29: =SUM(N29:O29) -> 0 | S29: =SUM(Q29:R29) -> 0 | V29: =SUM(T29:U29) -> 0
B30: =B29+1 -> 16 | G30: =E30+F30 -> 0 | J30: =SUM(H30:I30) -> 0 | M30: =SUM(K30:L30) -> 0 | P30: =SUM(N30:O30) -> 0 | S30: =SUM(Q30:R30) -> 0 | V30: =SUM(T30:U30) -> 0
B31: =B30+1 -> 17 | G31: =E31+F31 -> 0 | J31: =SUM(H31:I31) -> 0 | M31: =SUM(K31:L31) -> 0 | P31: =SUM(N31:O31) -> 0 | S31: =SUM(Q31:R31) -> 0 | V31: =SUM(T31:U31) -> 0
B32: =B31+1 -> 18 | G32: =E32+F32 -> 0 | J32: =SUM(H32:I32) -> 0 | M32: =SUM(K32:L32) -> 0 | P32: =SUM(N32:O32) -> 0 | S32: =SUM(Q32:R32) -> 0 | V32: =SUM(T32:U32) -> 0
B33: =B32+1 -> 19 | G33: =E33+F33 -> 0 | J33: =SUM(H33:I33) -> 0 | M33: =SUM(K33:L33) -> 0 | P33: =SUM(N33:O33) -> 0 | S33: =SUM(Q33:R33) -> 0 | V33: =SUM(T33:U33) -> 0
B34: =B33+1 -> 20 | G34: =E34+F34 -> 0 | J34: =SUM(H34:I34) -> 0 | M34: =SUM(K34:L34) -> 0 | P34: =SUM(N34:O34) -> 0 | S34: =SUM(Q34:R34) -> 0 | V34: =SUM(T34:U34) -> 0
B35: =B34+1 -> 21 | G35: =E35+F35 -> 0 | J35: =SUM(H35:I35) -> 0 | M35: =SUM(K35:L35) -> 0 | P35: =SUM(N35:O35) -> 0 | S35: =SUM(Q35:R35) -> 0 | V35: =SUM(T35:U35) -> 0
B36: =B35+1 -> 22 | G36: =E36+F36 -> 0 | J36: =SUM(H36:I36) -> 0 | M36: =SUM(K36:L36) -> 0 | P36: =SUM(N36:O36) -> 0 | S36: =SUM(Q36:R36) -> 0 | V36: =SUM(T36:U36) -> 0
C37: TOTAL COLABORACIONES EXTERNAS | E37: =SUM(E15:E36) -> 0 | F37: =SUM(F15:F36) -> 31738.29 | G37: =E37+F37 -> 31738.29 | H37: =SUM(H15:H36) -> 0 | I37: =SUM(I15:I36) -> 20330.78 | J37: =SUM(J15:J36) -> 20330.78 | K37: =SUM(K15:K36) -> 0 | L37: =SUM(L15:L36) -> 24880.89 | M37: =SUM(M15:M36) -> 24880.89 | N37: =SUM(N15:N36) -> 0 | O37: =SUM(O15:O36) -> 0 | ... V37: =SUM(V15:V36) -> 0

Sheet El._inmovilizado (AMORTIZACIÓN)
B4: 2.3 AMORTIZACIÓN DE ELEMENTOS DE INMOVILIZADO MATERIAL E INTANGIBLE
B7: - Por cada uno de los elementos de inmovilizado, se cumplimentará su correspondiente Ficha de ampliación del apartado 2.3.
B10: Código Elemento | C10: AMORTIZACIÓN DE ELEMENTOS DE INMOVILIZADO MATERIAL E INTANGIBLE | D10: =Personal!F13 -> 2023 | G10: =D10+1 -> 2024 | J10: =G10+1 -> 2025 | M10: =J10+1 -> 2026 | P10: =M10+1 -> 2027 | S10: =P10+1 -> 2028
B11: Código Recurso | D11: Coste/Gasto I+D | E11: Coste/Gasto IT | F11: Coste/Gasto TOTAL | G11: Coste/Gasto I+D | H11: Coste/Gasto IT | I11: Coste/Gasto TOTAL | J11: Coste/Gasto I+D | K11: Coste/Gasto IT | L11: Coste/Gasto TOTAL | M11: Coste/Gasto I+D | N11: Coste/Gasto IT | O11: Coste/Gasto TOTAL | P11: Coste/Gasto I+D | Q11: Coste/Gasto IT | R11: Coste/Gasto TOTAL | S11: Coste/Gasto I+D | T11: Coste/Gasto IT | U11: Coste/Gasto TOTAL
B12: 1 | F12: =SUM(D12:E12) -> 0 | I12: =SUM(G12:H12) -> 0 | L12: =SUM(J12:K12) -> 0 | O12: =SUM(M12:N12) -> 0 | R12: =SUM(P12:Q12) -> 0 | U12: =SUM(S12:T12) -> 0
B13: =B12+1 -> 2 | F13: =SUM(D13:E13) -> 0 | I13: =SUM(G13:H13) -> 0 | L13: =SUM(J13:K13) -> 0 | O13: =SUM(M13:N13) -> 0 | R13: =SUM(P13:Q13) -> 0 | U13: =SUM(S13:T13) -> 0
B14: =B13+1 -> 3 | F14: =SUM(D14:E14) -> 0 | I14: =SUM(G14:H14) -> 0 | L14: =SUM(J14:K14) -> 0 | O14: =SUM(M14:N14) -> 0 | R14: =SUM(P14:Q14) -> 0 | U14: =SUM(S14:T14) -> 0
B15: =B14+1 -> 4 | F15: =SUM(D15:E15) -> 0 | I15: =SUM(G15:H15) -> 0 | L15: =SUM(J15:K15) -> 0 | O15: =SUM(M15:N15) -> 0 | R15: =SUM(P15:Q15) -> 0 | U15: =SUM(S15:T15) -> 0
B16: =B15+1 -> 5 | F16: =SUM(D16:E16) -> 0 | I16: =SUM(G16:H16) -> 0 | L16: =SUM(J16:K16) -> 0 | O16: =SUM(M16:N16) -> 0 | R16: =SUM(P16:Q16) -> 0 | U16: =SUM(S16:T16) -> 0
B17: =B16+1 -> 6 | F17: =SUM(D17:E17) -> 0 | I17: =SUM(G17:H17) -> 0 | L17: =SUM(J17:K17) -> 0 | O17: =SUM(M17:N17) -> 0 | R17: =SUM(P17:Q17) -> 0 | U17: =SUM(S17:T17) -> 0
B18: =B17+1 -> 7 | F18: =SUM(D18:E18) -> 0 | I18: =SUM(G18:H18) -> 0 | L18: =SUM(J18:K18) -> 0 | O18: =SUM(M18:N18) -> 0 | R18: =SUM(P18:Q18) -> 0 | U18: =SUM(S18:T18) -> 0
B19: =B18+1 -> 8 | F19: =SUM(D19:E19) -> 0 | I19: =SUM(G19:H19) -> 0 | L19: =SUM(J19:K19) -> 0 | O19: =SUM(M19:N19) -> 0 | R19: =SUM(P19:Q19) -> 0 | U19: =SUM(S19:T19) -> 0
B20: =B19+1 -> 9 | F20: =SUM(D20:E20) -> 0 | I20: =SUM(G20:H20) -> 0 | L20: =SUM(J20:K20) -> 0 | O20: =SUM(M20:N20) -> 0 | R20: =SUM(P20:Q20) -> 0 | U20: =SUM(S20:T20) -> 0
B21: =B20+1 -> 10 | F21: =SUM(D21:E21) -> 0 | I21: =SUM(G21:H21) -> 0 | L21: =SUM(J21:K21) -> 0 | O21: =SUM(M21:N21) -> 0 | R21: =SUM(P21:Q21) -> 0 | U21: =SUM(S21:T21) -> 0
B22: =B21+1 -> 11 | F22: =SUM(D22:E22) -> 0 | I22: =SUM(G22:H22) -> 0 | L22: =SUM(J22:K22) -> 0 | O22: =SUM(M22:N22) -> 0 | R22: =SUM(P22:Q22) -> 0 | U22: =SUM(S22:T22) -> 0
B23: =B22+1 -> 12 | F23: =SUM(D23:E23) -> 0 | I23: =SUM(G23:H23) -> 0 | L23: =SUM(J23:K23) -> 0 | O23: =SUM(M23:N23) -> 0 | R23: =SUM(P23:Q23) -> 0 | U23: =SUM(S23:T23) -> 0
B24: =B23+1 -> 13 | F24: =SUM(D24:E24) -> 0 | I24: =SUM(G24:H24) -> 0 | L24: =SUM(J24:K24) -> 0 | O24: =SUM(M24:N24) -> 0 | R24: =SUM(P24:Q24) -> 0 | U24: =SUM(S24:T24) -> 0
... B31: =B30+1 -> 20 | F31: =SUM(D31:E31) -> 0 | I31: =SUM(G31:H31) -> 0 | L31: =SUM(J31:K31) -> 0 | O31: =SUM(M31:N31) -> 0 | R31: =SUM(P31:Q31) -> 0 | U31: =SUM(S31:T31) -> 0
C32: TOTAL | D32: =SUM(D12:D31) -> 0 | E32: =SUM(E12:E31) -> 0 | F32: =D32+E32 -> 0 | G32: =SUM(G12:G31) -> 0 | H32: =SUM(H12:H31) -> 0 | I32: =G32+H32 -> 0 | J32: =SUM(J12:J31) -> 0 | K32: =SUM(K12:K31) -> 0 | L32: =J32+K32 -> 0 | M32: =SUM(M12:M31) -> 0 | N32: =SUM(N12:N31) -> 0 | O32: =M32+N32 -> 0 | P32: =SUM(P12:P31) -> 0 | Q32: =SUM(Q12:Q31) -> 0 | R32: =P32+Q32 -> 0 | S32: =SUM(S12:S31) -> 0 | T32: =SUM(T12:T31) -> 0 | U32: =S32+T32 -> 0

Sheet El._inmovilizado (INVERSIÓN)
B4: 2.3 INVERSIÓN EN ELEMENTOS DE INMOVILIZADO MATERIAL E INTANGIBLE
B6: - Por cada uno de los elementos de inmovilizado, se cumplimentará su correspondiente Ficha de ampliación del apartado 2.3.
B9: Código Elemento | C9: INVERSIÓN EN ELEMENTOS DE INMOVILIZADO MATERIAL E INTANGIBLE | D9: =Personal!F13 -> 2023 | G9: =D9+1 -> 2024 | J9: =G9+1 -> 2025 | M9: =J9+1 -> 2026 | P9: =M9+1 -> 2027 | S9: =P9+1 -> 2028
B10: Código Recurso | D10: Coste/Gasto I+D | E10: Coste/Gasto IT | F10: Coste/Gasto TOTAL | G10: Coste/Gasto I+D | H10: Coste/Gasto IT | I10: Coste/Gasto TOTAL | J10: Coste/Gasto I+D | K10: Coste/Gasto IT | L10: Coste/Gasto TOTAL | M10: Coste/Gasto I+D | N10: Coste/Gasto IT | O10: Coste/Gasto TOTAL | P10: Coste/Gasto I+D | Q10: Coste/Gasto IT | R10: Coste/Gasto TOTAL | S10: Coste/Gasto I+D | T10: Coste/Gasto IT | U10: Coste/Gasto TOTAL
B11: 1 | F11: =SUM(D11:E11) -> 0 | I11: =SUM(G11:H11) -> 0 | L11: =SUM(J11:K11) -> 0 | O11: =SUM(M11:N11) -> 0 | R11: =SUM(P11:Q11) -> 0 | U11: =SUM(S11:T11) -> 0
B12: =B11+1 -> 2 | F12: =SUM(D12:E12) -> 0 | I12: =SUM(G12:H12) -> 0 | L12: =SUM(J12:K12) -> 0 | O12: =SUM(M12:N12) -> 0 | R12: =SUM(P12:Q12) -> 0 | U12: =SUM(S12:T12) -> 0
B13: =B12+1 -> 3 | F13: =SUM(D13:E13) -> 0 | I13: =SUM(G13:H13) -> 0 | L13: =SUM(J13:K13) -> 0 | O13: =SUM(M13:N13) -> 0 | R13: =SUM(P13:Q13) -> 0 | U13: =SUM(S13:T13) -> 0
B14: =B13+1 -> 4 | F14: =SUM(D14:E14) -> 0 | I14: =SUM(G14:H14) -> 0 | L14: =SUM(J14:K14) -> 0 | O14: =SUM(M14:N14) -> 0 | R14: =SUM(P14:Q14) -> 0 | U14: =SUM(S14:T14) -> 0
B15: =B14+1 -> 5 | F15: =SUM(D15:E15) -> 0 | I15: =SUM(G15:H15) -> 0 | L15: =SUM(J15:K15) -> 0 | O15: =SUM(M15:N15) -> 0 | R15: =SUM(P15:Q15) -> 0 | U15: =SUM(S15:T15) -> 0
B16: =B15+1 -> 6 | F16: =SUM(D16:E16) -> 0 | I16: =SUM(G16:H16) -> 0 | L16: =SUM(J16:K16) -> 0 | O16: =SUM(M16:N16) -> 0 | R16: =SUM(P16:Q16) -> 0 | U16: =SUM(S16:T16) -> 0
B17: =B16+1 -> 7 | F17: =SUM(D17:E17) -> 0 | I17: =SUM(G17:H17) -> 0 | L17: =SUM(J17:K17) -> 0 | O17: =SUM(M17:N17) -> 0 | R17: =SUM(P17:Q17) -> 0 | U17: =SUM(S17:T17) -> 0
B18: =B17+1 -> 8 | F18: =SUM(D18:E18) -> 0 | I18: =SUM(G18:H18) -> 0 | L18: =SUM(J18:K18) -> 0 | O18: =SUM(M18:N18) -> 0 | R18: =SUM(P18:Q18) -> 0 | U18: =SUM(S18:T18) -> 0
B19: =B18+1 -> 9 | F19: =SUM(D19:E19) -> 0 | I19: =SUM(G19:H19) -> 0 | L19: =SUM(J19:K19) -> 0 | O19: =SUM(M19:N19) -> 0 | R19: =SUM(P19:Q19) -> 0 | U19: =SUM(S19:T19) -> 0
B20: =B19+1 -> 10 | F20: =SUM(D20:E20) -> 0 | I20: =SUM(G20:H20) -> 0 | L20: =SUM(J20:K20) -> 0 | O20: =SUM(M20:N20) -> 0 | R20: =SUM(P20:Q20) -> 0 | U20: =SUM(S20:T20) -> 0
B21: =B20+1 -> 11 | F21: =SUM(D21:E21) -> 0 | I21: =SUM(G21:H21) -> 0 | L21: =SUM(J21:K21) -> 0 | O21: =SUM(M21:N21) -> 0 | R21: =SUM(P21:Q21) -> 0 | U21: =SUM(S21:T21) -> 0
B22: =B21+1 -> 12 | F22: =SUM(D22:E22) -> 0 | I22: =SUM(G22:H22) -> 0 | L22: =SUM(J22:K22) -> 0 | O22: =SUM(M22:N22) -> 0 | R22: =SUM(P22:Q22) -> 0 | U22: =SUM(S22:T22) -> 0
B23: =B22+1 -> 13 | F23: =SUM(D23:E23) -> 0 | I23: =SUM(G23:H23) -> 0 | L23: =SUM(J23:K23) -> 0 | O23: =SUM(M23:N23) -> 0 | R23: =SUM(P23:Q23) -> 0 | U23: =SUM(S23:T23) -> 0
... B30: =B29+1 -> 20 | F30: =SUM(D30:E30) -> 0 | I30: =SUM(G30:H30) -> 0 | L30: =SUM(J30:K30) -> 0 | O30: =SUM(M30:N30) -> 0 | R30: =SUM(P30:Q30) -> 0 | U30: =SUM(S30:T30) -> 0
C31: TOTAL | D31: =SUM(D11:D30) -> 0 | F31: =D31+E31 -> 0 | G31: =SUM(G11:G30) -> 0 | I31: =G31+H31 -> 0 | J31: =SUM(J11:J30) -> 0 | L31: =J31+K31 -> 0 | M31: =SUM(M11:M30) -> 0 | O31: =M31+N31 -> 0 | P31: =SUM(P11:P30) -> 0 | R31: =P31+Q31 -> 0 | S31: =SUM(S11:S30) -> 0 | U31: =S31+T31 -> 0

Sheet Fungibles
B4: 2.4 MATERIAL FUNGIBLE
B6: - Por cada una de las partidas correspondientes a un mismo proveedor o un concepto, cuya suma sea superior a 30.000 €, se cumplimentará/n su/s correspondiente/s Ficha/s de ampliación del apartado 2.4
B9: Código Fungible | C9: MATERIAL FUNGIBLE | D9: =Personal!F13 -> 2023 | G9: =D9+1 -> 2024 | J9: =G9+1 -> 2025 | M9: =J9+1 -> 2026 | P9: =M9+1 -> 2027 | S9: =P9+1 -> 2028
D10: Coste/Gasto I+D | E10: Coste/Gasto IT | F10: Coste/Gasto TOTAL | G10: Coste/Gasto I+D | H10: Coste/Gasto IT | I10: Coste/Gasto TOTAL | J10: Coste/Gasto I+D | K10: Coste/Gasto IT | L10: Coste/Gasto TOTAL | M10: Coste/Gasto I+D | N10: Coste/Gasto IT | O10: Coste/Gasto TOTAL | P10: Coste/Gasto I+D | Q10: Coste/Gasto IT | R10: Coste/Gasto TOTAL | S10: Coste/Gasto I+D | T10: Coste/Gasto IT | U10: Coste/Gasto TOTAL
B11: 1 | F11: =SUM(D11:E11) -> 0 | I11: =SUM(G11:H11) -> 0 | L11: =SUM(J11:K11) -> 0 | O11: =SUM(M11:N11) -> 0 | R11: =SUM(P11:Q11) -> 0 | U11: =SUM(S11:T11) -> 0
B12: =B11+1 -> 2 | F12: =SUM(D12:E12) -> 0 | I12: =SUM(G12:H12) -> 0 | L12: =SUM(J12:K12) -> 0 | O12: =SUM(M12:N12) -> 0 | R12: =SUM(P12:Q12) -> 0 | U12: =SUM(S12:T12) -> 0
B13: =B12+1 -> 3 | F13: =SUM(D13:E13) -> 0 | I13: =SUM(G13:H13) -> 0 | L13: =SUM(J13:K13) -> 0 | O13: =SUM(M13:N13) -> 0 | R13: =SUM(P13:Q13) -> 0 | U13: =SUM(S13:T13) -> 0
B14: =B13+1 -> 4 | F14: =SUM(D14:E14) -> 0 | I14: =SUM(G14:H14) -> 0 | L14: =SUM(J14:K14) -> 0 | O14: =SUM(M14:N14) -> 0 | R14: =SUM(P14:Q14) -> 0 | U14: =SUM(S14:T14) -> 0
B15: =B14+1 -> 5 | F15: =SUM(D15:E15) -> 0 | I15: =SUM(G15:H15) -> 0 | L15: =SUM(J15:K15) -> 0 | O15: =SUM(M15:N15) -> 0 | R15: =SUM(P15:Q15) -> 0 | U15: =SUM(S15:T15) -> 0
B16: =B15+1 -> 6 | F16: =SUM(D16:E16) -> 0 | I16: =SUM(G16:H16) -> 0 | L16: =SUM(J16:K16) -> 0 | O16: =SUM(M16:N16) -> 0 | R16: =SUM(P16:Q16) -> 0 | U16: =SUM(S16:T16) -> 0
B17: =B16+1 -> 7 | F17: =SUM(D17:E17) -> 0 | I17: =SUM(G17:H17) -> 0 | L17: =SUM(J17:K17) -> 0 | O17: =SUM(M17:N17) -> 0 | R17: =SUM(P17:Q17) -> 0 | U17: =SUM(S17:T17) -> 0
B18: =B17+1 -> 8 | F18: =SUM(D18:E18) -> 0 | I18: =SUM(G18:H18) -> 0 | L18: =SUM(J18:K18) -> 0 | O18: =SUM(M18:N18) -> 0 | R18: =SUM(P18:Q18) -> 0 | U18: =SUM(S18:T18) -> 0
B19: =B18+1 -> 9 | F19: =SUM(D19:E19) -> 0 | I19: =SUM(G19:H19) -> 0 | L19: =SUM(J19:K19) -> 0 | O19: =SUM(M19:N19) -> 0 | R19: =SUM(P19:Q19) -> 0 | U19: =SUM(S19:T19) -> 0
B20: =B19+1 -> 10 | F20: =SUM(D20:E20) -> 0 | I20: =SUM(G20:H20) -> 0 | L20: =SUM(J20:K20) -> 0 | O20: =SUM(M20:N20) -> 0 | R20: =SUM(P20:Q20) -> 0 | U20: =SUM(S20:T20) -> 0
B21: =B20+1 -> 11 | F21: =SUM(D21:E21) -> 0 | I21: =SUM(G21:H21) -> 0 | L21: =SUM(J21:K21) -> 0 | O21: =SUM(M21:N21) -> 0 | R21: =SUM(P21:Q21) -> 0 | U21: =SUM(S21:T21) -> 0
B22: =B21+1 -> 12 | F22: =SUM(D22:E22) -> 0 | I22: =SUM(G22:H22) -> 0 | L22: =SUM(J22:K22) -> 0 | O22: =SUM(M22:N22) -> 0 | R22: =SUM(P22:Q22) -> 0 | U22: =SUM(S22:T22) -> 0
B23: =B22+1 -> 13 | F23: =SUM(D23:E23) -> 0 | I23: =SUM(G23:H23) -> 0 | L23: =SUM(J23:K23) -> 0 | O23: =SUM(M23:N23) -> 0 | R23: =SUM(P23:Q23) -> 0 | U23: =SUM(S23:T23) -> 0
... B30: =B29+1 -> 20 | F30: =SUM(D30:E30) -> 0 | I30: =SUM(G30:H30) -> 0 | L30: =SUM(J30:K30) -> 0 | O30: =SUM(M30:N30) -> 0 | R30: =SUM(P30:Q30) -> 0 | U30: =SUM(S30:T30) -> 0
C31: TOTAL | D31: =SUM(D11:D30) -> 0 | E31: =SUM(E11:E30) -> 0 | F31: =D31+E31 -> 0 | G31: =SUM(G11:G30) -> 0 | H31: =SUM(H11:H30) -> 0 | I31: =G31+H31 -> 0 | J31: =SUM(J11:J30) -> 0 | K31: =SUM(K11:K30) -> 0 | L31: =J31+K31 -> 0 | M31: =SUM(M11:M30) -> 0 | N31: =SUM(N11:N30) -> 0 | O31: =M31+N31 -> 0 | P31: =SUM(P11:P30) -> 0 | Q31: =SUM(Q11:Q30) -> 0 | R31: =P31+Q31 -> 0 | S31: =SUM(S11:S30) -> 0 | T31: =SUM(T11:T30) -> 0 | U31: =S31+T31 -> 0

Sheet Otros Gastos
B4: 2.5 OTROS GASTOS
B6: - Para cada uno de los conceptos recogidos, que superen en una cuantía del 5% a la suma total del gasto de personal, o que sumados los de un mismo proveedor o modalidad superen dicha cuantía, se cumplimentará la Ficha de ampliación del apartado 2.5.
B9: Código Otros | C9: OTROS GASTOS | D9: =Personal!F13 -> 2023 | G9: =D9+1 -> 2024 | J9: =G9+1 -> 2025 | M9: =J9+1 -> 2026 | P9: =M9+1 -> 2027 | S9: =P9+1 -> 2028
B10: Código Recurso | D10: Coste/Gasto I+D | E10: Coste/Gasto IT | F10: Coste/Gasto TOTAL | G10: Coste/Gasto I+D | H10: Coste/Gasto IT | I10: Coste/Gasto TOTAL | J10: Coste/Gasto I+D | K10: Coste/Gasto IT | L10: Coste/Gasto TOTAL | M10: Coste/Gasto I+D | N10: Coste/Gasto IT | O10: Coste/Gasto TOTAL | P10: Coste/Gasto I+D | Q10: Coste/Gasto IT | R10: Coste/Gasto TOTAL | S10: Coste/Gasto I+D | T10: Coste/Gasto IT | U10: Coste/Gasto TOTAL
B11: 1 | F11: =SUM(D11:E11) -> 0 | I11: =SUM(G11:H11) -> 0 | L11: =SUM(J11:K11) -> 0 | O11: =SUM(M11:N11) -> 0 | R11: =SUM(P11:Q11) -> 0 | U11: =SUM(S11:T11) -> 0
B12: =B11+1 -> 2 | F12: =SUM(D12:E12) -> 0 | I12: =SUM(G12:H12) -> 0 | L12: =SUM(J12:K12) -> 0 | O12: =SUM(M12:N12) -> 0 | R12: =SUM(P12:Q12) -> 0 | U12: =SUM(S12:T12) -> 0
B13: =B12+1 -> 3 | F13: =SUM(D13:E13) -> 0 | I13: =SUM(G13:H13) -> 0 | L13: =SUM(J13:K13) -> 0 | O13: =SUM(M13:N13) -> 0 | R13: =SUM(P13:Q13) -> 0 | U13: =SUM(S13:T13) -> 0
B14: =B13+1 -> 4 | C14: Amazon Web Services | F14: =SUM(D14:E14) -> 0 | H14: 61683.39 | I14: =SUM(G14:H14) -> 61683.39 | L14: =SUM(J14:K14) -> 0 | O14: =SUM(M14:N14) -> 0 | R14: =SUM(P14:Q14) -> 0 | U14: =SUM(S14:T14) -> 0
B15: =B14+1 -> 5 | F15: =SUM(D15:E15) -> 0 | I15: =SUM(G15:H15) -> 0 | L15: =SUM(J15:K15) -> 0 | O15: =SUM(M15:N15) -> 0 | R15: =SUM(P15:Q15) -> 0 | U15: =SUM(S15:T15) -> 0
B16: =B15+1 -> 6 | F16: =SUM(D16:E16) -> 0 | I16: =SUM(G16:H16) -> 0 | L16: =SUM(J16:K16) -> 0 | O16: =SUM(M16:N16) -> 0 | R16: =SUM(P16:Q16) -> 0 | U16: =SUM(S16:T16) -> 0
B17: =B16+1 -> 7 | F17: =SUM(D17:E17) -> 0 | I17: =SUM(G17:H17) -> 0 | L17: =SUM(J17:K17) -> 0 | O17: =SUM(M17:N17) -> 0 | R17: =SUM(P17:Q17) -> 0 | U17: =SUM(S17:T17) -> 0
B18: =B17+1 -> 8 | F18: =SUM(D18:E18) -> 0 | I18: =SUM(G18:H18) -> 0 | L18: =SUM(J18:K18) -> 0 | O18: =SUM(M18:N18) -> 0 | R18: =SUM(P18:Q18) -> 0 | U18: =SUM(S18:T18) -> 0
B19: =B18+1 -> 9 | F19: =SUM(D19:E19) -> 0 | I19: =SUM(G19:H19) -> 0 | L19: =SUM(J19:K19) -> 0 | O19: =SUM(M19:N19) -> 0 | R19: =SUM(P19:Q19) -> 0 | U19: =SUM(S19:T19) -> 0
B20: =B19+1 -> 10 | F20: =SUM(D20:E20) -> 0 | I20: =SUM(G20:H20) -> 0 | L20: =SUM(J20:K20) -> 0 | O20: =SUM(M20:N20) -> 0 | R20: =SUM(P20:Q20) -> 0 | U20: =SUM(S20:T20) -> 0
B21: =B20+1 -> 11 | F21: =SUM(D21:E21) -> 0 | I21: =SUM(G21:H21) -> 0 | L21: =SUM(J21:K21) -> 0 | O21: =SUM(M21:N21) -> 0 | R21: =SUM(P21:Q21) -> 0 | U21: =SUM(S21:T21) -> 0
B22: =B21+1 -> 12 | F22: =SUM(D22:E22) -> 0 | I22: =SUM(G22:H22) -> 0 | L22: =SUM(J22:K22) -> 0 | O22: =SUM(M22:N22) -> 0 | R22: =SUM(P22:Q22) -> 0 | U22: =SUM(S22:T22) -> 0
B23: =B22+1 -> 13 | F23: =SUM(D23:E23) -> 0 | I23: =SUM(G23:H23) -> 0 | L23: =SUM(J23:K23) -> 0 | O23: =SUM(M23:N23) -> 0 | R23: =SUM(P23:Q23) -> 0 | U23: =SUM(S23:T23) -> 0
B24: =B23+1 -> 14 | F24: =SUM(D24:E24) -> 0 | I24: =SUM(G24:H24) -> 0 | L24: =SUM(J24:K24) -> 0 | O24: =SUM(M24:N24) -> 0 | R24: =SUM(P24:Q24) -> 0 | U24: =SUM(S24:T24) -> 0
B25: =B24+1 -> 15 | F25: =SUM(D25:E25) -> 0 | I25: =SUM(G25:H25) -> 0 | L25: =SUM(J25:K25) -> 0 | O25: =SUM(M25:N25) -> 0 | R25: =SUM(P25:Q25) -> 0 | U25: =SUM(S25:T25) -> 0
B26: =B25+1 -> 16 | F26: =SUM(D26:E26) -> 0 | I26: =SUM(G26:H26) -> 0 | L26: =SUM(J26:K26) -> 0 | O26: =SUM(M26:N26) -> 0 | R26: =SUM(P26:Q26) -> 0 | U26: =SUM(S26:T26) -> 0
... B30: =B29+1 -> 20 | F30: =SUM(D30:E30) -> 0 | I30: =SUM(G30:H30) -> 0 | L30: =SUM(J30:K30) -> 0 | O30: =SUM(M30:N30) -> 0 | R30: =SUM(P30:Q30) -> 0 | U30: =SUM(S30:T30) -> 0
C31: TOTAL | D31: =SUM(D11:D30) -> 0 | E31: =SUM(E11:E30) -> 0 | F31: =D31+E31 -> 0 | G31: =SUM(G11:G30) -> 0 | H31: =SUM(H11:H30) -> 61683.39 | I31: =G31+H31 -> 61683.39 | J31: =SUM(J11:J30) -> 0 | K31: =SUM(K11:K30) -> 0 | L31: =J31+K31 -> 0 | M31: =SUM(M11:M30) -> 0 | N31: =SUM(N11:N30) -> 0 | O31: =M31+N31 -> 0 | P31: =SUM(P11:P30) -> 0 | Q31: =SUM(Q11:Q30) -> 0 | R31: =P31+Q31 -> 0 | S31: =SUM(S11:S30) -> 0 | T31: =SUM(T11:T30) -> 0 | U31: =S31+T31 -> 0

Sheet I+D
B4: PRESUPUESTO EN INVESTIGACIÓN Y DESARROLLO DEL PROYECTO
B7: PRESUPUESTO EN INVESTIGACIÓN Y DESARROLLO DEL PROYECTO (en Euros)
B8: EJERCICIO FISCAL | D8: =Personal!F13 -> 2023 | E8: =D8+1 -> 2024 | F8: =E8+1 -> 2025 | G8: =F8+1 -> 2026 | H8: =G8+1 -> 2027 | I8: =H8+1 -> 2028
B9: Personal aplicado a actividades de I+D+i | D9: =Personal!G51 -> 0 | E9: =Personal!L51 -> 0 | F9: =Personal!Q51 -> 0 | G9: =Personal!V51 -> 0 | H9: =Personal!AA51 -> 0 | I9: =Personal!AF51 -> 0
B10: Personal investigador cualificado de adscripción exclusiva (sólo proyectos I+D) | D10: =Personal!G52 -> 0 | E10: =Personal!L52 -> 0 | F10: =Personal!Q52 -> 0 | G10: =Personal!V52 -> 0 | H10: =Personal!AA52 -> 0 | I10: =Personal!AF52 -> 0
B11: Amortización de elementos de inmovilizado material e intangible | D11: ='El._inmovilizado (AMORTIZACIÓN)'!D32 -> 0 | E11: ='El._inmovilizado (AMORTIZACIÓN)'!G32 -> 0 | F11: ='El._inmovilizado (AMORTIZACIÓN)'!J32 -> 0 | G11: ='El._inmovilizado (AMORTIZACIÓN)'!M32 -> 0 | H11: ='El._inmovilizado (AMORTIZACIÓN)'!P32 -> 0 | I11: ='El._inmovilizado (AMORTIZACIÓN)'!S32 -> 0
B12: Material fungible | D12: =Fungibles!D31 -> 0 | E12: =Fungibles!G31 -> 0 | F12: =Fungibles!J31 -> 0 | G12: =Fungibles!M31 -> 0 | H12: =Fungibles!P31 -> 0 | I12: =Fungibles!S31 -> 0
B13: Colaboraciones Externas: Universidades, OPIs y/o CITs | D13: ='C.Externas (OPIS)'!F40 -> 0 | E13: ='C.Externas (OPIS)'!I40 -> 0 | F13: ='C.Externas (OPIS)'!L40 -> 0 | G13: ='C.Externas (OPIS)'!O40 -> 0 | H13: ='C.Externas (OPIS)'!R40 -> 0 | I13: ='C.Externas (OPIS)'!U40 -> 0
B14: Otras colaboraciones externas | D14: ='C.Externas (Otros)'!E37 -> 0 | E14: ='C.Externas (Otros)'!H37 -> 0 | F14: ='C.Externas (Otros)'!K37 -> 0 | G14: ='C.Externas (Otros)'!N37 -> 0 | H14: ='C.Externas (Otros)'!Q37 -> 0 | I14: ='C.Externas (Otros)'!T37 -> 0
B15: Otros gastos | D15: ='Otros Gastos'!D31 -> 0 | E15: ='Otros Gastos'!G31 -> 0 | F15: ='Otros Gastos'!J31 -> 0 | G15: ='Otros Gastos'!M31 -> 0 | H15: ='Otros Gastos'!P31 -> 0 | I15: ='Otros Gastos'!S31 -> 0
B16: TOTAL COSTES / GASTOS | D16: =SUM(D9:D15) -> 0 | E16: =SUM(E9:E15) -> 0 | F16: =SUM(F9:F15) -> 0 | G16: =SUM(G9:G15) -> 0 | H16: =SUM(H9:H15) -> 0 | I16: =SUM(I9:I15) -> 0
B18: TOTAL INVERSIÓN EN ELEMENTOS DE INMOVILIZADO MATERIAL E INTANGIBLE | D18: ='El._inmovilizado (INVERSIÓN)'!D31 -> 0 | E18: ='El._inmovilizado (INVERSIÓN)'!G31 -> 0 | F18: ='El._inmovilizado (INVERSIÓN)'!J31 -> 0 | G18: ='El._inmovilizado (INVERSIÓN)'!M31 -> 0 | H18: ='El._inmovilizado (INVERSIÓN)'!P31 -> 0 | I18: ='El._inmovilizado (INVERSIÓN)'!S31 -> 0

Sheet iT
B4: PRESUPUESTO EN INNOVACIÓN TECNOLÓGICA DEL PROYECTO
B7: PRESUPUESTO EN INNOVACIÓN TECNOLÓGICA DEL PROYECTO (en Euros)
B8: EJERCICIO FISCAL | D8: =Personal!F13 -> 2023 | E8: =D8+1 -> 2024 | F8: =E8+1 -> 2025 | G8: =F8+1 -> 2026 | H8: =G8+1 -> 2027 | I8: =H8+1 -> 2028
B9: Personal aplicado a actividades de I+D+i | D9: =Personal!I51 -> 977621.55 | E9: =Personal!N51 -> 884669.6 | F9: =Personal!S51 -> 1073309.2 | G9: =Personal!X51 -> 0 | H9: =Personal!AC51 -> 0 | I9: =Personal!AH51 -> 0
B10: Personal investigador cualificado de adscripción exclusiva (sólo proyectos I+D)
B11: Amortización de elementos de inmovilizado material e intangible | D11: ='El._inmovilizado (AMORTIZACIÓN)'!E32 -> 0 | E11: ='El._inmovilizado (AMORTIZACIÓN)'!H32 -> 0 | F11: ='El._inmovilizado (AMORTIZACIÓN)'!K32 -> 0 | G11: ='El._inmovilizado (AMORTIZACIÓN)'!N32 -> 0 | H11: ='El._inmovilizado (AMORTIZACIÓN)'!Q32 -> 0 | I11: ='El._inmovilizado (AMORTIZACIÓN)'!T32 -> 0
B12: Material fungible | D12: =Fungibles!E31 -> 0 | E12: =Fungibles!H31 -> 0 | F12: =Fungibles!K31 -> 0 | G12: =Fungibles!N31 -> 0 | H12: =Fungibles!Q31 -> 0 | I12: =Fungibles!T31 -> 0
B13: Colaboraciones Externas: Universidades, OPIs y/o CITs | D13: ='C.Externas (OPIS)'!G40 -> 0 | E13: ='C.Externas (OPIS)'!J40 -> 0 | F13: ='C.Externas (OPIS)'!M40 -> 0 | G13: ='C.Externas (OPIS)'!P40 -> 0 | H13: ='C.Externas (OPIS)'!S40 -> 0 | I13: ='C.Externas (OPIS)'!V40 -> 0
B14: Otras colaboraciones externas | D14: ='C.Externas (Otros)'!F37 -> 31738.29 | E14: ='C.Externas (Otros)'!I37 -> 20330.78 | F14: ='C.Externas (Otros)'!L37 -> 24880.89 | G14: ='C.Externas (Otros)'!O37 -> 0 | H14: ='C.Externas (Otros)'!R37 -> 0 | I14: ='C.Externas (Otros)'!U37 -> 0
B15: Otros gastos | D15: ='Otros Gastos'!E31 -> 0 | E15: ='Otros Gastos'!H31 -> 61683.39 | F15: ='Otros Gastos'!K31 -> 0 | G15: ='Otros Gastos'!N31 -> 0 | H15: ='Otros Gastos'!Q31 -> 0 | I15: ='Otros Gastos'!T31 -> 0
B16: TOTAL COSTES / GASTOS | D16: =SUM(D9:D15) -> 1009359.8 | E16: =SUM(E9:E15) -> 966683.77 | F16: =SUM(F9:F15) -> 1098190.1 | G16: =SUM(G9:G15) -> 0 | H16: =SUM(H9:H15) -> 0 | I16: =SUM(I9:I15) -> 0

Sheet TOTAL
B4: PRESUPUESTO TOTAL DEL PROYECTO
B7: PRESUPUESTO TOTAL DEL PROYECTO (en Euros)
B9: EJERCICIO FISCAL | D9: =Personal!F13 -> 2023 | E9: =D9+1 -> 2024 | F9: =E9+1 -> 2025 | G9: =F9+1 -> 2026 | H9: =G9+1 -> 2027 | I9: =H9+1 -> 2028
B10: Personal aplicado a actividades de I+D+i | D10: ='I+D'!D9+iT!D9 -> 977621.55 | E10: ='I+D'!E9+iT!E9 -> 884669.6 | F10: ='I+D'!F9+iT!F9 -> 1073309.2 | G10: ='I+D'!G9+iT!G9 -> 0 | H10: ='I+D'!H9+iT!H9 -> 0 | I10: ='I+D'!I9+iT!I9 -> 0
B11: Personal investigador cualificado de adscripción exclusiva (sólo proyectos I+D) | D11: ='I+D'!D10+iT!D10 -> 0 | E11: ='I+D'!E10+iT!E10 -> 0 | F11: ='I+D'!F10+iT!F10 -> 0 | G11: ='I+D'!G10+iT!G10 -> 0 | H11: ='I+D'!H10+iT!H10 -> 0 | I11: ='I+D'!I10+iT!I10 -> 0
B12: Amortización de elementos de inmovilizado material e intangible | D12: ='I+D'!D11+iT!D11 -> 0 | E12: ='I+D'!E11+iT!E11 -> 0 | F12: ='I+D'!F11+iT!F11 -> 0 | G12: ='I+D'!G11+iT!G11 -> 0 | H12: ='I+D'!H11+iT!H11 -> 0 | I12: ='I+D'!I11+iT!I11 -> 0
B13: Material fungible | D13: ='I+D'!D12+iT!D12 -> 0 | E13: ='I+D'!E12+iT!E12 -> 0 | F13: ='I+D'!F12+iT!F12 -> 0 | G13: ='I+D'!G12+iT!G12 -> 0 | H13: ='I+D'!H12+iT!H12 -> 0 | I13: ='I+D'!I12+iT!I12 -> 0
B14: Colaboraciones Externas: Universidades, OPIs y/o CITs | D14: ='I+D'!D13+iT!D13 -> 0 | E14: ='I+D'!E13+iT!E13 -> 0 | F14: ='I+D'!F13+iT!F13 -> 0 | G14: ='I+D'!G13+iT!G13 -> 0 | H14: ='I+D'!H13+iT!H13 -> 0 | I14: ='I+D'!I13+iT!I13 -> 0
B15: Otras colaboraciones externas | D15: ='I+D'!D14+iT!D14 -> 31738.29 | E15: ='I+D'!E14+iT!E14 -> 20330.78 | F15: ='I+D'!F14+iT!F14 -> 24880.89 | G15: ='I+D'!G14+iT!G14 -> 0 | H15: ='I+D'!H14+iT!H14 -> 0 | I15: ='I+D'!I14+iT!I14 -> 0
B16: Otros gastos | D16: ='I+D'!D15+iT!D15 -> 0 | E16: ='I+D'!E15+iT!E15 -> 61683.39 | F16: ='I+D'!F15+iT!F15 -> 0 | G16: ='I+D'!G15+iT!G15 -> 0 | H16: ='I+D'!H15+iT!H15 -> 0 | I16: ='I+D'!I15+iT!I15 -> 0
B17: TOTAL COSTES / GASTOS | D17: =SUM(D10:D16) -> 1009359.8 | E17: =SUM(E10:E16) -> 966683.77 | F17: =SUM(F10:F16) -> 1098190.1 | G17: =SUM(G10:G16) -> 0 | H17: =SUM(H10:H16) -> 0 | I17: =SUM(I10:I16) -> 0
B19: TOTAL INVERSIÓN EN ELEMENTOS DE INMOVILIZADO MATERIAL E INTANGIBLE | D19: ='El._inmovilizado (INVERSIÓN)'!D31 -> 0 | E19: ='El._inmovilizado (INVERSIÓN)'!G31 -> 0 | F19: ='El._inmovilizado (INVERSIÓN)'!J31 -> 0 | G19: ='El._inmovilizado (INVERSIÓN)'!M31 -> 0 | H19: ='El._inmovilizado (INVERSIÓN)'!P31 -> 0 | I19: ='El._inmovilizado (INVERSIÓN)'!S31 -> 0

Sheet DESVIACIONES
A3: FICHA DE DESVIACIONES (sólo en caso de solicitud de informe del tipo a)
A5: ENUMERACIÓN DE LAS DESVIACIONES SUPERIORES AL 20% DEL PRESUPUESTO DEL PROYECTO:
A7: Nº | B7: CONCEPTO | C7: IDENTIFICACIÓN | D7: Presupuesto de Proyecto | G7: Efectivamente Incurrido | J7: Porcentaje
B8: (Personal, Colaboraciones, etc.) | C8: (Nombre de la persona, entidad, material, etc.) | D8: Coste/Gasto I+D | E8: Coste/Gasto IT | F8: Coste/Gasto total | G8: Coste/Gasto I+D | H8: Coste/Gasto IT | I8: Coste/Gasto total | J8: (%)
A9: 1 | B9: Personal aplicado a actividades de I+D+i | E9: 1063639.7 | F9: =SUM(D9:E9) -> 1063639.7 | H9: =TOTAL!E10 -> 884669.6 | I9: =SUM(G9:H9) -> 884669.6 | J9: =IF(F9=0,"",(I9-F9)/F9*100) -> -16.826198
A10: 2 | B10: Personal investigador cualificado y en exclusiva a I+D | F10: =SUM(D10:E10) -> 0 | H10: =TOTAL!E11 -> 0 | I10: =SUM(G10:H10) -> 0 | J10: =IF(F10=0,"",(I10-F10)/F10*100)
A11: 3 | B11: Amortización de elementos de inmovilizado material e Intangible | F11: =SUM(D11:E11) -> 0 | H11: =TOTAL!E12 -> 0 | I11: =SUM(G11:H11) -> 0 | J11: =IF(F11=0,"",(I11-F11)/F11*100)
A12: 4 | B12: Material fungible | F12: =SUM(D12:E12) -> 0 | H12: =TOTAL!E13 -> 0 | I12: =SUM(G12:H12) -> 0 | J12: =IF(F12=0,"",(I12-F12)/F12*100)
A13: 5 | B13: Colaboraciones Externas: Universidades, OPIs y/o CITs | F13: =SUM(D13:E13) -> 0 | H13: =TOTAL!E14 -> 0 | I13: =SUM(G13:H13) -> 0 | J13: =IF(F13=0,"",(I13-F13)/F13*100)
A14: 6 | B14: Otras colaboraciones externas | E14: 34912.12 | F14: =SUM(D14:E14) -> 34912.12 | H14: =TOTAL!E15 -> 20330.78 | I14: =SUM(G14:H14) -> 20330.78 | J14: =IF(F14=0,"",(I14-F14)/F14*100) -> -41.765839
A15: 7 | B15: Otros gastos | E15: 0 | F15: =SUM(D15:E15) -> 0 | H15: =TOTAL!E16 -> 61683.39 | I15: =SUM(G15:H15) -> 61683.39 | J15: =IF(F15=0,"",(I15-F15)/F15*100)
A16: TOTAL | D16: =SUM(D9:D15) -> 0 | E16: =SUM(E9:E15) -> 1098551.8 | F16: =SUM(F9:F15) -> 1098551.8 | G16: =SUM(G9:G15) -> 0 | H16: =SUM(H9:H15) -> 966683.77 | I16: =SUM(I9:I15) -> 966683.77 | J16: =IF(F16=0,"",(I16-F16)/F16*100) -> -12.003809

Sheet DOC JUSTIFICATIVOS
C3: LISTADO DE LOS DOCUMENTOS JUSTIFICATIVOS DE LOS GASTOS O COSTES INCURRIDOS EN EL PROYECTO
C5: Nº | E5: NOMBRE | F5: Nº/TIPO DE DOCUMENTO | G5: FECHA | H5: TITULACIÓN | I5: IMPORTE (€)
I6: I+D | J6: IT | K6: TOTAL
C8: Personal aplicado a actividades de I+D+i
C9: 1 | E9: =Personal!C15 -> ALEJANDRO NAVALON FERNANDEZ | F9: RNT - IDC - CCRR | G9: 2024 | H9: =Personal!D15 -> Licenciado en Ingenería Informática | J9: 42747.6 | K9: =I9+J9 -> 42747.6
C10: =C9+1 -> 2 | E10: =Personal!C16 -> ANDRES QUESADA MOLINERO | F10: RNT - IDC - CCRR | G10: 2024 | H10: =Personal!D16 -> Diplomado en Ingenería Informática | J10: 45528.5 | K10: =I10+J10 -> 45528.5
C11: =C10+1 -> 3 | E11: =Personal!C17 -> CRISTIAN PALAU TARRAGO | F11: RNT - IDC - CCRR | G11: 2024 | H11: =Personal!D17 -> Graduado en Ingenería Informática | J11: 40678.2 | K11: =I11+J11 -> 40678.2
C12: =C11+1 -> 4 | E12: =Personal!C18 -> DANIEL CLARES MARTIN | F12: RNT - IDC - CCRR | G12: 2024 | H12: =Personal!D18 -> Grado superior en aplicaciones web | J12: 20312.5 | K12: =I12+J12 -> 20312.5
C13: =C12+1 -> 5 | E13: =Personal!C19 -> DANIEL GUASCH PARRA | F13: RNT - IDC - CCRR | G13: 2024 | H13: =Personal!D19 -> Grado superior en aplicaciones web | J13: 25110 | K13: =I13+J13 -> 25110
C14: =C13+1 -> 6 | E14: =Personal!C20 -> DAVID MARTINEZ PLANELLAS | F14: RNT - IDC - CCRR | G14: 2024 | H14: =Personal!D20 -> Ingeniero técnico informático | J14: 11679.3 | K14: =I14+J14 -> 11679.3
C15: =C14+1 -> 7 | E15: =Personal!C21 -> DIDAC FERRER MARDONES | F15: RNT - IDC - CCRR | G15: 2024 | H15: =Personal!D21 -> Grado superior en administración de sistemas | J15: 32520.5 | K15: =I15+J15 -> 32520.5
C16: =C15+1 -> 8 | E16: =Personal!C22 -> DIEGO JAVIER KORMES | F16: RNT - IDC - CCRR | G16: 2024 | H16: =Personal!D22 -> Licenciado en Biología | J16: 47610.2 | K16: =I16+J16 -> 47610.2
C17: =C16+1 -> 9 | E17: =Personal!C23 -> ELOI VIVAS MARTINEZ | F17: RNT - IDC - CCRR | G17: 2024 | H17: =Personal!D23 -> CFGS Desarrollo de Aplicaciones Multiplataforma | J17: 35568 | K17: =I17+J17 -> 35568
C18: =C17+1 -> 10 | E18: =Personal!C24 -> ERIK MOMPEAN RUIZ | F18: RNT - IDC - CCRR | G18: 2024 | H18: =Personal!D24 -> Grado superior en aplicaciones multiplataforma | J18: 38443.35 | K18: =I18+J18 -> 38443.35
C19: =C18+1 -> 11 | E19: =Personal!C25 -> EYNAR ARNEZ ANDRADE | F19: RNT - IDC - CCRR | G19: 2024 | H19: =Personal!D25 -> Grado superior Ingeniería Informatica | J19: 23101.2 | K19: =I19+J19 -> 23101.2
C20: =C19+1 -> 12 | E20: =Personal!C26 -> FRANCISCO JAVIE GINE VENTURA | F20: RNT - IDC - CCRR | G20: 2024 | H20: =Personal!D26 -> Grado superior Ingeniería Informatica | J20: 12860 | K20: =I20+J20 -> 12860
C21: =C20+1 -> 13 | E21: =Personal!C27 -> JAVIER ALEJANDRO FUENTES | F21: RNT - IDC - CCRR | G21: 2024 | H21: =Personal!D27 -> Diplomado en Analista de Sistemas | J21: 37002 | K21: =I21+J21 -> 37002
C22: =C21+1 -> 14 | E22: =Personal!C28 -> JAVIER ENRIQUE PINTO GONÇALVES | F22: RNT - IDC - CCRR | G22: 2024 | H22: =Personal!D28 -> Graduado en Ingenería Informática | J22: 45667.2 | K22: =I22+J22 -> 45667.2
C23: =C22+1 -> 15 | E23: =Personal!C29 -> JAVIER PILLADO DOPICO | F23: RNT - IDC - CCRR | G23: 2024 | H23: Graduado en Ingeniería Informática | J23: 28893.2 | K23: =I23+J23 -> 28893.2
C24: =C23+1 -> 16 | E24: =Personal!C30 -> JEFFREY JOSE SOARES AFONSO | F24: RNT - IDC - CCRR | G24: 2024 | H24: =Personal!D30 -> Graduado en Ingenería Informática | J24: 25556.25 | K24: =I24+J24 -> 25556.25
C25: =C24+1 -> 17 | E25: =Personal!C31 -> JESSICA PLA GARCIA | F25: RNT - IDC - CCRR | G25: 2024 | H25: =Personal!D31 -> Graduado en Ingenería Informática | J25: 15730 | K25: =I25+J25 -> 15730
C26: =C25+1 -> 18 | E26: =Personal!C32 -> JORDI AVILES MARTOS | F26: RNT - IDC - CCRR | G26: 2024 | H26: =Personal!D32 -> CFGS Desarrollo de Aplicaciones Multiplataforma | J26: 5507.5 | K26: =I26+J26 -> 5507.5
C27: =C26+1 -> 19 | E27: =Personal!C33 -> JUAN ANTONIO LAMA SAENZ | F27: RNT - IDC - CCRR | G27: 2024 | H27: =Personal!D33 -> Diplomado en Ingenería Informática | J27: 83102.15 | K27: =I27+J27 -> 83102.15
C28: =C27+1 -> 20 | E28: =Personal!C34 -> JUAN GARCIA MURILLO | F28: RNT - IDC - CCRR | G28: 2024 | H28: =Personal!D34 -> Diplomado en Ingenería Informática | J28: 39270 | K28: =I28+J28 -> 39270
C29: =C28+1 -> 21 | E29: =Personal!C35 -> LAURA ARROYO SANCHEZ | F29: RNT - IDC - CCRR | G29: 2024 | H29: =Personal!D35 -> Licenciada en Ingenería Informática | J29: 23840 | K29: =I29+J29 -> 23840
C30: =C29+1 -> 22 | E30: =Personal!C36 -> LUCIANO BURGOS LOMBARDI | F30: RNT - IDC - CCRR | G30: 2024 | H30: =Personal!D36 -> Graduado en Física | J30: 16946.3 | K30: =I30+J30 -> 16946.3
C31: =C30+1 -> 23 | E31: =Personal!C37 -> LUIS CASAMAJOR PALOMA | F31: RNT - IDC - CCRR | G31: 2024 | H31: =Personal!D37 -> CFGS Desarrollo de Aplicaciones Multiplataforma | J31: 28186.5 | K31: =I31+J31 -> 28186.5
C32: =C31+1 -> 24 | E32: =Personal!C38 -> MARC MATEO PRATS | F32: RNT - IDC - CCRR | G32: 2024 | H32: =Personal!D38 -> Grado en Ingenería Informática | J32: 16648.8 | K32: =I32+J32 -> 16648.8
C33: =C32+1 -> 25 | E33: =Personal!C39 -> MARTA TOMAS PARIS | F33: RNT - IDC - CCRR | G33: 2024 | H33: =Personal!D39 -> Diplomado en Ingenería Informática | J33: 33888.4 | K33: =I33+J33 -> 33888.4
C34: =C33+1 -> 26 | E34: =Personal!C40 -> ORIOL BERNADAS CIURANA | F34: RNT - IDC - CCRR | G34: 2024 | H34: =Personal!D40 -> Grado superior en aplicaciones web | J34: 33915 | K34: =I34+J34 -> 33915
C35: =C34+1 -> 27 | E35: =Personal!C41 -> POL CAMPS CASTRO | F35: RNT - IDC - CCRR | G35: 2024 | H35: =Personal!D41 -> Grado de Ingeniería en Tecnologias Industriales | J35: 22762.95 | K35: =I35+J35 -> 22762.95
... C37: =C36+1 -> 29 | E37: =Personal!C43 -> VICTOR GOMEZ REYES | F37: RNT - IDC - CCRR | G37: 2024 | H37: =Personal!D43 -> Licenciado en Ingenería Informática | J37: 35958 | K37: =I37+J37 -> 35958
C38: Total | I38: =SUM(I9:I37) -> 0 | J38: =SUM(J9:J37) -> 884669.6 | K38: =SUM(K9:K37) -> 884669.6
C40: Personal Investigador cualificado y aplicado en exclusiva a actividades de I+D
C41: 1 | K41: =I41 -> 0
C42: =C41+1 -> 2 | K42: =I42 -> 0
C43: =C42+1 -> 3 | K43: =I43 -> 0
C44: =C43+1 -> 4 | K44: =I44 -> 0
C45: =C44+1 -> 5 | K45: =I45 -> 0
C46: =C45+1 -> 6 | K46: =I46 -> 0
...
