Workbook

Sheet Datos solicitud
B3: DATOS RELATIVOS A LA SOLICITUD DE INFORME MOTIVADO
B5: RAZÓN SOCIAL ENTIDAD: | E5: ORANGE ESPAGNE S.A.U
B7: TÍTULO DEL PROYECTO: | E7: INTOPQUERE
B10: EJERCICIO FISCAL DE SOLICITUD (dd/mm/aaaa): | E10: FECHA INICIO: | F10: 44197 | G10: FECHA FIN: | H10: 44561
B12: AÑO DE INICIO DEL PROYECTO: | E12: 2021
B14: Nº DE EXPEDIENTE (INFORME MOTIVADO):

Sheet Instrucciones
B3: INSTRUCCIONES
B5: 1- Debe entregarse un único documento PDF que incluya, por lo menos, todas las Hojas del Formulario donde se hayan introducido datos. Las Hojas deben presentarse en el orden establecido en esta plantilla. La primera página del PDF debe ser la Hoja 'Datos solicitud' con los datos de la solicitante. No agregue al documento PDF resultante otras páginas diferentes a las expuestas en este Formulario. No es necesario que la presente Hoja con instrucciones se incluya en el PDF resultante que ha de entregarse, pero, si se muestra, debe ser escalada ajustando la hoja en una única página. Deben seguirse las instrucciones concretas marcadas en fuente roja que se exponen al inicio de algunas de las Hojas del Formulario. Las Hojas 'I+D' e 'IT' deberán ser incluidas en función de la calificación que haya sido consignada en las Hojas restantes. La Hoja 'TOTAL' debe ser incluida obligatoriamente en todos los casos. 2- Para solicitudes tipo 'A' es obligatorio incluir la Hoja con la “Ficha de desviaciones” y describir aquellas desviaciones que sean superiores al 20%. Así mismo, para solicitudes tipo 'A' es obligatorio incluir la Hoja con el Listado de documentos justificativos de los gastos correctamente cumplimentado en cada fila/celda (incluso para los Formularios "adicionales" que deben presentarse en solicitudes de AIEs). 3- En cada Hoja, deben añadirse tantas filas como se consideren necesarias. En cada fila añadida deben reproducirse las Fórmulas existentes en la Hoja para que se efectúen los cálculos automáticos. No deben realizarse modificaciones en las Fórmulas. Debe respetarse la estructura general del Formulario. No elimine las Filas que no utilice, deje en blanco las que no considere oportunas. 4- Los gastos reflejados en cada una de las Hojas deben guardar correspondencia entre sí. A su vez, los gastos mostrados en el presente Formulario deben coincidir con los 'Gastos Presentados/Presupuestados' que se muestren en el 'Informe Técnico de la EC' y en el 'Informe Técnico XSIG (XML)' que deben acompañar a su Solicitud. Es decir, deben mostrarse los valores de los gastos presentados a Certificación, no los gastos resultantes de dicha Certificación (salvo que sean idénticos). De igual forma, los gastos mostrados deben coincidir con los 'Gastos Presentados/Presupuestados' que se muestren en la Memoria Técnica/Económica. 5- Si el proyecto tiene una duración mayor de 6 anualidades, deberán entregarse dos o más Formularios. Uno que abarque las anualidades 1-6, otro 7-12, y así sucesivamente. En estos casos, en cada Formulario deberá indicarse como 'Año de Inicio' el primero de los años empleados en ese rango. En cualquier caso, no se deben añadir/eliminar columnas. 6- Los datos del Ejercicio fiscal y del Título del proyecto deben responder con exactitud a lo asociado a la solicitud de informe motivado. El Título no puede superar los 100 caracteres. 7- Debe respetarse la estructura y el formato del documento. El contenido descriptivo de cada línea de gasto ha de ser reflejado obligatoriamente en Castellano, incluyendo los campos 'Concepto' y 'Titulación' del 'Listado de los documentos justificativos...'. No se admite incluir más de 400 caracteres en cada uno de los campos del Formulario. Si se incluyen más de 400 caracteres el documento no se considerará válido. 8- En el campo 'CONCEPTO' de cada Línea de gasto (incluyendo al 'Listado de los documentos justificativos...') deberá describirse sintéticamente el gasto, sin limitarse a una mera descripción genérica como “servicios profesionales”, “materiales varios”, “gastos según pedido X”, etc.). Es decir, el contenido de cada Fila ha de ser representativo del Gasto asociado. 9- Al transformar el documento en PDF se debe asegurar que el contenido incluido en las celdas no se oculta en la transformación, ya que, en dicho caso, el documento no se considerará válido. Si es necesario se pueden separar las Filas de una tabla en diferentes páginas, pero NO se admite separar las Columnas de una misma tabla en diferentes páginas. Verifique que, para cada tabla, se muestran todas las columnas. 10- En caso de tratarse de un Formulario "adicional", en el campo "Razón social entidad", a la derecha del dato de la AIE solicitante, se debe reflejar entre paréntesis, la Razón Social de la entidad subcontratada de la que se aporta el Formulario "adicional".

Sheet Personal
B4: 2.1 PERSONAL INVESTIGADOR
B6: - Para anualidades futuras, si el nombre de la persona aún no se conoce, en lugar del "NOMBRE" se reflejará el Perfil dentro del proyecto.
B8: - En la columna 'Excl I+D`se indicará si se trata o no de un investigador adscrito en exclusiva a I+D
B10: - Por cada uno de los participantes en el proyecto, se cumplimentará su correspondiente Ficha de ampliación del apartado 2.1.
B13: Código Persona | C13: Nombre y Apellidos | D13: Titulación | E13: Excl I+D (SÍ/NO) | F13: ='Datos solicitud'!E12 -> 2021 | K13: =F13+1 -> 2022 | P13: =K13+1 -> 2023 | U13: =P13+1 -> 2024 | Z13: =U13+1 -> 2025 | AE13: =Z13+1 -> 2026
F14: Horas imputadas I+D | G14: Coste/Gasto I+D | H14: Horas imputadas IT | I14: Coste/Gasto IT | J14: Coste/Gasto TOTAL | K14: Horas imputadas I+D | L14: Coste/Gasto I+D | M14: Horas imputadas IT | N14: Coste/Gasto IT | O14: Coste/Gasto TOTAL | P14: Horas imputadas I+D | Q14: Coste/Gasto I+D | R14: Horas imputadas IT | S14: Coste/Gasto IT | T14: Coste/Gasto TOTAL | U14: Horas imputadas I+D | V14: Coste/Gasto I+D | W14: Horas imputadas IT | X14: Coste/Gasto IT | Y14: Coste/Gasto TOTAL | Z14: Horas imputadas I+D | AA14: Coste/Gasto I+D | AB14: Horas imputadas IT | AC14: Coste/Gasto IT | AD14: Coste/Gasto TOTAL | AE14: Horas imputadas I+D | AF14: Coste/Gasto I+D | AG14: Horas imputadas IT | AH14: Coste/Gasto IT | AI14: Coste/Gasto TOTAL
B15: 1 | C15: ALBERTO MARGAÑON MENDEZ | D15: Ingeniero Superior en Organización Industrial | E15: NO | H15: 1653 | I15: 68037.48 | J15: =G15+I15 -> 68037.48 | O15: =L15+N15 -> 0 | T15: =Q15+S15 -> 0 | Y15: =V15+X15 -> 0 | AD15: =AA15+AC15 -> 0 | AI15: =AF15+AH15 -> 0
B16: =B15+1 -> 2 | C16: ANTONIO PULIDO RUIZ | D16: Ingeniero de Telecomunicaciones | E16: NO | H16: 1280.4 | I16: 42547.69 | J16: =G16+I16 -> 42547.69 | O16: =L16+N16 -> 0 | T16: =Q16+S16 -> 0 | Y16: =V16+X16 -> 0 | AD16: =AA16+AC16 -> 0 | AI16: =AF16+AH16 -> 0
B17: =B16+1 -> 3 | C17: BERNARDO PEREZ DOMINGUEZ | D17: Ingeniero de Telecomunicaciones | E17: NO | H17: 1653 | I17: 63772.74 | J17: =G17+I17 -> 63772.74 | O17: =L17+N17 -> 0 | T17: =Q17+S17 -> 0 | Y17: =V17+X17 -> 0 | AD17: =AA17+AC17 -> 0 | AI17: =AF17+AH17 -> 0
B18: =B17+1 -> 4 | C18: CALOGERO AVOLA | D18: Ingeniería electrónica y de Comunicaciones | E18: NO | H18: 1653 | I18: 64169.46 | J18: =G18+I18 -> 64169.46 | O18: =L18+N18 -> 0 | T18: =Q18+S18 -> 0 | Y18: =V18+X18 -> 0 | AD18: =AA18+AC18 -> 0 | AI18: =AF18+AH18 -> 0
B19: =B18+1 -> 5 | C19: JOSE LUIS VILLARRUBIA TEJERO | D19: Ingeniero de Telecomunicaciones | E19: NO | H19: 1440.73 | I19: 45397.4 | J19: =G19+I19 -> 45397.4 | O19: =L19+N19 -> 0 | T19: =Q19+S19 -> 0 | Y19: =V19+X19 -> 0 | AD19: =AA19+AC19 -> 0 | AI19: =AF19+AH19 -> 0
B20: =B19+1 -> 6 | C20: JOSE RAMON ARNAU RAMIREZ | D20: CFGS Electrónica | E20: NO | H20: 1431.7 | I20: 52171.15 | J20: =G20+I20 -> 52171.15 | O20: =L20+N20 -> 0 | T20: =Q20+S20 -> 0 | Y20: =V20+X20 -> 0 | AD20: =AA20+AC20 -> 0 | AI20: =AF20+AH20 -> 0
B21: =B20+1 -> 7 | C21: JULIAN GODINO GUTIERREZ | D21: Ingeniería Informática | E21: NO | H21: 1653 | I21: 58631.91 | J21: =G21+I21 -> 58631.91 | O21: =L21+N21 -> 0 | T21: =Q21+S21 -> 0 | Y21: =V21+X21 -> 0 | AD21: =AA21+AC21 -> 0 | AI21: =AF21+AH21 -> 0
B22: =B21+1 -> 8 | C22: MIGUEL ANGEL FERREIRO RODRIGUEZ | D22: Ingeniero Superior Telecomunicación | E22: NO | H22: 831.97 | I22: 54177.89 | J22: =G22+I22 -> 54177.89 | O22: =L22+N22 -> 0 | T22: =Q22+S22 -> 0 | Y22: =V22+X22 -> 0 | AD22: =AA22+AC22 -> 0 | AI22: =AF22+AH22 -> 0
B23: =B22+1 -> 9 | C23: SUSANA ALVAREZ GONZALEZ | D23: Ingeniero Técnico industrial, especialidad Eléctrica | E23: NO | H23: 1653 | I23: 62417.28 | J23: =G23+I23 -> 62417.28 | O23: =L23+N23 -> 0 | T23: =Q23+S23 -> 0 | Y23: =V23+X23 -> 0 | AD23: =AA23+AC23 -> 0 | AI23: =AF23+AH23 -> 0
B24: =B23+1 -> 10 | E24: NO | J24: =G24+I24 -> 0 | O24: =L24+N24 -> 0 | T24: =Q24+S24 -> 0 | Y24: =V24+X24 -> 0 | AD24: =AA24+AC24 -> 0 | AI24: =AF24+AH24 -> 0
B25: =B24+1 -> 11 | C25: Personal 2022 | E25: NO | J25: =G25+I25 -> 0 | M25: 14299.73 | N25: 572889.74 | O25: =L25+N25 -> 572889.74 | T25: =Q25+S25 -> 0 | Y25: =V25+X25 -> 0 | AD25: =AA25+AC25 -> 0 | AI25: =AF25+AH25 -> 0
B26: =B25+1 -> 12 | C26: Personal 2023 | E26: NO | J26: =G26+I26 -> 0 | O26: =L26+N26 -> 0 | R26: 14299.73 | S26: 615985.37 | T26: =Q26+S26 -> 615985.37 | Y26: =V26+X26 -> 0 | AD26: =AA26+AC26 -> 0 | AI26: =AF26+AH26 -> 0
B27: =B26+1 -> 13 | C27: Personal 2024 | E27: NO | J27: =G27+I27 -> 0 | O27: =L27+N27 -> 0 | T27: =Q27+S27 -> 0 | W27: 15337.81 | X27: 717312.07 | Y27: =V27+X27 -> 717312.07 | AD27: =AA27+AC27 -> 0 | AI27: =AF27+AH27 -> 0
B28: =B27+1 -> 14 | E28: NO | J28: =G28+I28 -> 0 | O28: =L28+N28 -> 0 | T28: =Q28+S28 -> 0 | Y28: =V28+X28 -> 0 | AD28: =AA28+AC28 -> 0 | AI28: =AF28+AH28 -> 0
B29: =B28+1 -> 15 | E29: NO | J29: =G29+I29 -> 0 | O29: =L29+N29 -> 0 | T29: =Q29+S29 -> 0 | Y29: =V29+X29 -> 0 | AD29: =AA29+AC29 -> 0 | AI29: =AF29+AH29 -> 0
B30: =B29+1 -> 16 | E30: NO | J30: =G30+I30 -> 0 | O30: =L30+N30 -> 0 | T30: =Q30+S30 -> 0 | Y30: =V30+X30 -> 0 | AD30: =AA30+AC30 -> 0 | AI30: =AF30+AH30 -> 0
B31: =B30+1 -> 17 | E31: NO | J31: =G31+I31 -> 0 | O31: =L31+N31 -> 0 | T31: =Q31+S31 -> 0 | Y31: =V31+X31 -> 0 | AD31: =AA31+AC31 -> 0 | AI31: =AF31+AH31 -> 0
B32: =B31+1 -> 18 | E32: NO | J32: =G32+I32 -> 0 | O32: =L32+N32 -> 0 | T32: =Q32+S32 -> 0 | Y32: =V32+X32 -> 0 | AD32: =AA32+AC32 -> 0 | AI32: =AF32+AH32 -> 0
B33: =B32+1 -> 19 | E33: NO | J33: =G33+I33 -> 0 | O33: =L33+N33 -> 0 | T33: =Q33+S33 -> 0 | Y33: =V33+X33 -> 0 | AD33: =AA33+AC33 -> 0 | AI33: =AF33+AH33 -> 0
B34: =B33+1 -> 20 | E34: NO | J34: =G34+I34 -> 0 | O34: =L34+N34 -> 0 | T34: =Q34+S34 -> 0 | Y34: =V34+X34 -> 0 | AD34: =AA34+AC34 -> 0 | AI34: =AF34+AH34 -> 0
D35: TOTAL personal NO ADSCRITO EN EXCLUSIVA a Actividades de I+D | F35: =SUMIF($E15:$E34,"<>SÍ",F15:F34) -> 0 | G35: =SUMIF($E15:$E34,"<>SÍ",G15:G34) -> 0 | H35: =SUMIF($E15:$E34,"<>SÍ",H15:H34) -> 13249.8 | I35: =SUMIF($E15:$E34,"<>SÍ",I15:I34) -> 511323 | J35: =G35+I35 -> 511323 | K35: =SUMIF($E15:$E34,"<>SÍ",K15:K34) -> 0 | L35: =SUMIF($E15:$E34,"<>SÍ",L15:L34) -> 0 | M35: =SUMIF($E15:$E34,"<>SÍ",M15:M34) -> 14299.73 | N35: =SUMIF($E15:$E34,"<>SÍ",N15:N34) -> 572889.74 | O35: =L35+N35 -> 572889.74 | P35: =SUMIF($E15:$E34,"<>SÍ",P15:P34) -> 0 | Q35: =SUMIF($E15:$E34,"<>SÍ",Q15:Q34) -> 0 | R35: =SUMIF($E15:$E34,"<>SÍ",R15:R34) -> 14299.73 | S35: =SUMIF($E15:$E34,"<>SÍ",S15:S34) -> 615985.37 | T35: =Q35+S35 -> 615985.37 | U35: =SUMIF($E15:$E34,"<>SÍ",U15:U34) -> 0 | V35: =SUMIF($E15:$E34,"<>SÍ",V15:V34) -> 0 | W35: =SUMIF($E15:$E34,"<>SÍ",W15:W34) -> 15337.81 | X35: =SUMIF($E15:$E34,"<>SÍ",X15:X34) -> 717312.07 | Y35: =V35+X35 -> 717312.07 | Z35: =SUMIF($E15:$E34,"<>SÍ",Z15:Z34) -> 0 | AA35: =SUMIF($E15:$E34,"<>SÍ",AA15:AA34) -> 0 | AB35: =SUMIF($E15:$E34,"<>SÍ",AB15:AB34) -> 0 | AC35: =SUMIF($E15:$E34,"<>SÍ",AC15:AC34) -> 0 | AD35: =AA35+AC35 -> 0 | AE35: =SUMIF($E15:$E34,"<>SÍ",AE15:AE34) -> 0 | AF35: =SUMIF($E15:$E34,"<>SÍ",AF15:AF34) -> 0 | AG35: =SUMIF($E15:$E34,"<>SÍ",AG15:AG34) -> 0 | AH35: =SUMIF($E15:$E34,"<>SÍ",AH15:AH34) -> 0 | AI35: =AF35+AH35 -> 0
D36: TOTAL personal ADSCRITO EN EXCLUSIVA a Actividades de I+D | F36: =SUMIF($E15:$E34,"SÍ",F15:F34) -> 0 | G36: =SUMIF($E15:$E34,"SÍ",G15:G34) -> 0 | J36: =G36 -> 0 | K36: =SUMIF($E15:$E34,"SÍ",K15:K34) -> 0 | L36: =SUMIF($E15:$E34,"SÍ",L15:L34) -> 0 | O36: =L36 -> 0 | P36: =SUMIF($E15:$E34,"SÍ",P15:P34) -> 0 | Q36: =SUMIF($E15:$E34,"SÍ",Q15:Q34) -> 0 | T36: =Q36 -> 0 | U36: =SUMIF($E15:$E34,"SÍ",U15:U34) -> 0 | V36: =SUMIF($E15:$E34,"SÍ",V15:V34) -> 0 | Y36: =V36 -> 0 | Z36: =SUMIF($E15:$E34,"SÍ",Z15:Z34) -> 0 | AA36: =SUMIF($E15:$E34,"SÍ",AA15:AA34) -> 0 | AD36: =AA36 -> 0 | AE36: =SUMIF($E15:$E34,"SÍ",AE15:AE34) -> 0 | AF36: =SUMIF($E15:$E34,"SÍ",AF15:AF34) -> 0 | AI36: =AF36 -> 0
D37: TOTAL PERSONAL | F37: =F35+F36 -> 0 | G37: =G35+G36 -> 0 | H37: =H35 -> 13249.8 | I37: =I35 -> 511323 | J37: =G37+I37 -> 511323 | K37: =K35+K36 -> 0 | L37: =L35+L36 -> 0 | M37: =M35 -> 14299.73 | N37: =N35 -> 572889.74 | O37: =L37+N37 -> 572889.74 | P37: =P35+P36 -> 0 | Q37: =Q35+Q36 -> 0 | R37: =R35 -> 14299.73 | S37: =S35 -> 615985.37 | T37: =Q37+S37 -> 615985.37 | U37: =U35+U36 -> 0 | V37: =V35+V36 -> 0 | W37: =W35 -> 15337.81 | X37: =X35 -> 717312.07 | Y37: =V37+X37 -> 717312.07 | Z37: =Z35+Z36 -> 0 | AA37: =AA35+AA36 -> 0 | AB37: =AB35 -> 0 | AC37: =AC35 -> 0 | AD37: =AA37+AC37 -> 0 | AE37: =AE35+AE36 -> 0 | AF37: =AF35+AF36 -> 0 | AG37: =AG35 -> 0 | AH37: =AH35 -> 0 | AI37: =AF37+AH37 -> 0

Sheet C.Externas (OPIS)
B4: 2.2 COLABORACIONES EXTERNAS
B5: 2.2.1 Universidades, Organismos Públicos de Investigación y Centros de Innovación y Tecnología (reconocidos y registrados como tales)
B8: - Para anualidades futuras, si el nombre de la colaboración externa (Universidad, OPI o CIT) aún no se conoce, en lugar de la "ENTIDAD" se reflejará el servicio y las actividades a subcontratar.
B10: - Es obligatorio indicar la 'Tipología' de la colaboración (UNI, OPI o CIT).
B12: - Por cada una de las entidades colaboradoras, se cumplimentará/n su/s correspondiente/s Ficha/s de ampliación del apartado 2.2 y el resto de Fichas "adicionales" cuando proceda.
B15: Código Colaboración | C15: Entidad | D15: NIF | E15: Tipo | F15: =Personal!F13 -> 2021 | I15: =F15+1 -> 2022 | L15: =I15+1 -> 2023 | O15: =L15+1 -> 2024 | R15: =O15+1 -> 2025 | U15: =R15+1 -> 2026
B16: Código Recurso | C16: Nombre | F16: Coste/Gasto I+D | G16: Coste/Gasto IT | H16: Coste/Gasto TOTAL | I16: Coste/Gasto I+D | J16: Coste/Gasto IT | K16: Coste/Gasto TOTAL | L16: Coste/Gasto I+D | M16: Coste/Gasto IT | N16: Coste/Gasto TOTAL | O16: Coste/Gasto I+D | P16: Coste/Gasto IT | Q16: Coste/Gasto TOTAL | R16: Coste/Gasto I+D | S16: Coste/Gasto IT | T16: Coste/Gasto TOTAL | U16: Coste/Gasto I+D | V16: Coste/Gasto IT | W16: Coste/Gasto TOTAL
B17: 1 | H17: =SUM(F17:G17) -> 0 | K17: =SUM(I17:J17) -> 0 | N17: =SUM(L17:M17) -> 0 | Q17: =SUM(O17:P17) -> 0 | T17: =SUM(R17:S17) -> 0 | W17: =U17+V17 -> 0
B18: =B17+1 -> 2 | H18: =SUM(F18:G18) -> 0 | K18: =SUM(I18:J18) -> 0 | N18: =SUM(L18:M18) -> 0 | Q18: =SUM(O18:P18) -> 0 | T18: =SUM(R18:S18) -> 0 | W18: =U18+V18 -> 0
B19: =B18+1 -> 3 | H19: =SUM(F19:G19) -> 0 | K19: =SUM(I19:J19) -> 0 | N19: =SUM(L19:M19) -> 0 | Q19: =SUM(O19:P19) -> 0 | T19: =SUM(R19:S19) -> 0 | W19: =U19+V19 -> 0
B20: =B19+1 -> 4 | H20: =SUM(F20:G20) -> 0 | K20: =SUM(I20:J20) -> 0 | N20: =SUM(L20:M20) -> 0 | Q20: =SUM(O20:P20) -> 0 | T20: =SUM(R20:S20) -> 0 | W20: =U20+V20 -> 0
B21: =B20+1 -> 5 | H21: =SUM(F21:G21) -> 0 | K21: =SUM(I21:J21) -> 0 | N21: =SUM(L21:M21) -> 0 | Q21: =SUM(O21:P21) -> 0 | T21: =SUM(R21:S21) -> 0 | W21: =U21+V21 -> 0
B22: =B21+1 -> 6 | H22: =SUM(F22:G22) -> 0 | K22: =SUM(I22:J22) -> 0 | N22: =SUM(L22:M22) -> 0 | Q22: =SUM(O22:P22) -> 0 | T22: =SUM(R22:S22) -> 0 | W22: =U22+V22 -> 0
B23: =B22+1 -> 7 | H23: =SUM(F23:G23) -> 0 | K23: =SUM(I23:J23) -> 0 | N23: =SUM(L23:M23) -> 0 | Q23: =SUM(O23:P23) -> 0 | T23: =SUM(R23:S23) -> 0 | W23: =U23+V23 -> 0
B24: =B23+1 -> 8 | H24: =SUM(F24:G24) -> 0 | K24: =SUM(I24:J24) -> 0 | N24: =SUM(L24:M24) -> 0 | Q24: =SUM(O24:P24) -> 0 | T24: =SUM(R24:S24) -> 0 | W24: =U24+V24 -> 0
B25: =B24+1 -> 9 | H25: =SUM(F25:G25) -> 0 | K25: =SUM(I25:J25) -> 0 | N25: =SUM(L25:M25) -> 0 | Q25: =SUM(O25:P25) -> 0 | T25: =SUM(R25:S25) -> 0 | W25: =U25+V25 -> 0
B26: =B25+1 -> 10 | H26: =SUM(F26:G26) -> 0 | K26: =SUM(I26:J26) -> 0 | N26: =SUM(L26:M26) -> 0 | Q26: =SUM(O26:P26) -> 0 | T26: =SUM(R26:S26) -> 0 | W26: =U26+V26 -> 0
B27: =B26+1 -> 11 | H27: =SUM(F27:G27) -> 0 | K27: =SUM(I27:J27) -> 0 | N27: =SUM(L27:M27) -> 0 | Q27: =SUM(O27:P27) -> 0 | T27: =SUM(R27:S27) -> 0 | W27: =U27+V27 -> 0
B28: =B27+1 -> 12 | H28: =SUM(F28:G28) -> 0 | K28: =SUM(I28:J28) -> 0 | N28: =SUM(L28:M28) -> 0 | Q28: =SUM(O28:P28) -> 0 | T28: =SUM(R28:S28) -> 0 | W28: =U28+V28 -> 0
B29: =B28+1 -> 13 | H29: =SUM(F29:G29) -> 0 | K29: =SUM(I29:J29) -> 0 | N29: =SUM(L29:M29) -> 0 | Q29: =SUM(O29:P29) -> 0 | T29: =SUM(R29:S29) -> 0 | W29: =U29+V29 -> 0
... B36: =B35+1 -> 20 | H36: =SUM(F36:G36) -> 0 | K36: =SUM(I36:J36) -> 0 | N36: =SUM(L36:M36) -> 0 | Q36: =SUM(O36:P36) -> 0 | T36: =SUM(R36:S36) -> 0 | W36: =U36+V36 -> 0
C37: TOTAL COLABORACIONES EXTERNAS contratadas / encargadas a UNIVERSIDADES | E37: UNI | F37: =SUMIF($E$17:$E$36,$E37,F$17:F$36) -> 0 | G37: =SUMIF($E$17:$E$36,$E37,G$17:G$36) -> 0 | H37: =SUM(F37:G37) -> 0 | I37: =SUMIF($E$17:$E$36,$E37,I$17:I$36) -> 0 | J37: =SUMIF($E$17:$E$36,$E37,J$17:J$36) -> 0 | K37: =SUM(I37:J37) -> 0 | L37: =SUMIF($E$17:$E$36,$E37,L$17:L$36) -> 0 | M37: =SUMIF($E$17:$E$36,$E37,M$17:M$36) -> 0 | N37: =SUM(L37:M37) -> 0 | O37: =SUMIF($E$17:$E$36,$E37,O$17:O$36) -> 0 | P37: =SUMIF($E$17:$E$36,$E37,P$17:P$36) -> 0 | Q37: =SUM(O37:P37) -> 0 | R37: =SUMIF($E$17:$E$36,$E37,R$17:R$36) -> 0 | S37: =SUMIF($E$17:$E$36,$E37,S$17:S$36) -> 0 | T37: =SUM(R37:S37) -> 0 | U37: =SUMIF($E$17:$E$36,$E37,U$17:U$36) -> 0 | V37: =SUMIF($E$17:$E$36,$E37,V$17:V$36) -> 0 | W37: =SUM(U37:V37) -> 0
C38: TOTAL COLABORACIONES EXTERNAS contratadas / encargadas a ORGANISMOS PÚBLICOS DE INVESTIGACIÓN | E38: OPI | F38: =SUMIF($E$17:$E$36,$E38,F$17:F$36) -> 0 | G38: =SUMIF($E$17:$E$36,$E38,G$17:G$36) -> 0 | H38: =SUM(F38:G38) -> 0 | I38: =SUMIF($E$17:$E$36,$E38,I$17:I$36) -> 0 | J38: =SUMIF($E$17:$E$36,$E38,J$17:J$36) -> 0 | K38: =SUM(I38:J38) -> 0 | L38: =SUMIF($E$17:$E$36,$E38,L$17:L$36) -> 0 | M38: =SUMIF($E$17:$E$36,$E38,M$17:M$36) -> 0 | N38: =SUM(L38:M38) -> 0 | O38: =SUMIF($E$17:$E$36,$E38,O$17:O$36) -> 0 | P38: =SUMIF($E$17:$E$36,$E38,P$17:P$36) -> 0 | Q38: =SUM(O38:P38) -> 0 | R38: =SUMIF($E$17:$E$36,$E38,R$17:R$36) -> 0 | S38: =SUMIF($E$17:$E$36,$E38,S$17:S$36) -> 0 | T38: =SUM(R38:S38) -> 0 | U38: =SUMIF($E$17:$E$36,$E38,U$17:U$36) -> 0 | V38: =SUMIF($E$17:$E$36,$E38,V$17:V$36) -> 0 | W38: =SUM(U38:V38) -> 0
C39: TOTAL COLABORACIONES EXTERNAS contratadas / encargadas a CENTROS DE INNOVACIÓN Y TECNOLOGÍA | E39: CIT | F39: =SUMIF($E$17:$E$36,$E39,F$17:F$36) -> 0 | G39: =SUMIF($E$17:$E$36,$E39,G$17:G$36) -> 0 | H39: =SUM(F39:G39) -> 0 | I39: =SUMIF($E$17:$E$36,$E39,I$17:I$36) -> 0 | J39: =SUMIF($E$17:$E$36,$E39,J$17:J$36) -> 0 | K39: =SUM(I39:J39) -> 0 | L39: =SUMIF($E$17:$E$36,$E39,L$17:L$36) -> 0 | M39: =SUMIF($E$17:$E$36,$E39,M$17:M$36) -> 0 | N39: =SUM(L39:M39) -> 0 | O39: =SUMIF($E$17:$E$36,$E39,O$17:O$36) -> 0 | P39: =SUMIF($E$17:$E$36,$E39,P$17:P$36) -> 0 | Q39: =SUM(O39:P39) -> 0 | R39: =SUMIF($E$17:$E$36,$E39,R$17:R$36) -> 0 | S39: =SUMIF($E$17:$E$36,$E39,S$17:S$36) -> 0 | T39: =SUM(R39:S39) -> 0 | U39: =SUMIF($E$17:$E$36,$E39,U$17:U$36) -> 0 | V39: =SUMIF($E$17:$E$36,$E39,V$17:V$36) -> 0 | W39: =SUM(U39:V39) -> 0
C40: TOTAL COL. EXTERNAS CONTRATADAS /ENCARGADAS A UNIVERSIDADES, OPIs y CCTT | F40: =F37+F38+F39 -> 0 | G40: =G37+G38+G39 -> 0 | H40: =F40+G40 -> 0 | I40: =I37+I38+I39 -> 0 | J40: =J37+J38+J39 -> 0 | K40: =I40+J40 -> 0 | L40: =L37+L38+L39 -> 0 | M40: =M37+M38+M39 -> 0 | N40: =L40+M40 -> 0 | O40: =O37+O38+O39 -> 0 | P40: =P37+P38+P39 -> 0 | Q40: =O40+P40 -> 0 | R40: =R37+R38+R39 -> 0 | S40: =S37+S38+S39 -> 0 | T40: =R40+S40 -> 0 | U40: =U37+U38+U39 -> 0 | V40: =V37+V38+V39 -> 0 | W40: =U40+V40 -> 0

Sheet C.Externas (Otros)
B4: 2.2 COLABORACIONES EXTERNAS
B5: 2.2.2 Otros (Empresas Privadas, Asociaciones, etc.)
B8: - Para anualidades futuras, si el nombre de la colaboración externa (Universidad, OPI o CIT) aún no se conoce, en lugar de la "ENTIDAD" se reflejará el servicio y las actividades a subcontratar.
B10: - Por cada una de las entidades de colaboración, se cumplimentará/n su/s correspondiente/s ficha/s de ampliación del apartado 2.2 y el resto de Fichas "adicionales" cuando proceda.
B13: Código Colaboración | C13: Entidad | D13: NIF | E13: =Personal!F13 -> 2021 | H13: =E13+1 -> 2022 | K13: =H13+1 -> 2023 | N13: =K13+1 -> 2024 | Q13: =N13+1 -> 2025 | T13: =Q13+1 -> 2026
B14: Código Recurso | C14: Nombre | E14: Coste/Gasto I+D | F14: Coste/Gasto IT | G14: Coste/Gasto TOTAL | H14: Coste/Gasto I+D | I14: Coste/Gasto IT | J14: Coste/Gasto TOTAL | K14: Coste/Gasto I+D | L14: Coste/Gasto IT | M14: Coste/Gasto TOTAL | N14: Coste/Gasto I+D | O14: Coste/Gasto IT | P14: Coste/Gasto TOTAL | Q14: Coste/Gasto I+D | R14: Coste/Gasto IT | S14: Coste/Gasto TOTAL | T14: Coste/Gasto I+D | U14: Coste/Gasto IT | V14: Coste/Gasto TOTAL
B15: 1 | C15: Accenture, S.L. | D15: B79217790 | F15: 89996.84 | G15: =E15+F15 -> 89996.84 | J15: =SUM(H15:I15) -> 0 | M15: =SUM(K15:L15) -> 0 | P15: =SUM(N15:O15) -> 0 | S15: =SUM(Q15:R15) -> 0 | V15: =SUM(T15:U15) -> 0
B16: =B15+1 -> 2 | C16: Altran lnnovacion SLU | D16: B80428972 | F16: 20466.78 | G16: =E16+F16 -> 20466.78 | J16: =SUM(H16:I16) -> 0 | M16: =SUM(K16:L16) -> 0 | P16: =SUM(N16:O16) -> 0 | S16: =SUM(Q16:R16) -> 0 | V16: =SUM(T16:U16) -> 0
B17: =B16+1 -> 3 | C17: Arca Ingenieros y Consultoria, S.L. | D17: B96802244 | F17: 4224 | G17: =E17+F17 -> 4224 | J17: =SUM(H17:I17) -> 0 | M17: =SUM(K17:L17) -> 0 | P17: =SUM(N17:O17) -> 0 | S17: =SUM(Q17:R17) -> 0 | V17: =SUM(T17:U17) -> 0
B18: =B17+1 -> 4 | C18: Berocam Consulting S.L. | D18: B87197539 | F18: 32873.44 | G18: =E18+F18 -> 32873.44 | J18: =SUM(H18:I18) -> 0 | M18: =SUM(K18:L18) -> 0 | P18: =SUM(N18:O18) -> 0 | S18: =SUM(Q18:R18) -> 0 | V18: =SUM(T18:U18) -> 0
B19: =B18+1 -> 5 | C19: DIVITEL MOVIL, S.L.U. | D19: B82783663 | F19: 91500 | G19: =E19+F19 -> 91500 | J19: =SUM(H19:I19) -> 0 | M19: =SUM(K19:L19) -> 0 | P19: =SUM(N19:O19) -> 0 | S19: =SUM(Q19:R19) -> 0 | V19: =SUM(T19:U19) -> 0
B20: =B19+1 -> 6 | C20: NTT DATA SPAIN SL | D20: B82387770 | F20: 217604.97 | G20: =E20+F20 -> 217604.97 | J20: =SUM(H20:I20) -> 0 | M20: =SUM(K20:L20) -> 0 | P20: =SUM(N20:O20) -> 0 | S20: =SUM(Q20:R20) -> 0 | V20: =SUM(T20:U20) -> 0
B21: =B20+1 -> 7 | G21: =E21+F21 -> 0 | J21: =SUM(H21:I21) -> 0 | M21: =SUM(K21:L21) -> 0 | P21: =SUM(N21:O21) -> 0 | S21: =SUM(Q21:R21) -> 0 | V21: =SUM(T21:U21) -> 0
B22: =B21+1 -> 8 | C22: C.Externas 2022 | G22: =E22+F22 -> 0 | H22: 519249.72 | I22: 519249.72 | J22: =SUM(H22:I22) -> 1038499.4 | M22: =SUM(K22:L22) -> 0 | P22: =SUM(N22:O22) -> 0 | S22: =SUM(Q22:R22) -> 0 | V22: =SUM(T22:U22) -> 0
B23: =B22+1 -> 9 | C23: C.Externas 2023 | G23: =E23+F23 -> 0 | J23: =SUM(H23:I23) -> 0 | K23: 732292.43 | L23: 732292.43 | M23: =SUM(K23:L23) -> 1464584.9 | P23: =SUM(N23:O23) -> 0 | S23: =SUM(Q23:R23) -> 0 | V23: =SUM(T23:U23) -> 0
B24: =B23+1 -> 10 | C24: C.Externas 2024 | G24: =E24+F24 -> 0 | J24: =SUM(H24:I24) -> 0 | M24: =SUM(K24:L24) -> 0 | N24: 615333.58 | O24: 615333.58 | P24: =SUM(N24:O24) -> 1230667.2 | S24: =SUM(Q24:R24) -> 0 | V24: =SUM(T24:U24) -> 0
B25: =B24+1 -> 11 | G25: =E25+F25 -> 0 | J25: =SUM(H25:I25) -> 0 | M25: =SUM(K25:L25) -> 0 | P25: =SUM(N25:O25) -> 0 | S25: =SUM(Q25:R25) -> 0 | V25: =SUM(T25:U25) -> 0
B26: =B25+1 -> 12 | G26: =E26+F26 -> 0 | J26: =SUM(H26:I26) -> 0 | M26: =SUM(K26:L26) -> 0 | P26: =SUM(N26:O26) -> 0 | S26: =SUM(Q26:R26) -> 0 | V26: =SUM(T26:U26) -> 0
B27: =B26+1 -> 13 | G27: =E27+F27 -> 0 | J27: =SUM(H27:I27) -> 0 | M27: =SUM(K27:L27) -> 0 | P27: =SUM(N27:O27) -> 0 | S27: =SUM(Q27:R27) -> 0 | V27: =SUM(T27:U27) -> 0
B28: =B27+1 -> 14 | G28: =E28+F28 -> 0 | J28: =SUM(H28:I28) -> 0 | M28: =SUM(K28:L28) -> 0 | P28: =SUM(N28:O28) -> 0 | S28: =SUM(Q28:R28) -> 0 | V28: =SUM(T28:U28) -> 0
B29: =B28+1 -> 15 | G29: =E29+F29 -> 0 | J29: =SUM(H29:I29) -> 0 | M29: =SUM(K29:L29) -> 0 | P29: =SUM(N29:O29) -> 0 | S29: =SUM(Q29:R29) -> 0 | V29: =SUM(T29:U29) -> 0
B30: =B29+1 -> 16 | G30: =E30+F30 -> 0 | J30: =SUM(H30:I30) -> 0 | M30: =SUM(K30:L30) -> 0 | P30: =SUM(N30:O30) -> 0 | S30: =SUM(Q30:R30) -> 0 | V30: =SUM(T30:U30) -> 0
B31: =B30+1 -> 17 | G31: =E31+F31 -> 0 | J31: =SUM(H31:I31) -> 0 | M31: =SUM(K31:L31) -> 0 | P31: =SUM(N31:O31) -> 0 | S31: =SUM(Q31:R31) -> 0 | V31: =SUM(T31:U31) -> 0
B32: =B31+1 -> 18 | G32: =E32+F32 -> 0 | J32: =SUM(H32:I32) -> 0 | M32: =SUM(K32:L32) -> 0 | P32: =SUM(N32:O32) -> 0 | S32: =SUM(Q32:R32) -> 0 | V32: =SUM(T32:U32) -> 0
B33: =B32+1 -> 19 | G33: =E33+F33 -> 0 | J33: =SUM(H33:I33) -> 0 | M33: =SUM(K33:L33) -> 0 | P33: =SUM(N33:O33) -> 0 | S33: =SUM(Q33:R33) -> 0 | V33: =SUM(T33:U33) -> 0
B34: =B33+1 -> 20 | G34: =E34+F34 -> 0 | J34: =SUM(H34:I34) -> 0 | M34: =SUM(K34:L34) -> 0 | P34: =SUM(N34:O34) -> 0 | S34: =SUM(Q34:R34) -> 0 | V34: =SUM(T34:U34) -> 0
C35: TOTAL COLABORACIONES EXTERNAS | E35: =SUM(E15:E34) -> 0 | F35: =SUM(F15:F34) -> 456666.03 | G35: =E35+F35 -> 456666.03 | H35: =SUM(H15:H34) -> 519249.72 | I35: =SUM(I15:I34) -> 519249.72 | J35: =SUM(J15:J34) -> 1038499.4 | K35: =SUM(K15:K34) -> 732292.43 | L35: =SUM(L15:L34) -> 732292.43 | M35: =SUM(M15:M34) -> 1464584.9 | N35: =SUM(N15:N34) -> 615333.58 | O35: =SUM(O15:O34) -> 615333.58 | ... V35: =SUM(V15:V34) -> 0

Sheet El._inmovilizado (AMORTIZACIÓN)
B4: 2.3 AMORTIZACIÓN DE ELEMENTOS DE INMOVILIZADO MATERIAL E INTANGIBLE
B7: - Por cada uno de los elementos de inmovilizado, se cumplimentará su correspondiente Ficha de ampliación del apartado 2.3.
B10: Código Elemento | C10: AMORTIZACIÓN DE ELEMENTOS DE INMOVILIZADO MATERIAL E INTANGIBLE | D10: =Personal!F13 -> 2021 | G10: =D10+1 -> 2022 | J10: =G10+1 -> 2023 | M10: =J10+1 -> 2024 | P10: =M10+1 -> 2025 | S10: =P10+1 -> 2026
B11: Código Recurso | D11: Coste/Gasto I+D | E11: Coste/Gasto IT | F11: Coste/Gasto TOTAL | G11: Coste/Gasto I+D | H11: Coste/Gasto IT | I11: Coste/Gasto TOTAL | J11: Coste/Gasto I+D | K11: Coste/Gasto IT | L11: Coste/Gasto TOTAL | M11: Coste/Gasto I+D | N11: Coste/Gasto IT | O11: Coste/Gasto TOTAL | P11: Coste/Gasto I+D | Q11: Coste/Gasto IT | R11: Coste/Gasto TOTAL | S11: Coste/Gasto I+D | T11: Coste/Gasto IT | U11: Coste/Gasto TOTAL
B12: 1 | F12: =SUM(D12:E12) -> 0 | I12: =SUM(G12:H12) -> 0 | L12: =SUM(J12:K12) -> 0 | O12: =SUM(M12:N12) -> 0 | R12: =SUM(P12:Q12) -> 0 | U12: =SUM(S12:T12) -> 0
B13: =B12+1 -> 2 | F13: =SUM(D13:E13) -> 0 | I13: =SUM(G13:H13) -> 0 | L13: =SUM(J13:K13) -> 0 | O13: =SUM(M13:N13) -> 0 | R13: =SUM(P13:Q13) -> 0 | U13: =SUM(S13:T13) -> 0
B14: =B13+1 -> 3 | F14: =SUM(D14:E14) -> 0 | I14: =SUM(G14:H14) -> 0 | L14: =SUM(J14:K14) -> 0 | O14: =SUM(M14:N14) -> 0 | R14: =SUM(P14:Q14) -> 0 | U14: =SUM(S14:T14) -> 0
B15: =B14+1 -> 4 | F15: =SUM(D15:E15) -> 0 | I15: =SUM(G15:H15) -> 0 | L15: =SUM(J15:K15) -> 0 | O15: =SUM(M15:N15) -> 0 | R15: =SUM(P15:Q15) -> 0 | U15: =SUM(S15:T15) -> 0
B16: =B15+1 -> 5 | F16: =SUM(D16:E16) -> 0 | I16: =SUM(G16:H16) -> 0 | L16: =SUM(J16:K16) -> 0 | O16: =SUM(M16:N16) -> 0 | R16: =SUM(P16:Q16) -> 0 | U16: =SUM(S16:T16) -> 0
B17: =B16+1 -> 6 | F17: =SUM(D17:E17) -> 0 | I17: =SUM(G17:H17) -> 0 | L17: =SUM(J17:K17) -> 0 | O17: =SUM(M17:N17) -> 0 | R17: =SUM(P17:Q17) -> 0 | U17: =SUM(S17:T17) -> 0
B18: =B17+1 -> 7 | F18: =SUM(D18:E18) -> 0 | I18: =SUM(G18:H18) -> 0 | L18: =SUM(J18:K18) -> 0 | O18: =SUM(M18:N18) -> 0 | R18: =SUM(P18:Q18) -> 0 | U18: =SUM(S18:T18) -> 0
B19: =B18+1 -> 8 | F19: =SUM(D19:E19) -> 0 | I19: =SUM(G19:H19) -> 0 | L19: =SUM(J19:K19) -> 0 | O19: =SUM(M19:N19) -> 0 | R19: =SUM(P19:Q19) -> 0 | U19: =SUM(S19:T19) -> 0
B20: =B19+1 -> 9 | F20: =SUM(D20:E20) -> 0 | I20: =SUM(G20:H20) -> 0 | L20: =SUM(J20:K20) -> 0 | O20: =SUM(M20:N20) -> 0 | R20: =SUM(P20:Q20) -> 0 | U20: =SUM(S20:T20) -> 0
B21: =B20+1 -> 10 | F21: =SUM(D21:E21) -> 0 | I21: =SUM(G21:H21) -> 0 | L21: =SUM(J21:K21) -> 0 | O21: =SUM(M21:N21) -> 0 | R21: =SUM(P21:Q21) -> 0 | U21: =SUM(S21:T21) -> 0
B22: =B21+1 -> 11 | F22: =SUM(D22:E22) -> 0 | I22: =SUM(G22:H22) -> 0 | L22: =SUM(J22:K22) -> 0 | O22: =SUM(M22:N22) -> 0 | R22: =SUM(P22:Q22) -> 0 | U22: =SUM(S22:T22) -> 0
B23: =B22+1 -> 12 | F23: =SUM(D23:E23) -> 0 | I23: =SUM(G23:H23) -> 0 | L23: =SUM(J23:K23) -> 0 | O23: =SUM(M23:N23) -> 0 | R23: =SUM(P23:Q23) -> 0 | U23: =SUM(S23:T23) -> 0
B24: =B23+1 -> 13 | F24: =SUM(D24:E24) -> 0 | I24: =SUM(G24:H24) -> 0 | L24: =SUM(J24:K24) -> 0 | O24: =SUM(M24:N24) -> 0 | R24: =SUM(P24:Q24) -> 0 | U24: =SUM(S24:T24) -> 0
... B31: =B30+1 -> 20 | F31: =SUM(D31:E31) -> 0 | I31: =SUM(G31:H31) -> 0 | L31: =SUM(J31:K31) -> 0 | O31: =SUM(M31:N31) -> 0 | R31: =SUM(P31:Q31) -> 0 | U31: =SUM(S31:T31) -> 0
C32: TOTAL | D32: =SUM(D12:D31) -> 0 | E32: =SUM(E12:E31) -> 0 | F32: =D32+E32 -> 0 | G32: =SUM(G12:G31) -> 0 | H32: =SUM(H12:H31) -> 0 | I32: =G32+H32 -> 0 | J32: =SUM(J12:J31) -> 0 | K32: =SUM(K12:K31) -> 0 | L32: =J32+K32 -> 0 | M32: =SUM(M12:M31) -> 0 | N32: =SUM(N12:N31) -> 0 | O32: =M32+N32 -> 0 | P32: =SUM(P12:P31) -> 0 | Q32: =SUM(Q12:Q31) -> 0 | R32: =P32+Q32 -> 0 | S32: =SUM(S12:S31) -> 0 | T32: =SUM(T12:T31) -> 0 | U32: =S32+T32 -> 0

Sheet El._inmovilizado (INVERSIÓN)
B4: 2.3 INVERSIÓN EN ELEMENTOS DE INMOVILIZADO MATERIAL E INTANGIBLE
B6: - Por cada uno de los elementos de inmovilizado, se cumplimentará su correspondiente Ficha de ampliación del apartado 2.3.
B9: Código Elemento | C9: INVERSIÓN EN ELEMENTOS DE INMOVILIZADO MATERIAL E INTANGIBLE | D9: =Personal!F13 -> 2021 | G9: =D9+1 -> 2022 | J9: =G9+1 -> 2023 | M9: =J9+1 -> 2024 | P9: =M9+1 -> 2025 | S9: =P9+1 -> 2026
B10: Código Recurso | D10: Coste/Gasto I+D | E10: Coste/Gasto IT | F10: Coste/Gasto TOTAL | G10: Coste/Gasto I+D | H10: Coste/Gasto IT | I10: Coste/Gasto TOTAL | J10: Coste/Gasto I+D | K10: Coste/Gasto IT | L10: Coste/Gasto TOTAL | M10: Coste/Gasto I+D | N10: Coste/Gasto IT | O10: Coste/Gasto TOTAL | P10: Coste/Gasto I+D | Q10: Coste/Gasto IT | R10: Coste/Gasto TOTAL | S10: Coste/Gasto I+D | T10: Coste/Gasto IT | U10: Coste/Gasto TOTAL
B11: 1 | F11: =SUM(D11:E11) -> 0 | I11: =SUM(G11:H11) -> 0 | L11: =SUM(J11:K11) -> 0 | O11: =SUM(M11:N11) -> 0 | R11: =SUM(P11:Q11) -> 0 | U11: =SUM(S11:T11) -> 0
B12: =B11+1 -> 2 | F12: =SUM(D12:E12) -> 0 | I12: =SUM(G12:H12) -> 0 | L12: =SUM(J12:K12) -> 0 | O12: =SUM(M12:N12) -> 0 | R12: =SUM(P12:Q12) -> 0 | U12: =SUM(S12:T12) -> 0
B13: =B12+1 -> 3 | F13: =SUM(D13:E13) -> 0 | I13: =SUM(G13:H13) -> 0 | L13: =SUM(J13:K13) -> 0 | O13: =SUM(M13:N13) -> 0 | R13: =SUM(P13:Q13) -> 0 | U13: =SUM(S13:T13) -> 0
B14: =B13+1 -> 4 | F14: =SUM(D14:E14) -> 0 | I14: =SUM(G14:H14) -> 0 | L14: =SUM(J14:K14) -> 0 | O14: =SUM(M14:N14) -> 0 | R14: =SUM(P14:Q14) -> 0 | U14: =SUM(S14:T14) -> 0
B15: =B14+1 -> 5 | F15: =SUM(D15:E15) -> 0 | I15: =SUM(G15:H15) -> 0 | L15: =SUM(J15:K15) -> 0 | O15: =SUM(M15:N15) -> 0 | R15: =SUM(P15:Q15) -> 0 | U15: =SUM(S15:T15) -> 0
B16: =B15+1 -> 6 | F16: =SUM(D16:E16) -> 0 | I16: =SUM(G16:H16) -> 0 | L16: =SUM(J16:K16) -> 0 | O16: =SUM(M16:N16) -> 0 | R16: =SUM(P16:Q16) -> 0 | U16: =SUM(S16:T16) -> 0
B17: =B16+1 -> 7 | F17: =SUM(D17:E17) -> 0 | I17: =SUM(G17:H17) -> 0 | L17: =SUM(J17:K17) -> 0 | O17: =SUM(M17:N17) -> 0 | R17: =SUM(P17:Q17) -> 0 | U17: =SUM(S17:T17) -> 0
B18: =B17+1 -> 8 | F18: =SUM(D18:E18) -> 0 | I18: =SUM(G18:H18) -> 0 | L18: =SUM(J18:K18) -> 0 | O18: =SUM(M18:N18) -> 0 | R18: =SUM(P18:Q18) -> 0 | U18: =SUM(S18:T18) -> 0
B19: =B18+1 -> 9 | F19: =SUM(D19:E19) -> 0 | I19: =SUM(G19:H19) -> 0 | L19: =SUM(J19:K19) -> 0 | O19: =SUM(M19:N19) -> 0 | R19: =SUM(P19:Q19) -> 0 | U19: =SUM(S19:T19) -> 0
B20: =B19+1 -> 10 | F20: =SUM(D20:E20) -> 0 | I20: =SUM(G20:H20) -> 0 | L20: =SUM(J20:K20) -> 0 | O20: =SUM(M20:N20) -> 0 | R20: =SUM(P20:Q20) -> 0 | U20: =SUM(S20:T20) -> 0
B21: =B20+1 -> 11 | F21: =SUM(D21:E21) -> 0 | I21: =SUM(G21:H21) -> 0 | L21: =SUM(J21:K21) -> 0 | O21: =SUM(M21:N21) -> 0 | R21: =SUM(P21:Q21) -> 0 | U21: =SUM(S21:T21) -> 0
B22: =B21+1 -> 12 | F22: =SUM(D22:E22) -> 0 | I22: =SUM(G22:H22) -> 0 | L22: =SUM(J22:K22) -> 0 | O22: =SUM(M22:N22) -> 0 | R22: =SUM(P22:Q22) -> 0 | U22: =SUM(S22:T22) -> 0
B23: =B22+1 -> 13 | F23: =SUM(D23:E23) -> 0 | I23: =SUM(G23:H23) -> 0 | L23: =SUM(J23:K23) -> 0 | O23: =SUM(M23:N23) -> 0 | R23: =SUM(P23:Q23) -> 0 | U23: =SUM(S23:T23) -> 0
... B30: =B29+1 -> 20 | F30: =SUM(D30:E30) -> 0 | I30: =SUM(G30:H30) -> 0 | L30: =SUM(J30:K30) -> 0 | O30: =SUM(M30:N30) -> 0 | R30: =SUM(P30:Q30) -> 0 | U30: =SUM(S30:T30) -> 0
C31: TOTAL | D31: =SUM(D11:D30) -> 0 | F31: =D31+E31 -> 0 | G31: =SUM(G11:G30) -> 0 | I31: =G31+H31 -> 0 | J31: =SUM(J11:J30) -> 0 | L31: =J31+K31 -> 0 | M31: =SUM(M11:M30) -> 0 | O31: =M31+N31 -> 0 | P31: =SUM(P11:P30) -> 0 | R31: =P31+Q31 -> 0 | S31: =SUM(S11:S30) -> 0 | U31: =S31+T31 -> 0

Sheet Fungibles
B4: 2.4 MATERIAL FUNGIBLE
B6: - Por cada una de las partidas correspondientes a un mismo proveedor o un concepto, cuya suma sea superior a 30.000 €, se cumplimentará/n su/s correspondiente/s Ficha/s de ampliación del apartado 2.4
B9: Código Fungible | C9: MATERIAL FUNGIBLE | D9: =Personal!F13 -> 2021 | G9: =D9+1 -> 2022 | J9: =G9+1 -> 2023 | M9: =J9+1 -> 2024 | P9: =M9+1 -> 2025 | S9: =P9+1 -> 2026
D10: Coste/Gasto I+D | E10: Coste/Gasto IT | F10: Coste/Gasto TOTAL | G10: Coste/Gasto I+D | H10: Coste/Gasto IT | I10: Coste/Gasto TOTAL | J10: Coste/Gasto I+D | K10: Coste/Gasto IT | L10: Coste/Gasto TOTAL | M10: Coste/Gasto I+D | N10: Coste/Gasto IT | O10: Coste/Gasto TOTAL | P10: Coste/Gasto I+D | Q10: Coste/Gasto IT | R10: Coste/Gasto TOTAL | S10: Coste/Gasto I+D | T10: Coste/Gasto IT | U10: Coste/Gasto TOTAL
B11: 1 | F11: =SUM(D11:E11) -> 0 | I11: =SUM(G11:H11) -> 0 | L11: =SUM(J11:K11) -> 0 | O11: =SUM(M11:N11) -> 0 | R11: =SUM(P11:Q11) -> 0 | U11: =SUM(S11:T11) -> 0
B12: =B11+1 -> 2 | F12: =SUM(D12:E12) -> 0 | I12: =SUM(G12:H12) -> 0 | L12: =SUM(J12:K12) -> 0 | O12: =SUM(M12:N12) -> 0 | R12: =SUM(P12:Q12) -> 0 | U12: =SUM(S12:T12) -> 0
B13: =B12+1 -> 3 | F13: =SUM(D13:E13) -> 0 | I13: =SUM(G13:H13) -> 0 | L13: =SUM(J13:K13) -> 0 | O13: =SUM(M13:N13) -> 0 | R13: =SUM(P13:Q13) -> 0 | U13: =SUM(S13:T13) -> 0
B14: =B13+1 -> 4 | F14: =SUM(D14:E14) -> 0 | I14: =SUM(G14:H14) -> 0 | L14: =SUM(J14:K14) -> 0 | O14: =SUM(M14:N14) -> 0 | R14: =SUM(P14:Q14) -> 0 | U14: =SUM(S14:T14) -> 0
B15: =B14+1 -> 5 | F15: =SUM(D15:E15) -> 0 | I15: =SUM(G15:H15) -> 0 | L15: =SUM(J15:K15) -> 0 | O15: =SUM(M15:N15) -> 0 | R15: =SUM(P15:Q15) -> 0 | U15: =SUM(S15:T15) -> 0
B16: =B15+1 -> 6 | F16: =SUM(D16:E16) -> 0 | I16: =SUM(G16:H16) -> 0 | L16: =SUM(J16:K16) -> 0 | O16: =SUM(M16:N16) -> 0 | R16: =SUM(P16:Q16) -> 0 | U16: =SUM(S16:T16) -> 0
B17: =B16+1 -> 7 | F17: =SUM(D17:E17) -> 0 | I17: =SUM(G17:H17) -> 0 | L17: =SUM(J17:K17) -> 0 | O17: =SUM(M17:N17) -> 0 | R17: =SUM(P17:Q17) -> 0 | U17: =SUM(S17:T17) -> 0
B18: =B17+1 -> 8 | F18: =SUM(D18:E18) -> 0 | I18: =SUM(G18:H18) -> 0 | L18: =SUM(J18:K18) -> 0 | O18: =SUM(M18:N18) -> 0 | R18: =SUM(P18:Q18) -> 0 | U18: =SUM(S18:T18) -> 0
B19: =B18+1 -> 9 | F19: =SUM(D19:E19) -> 0 | I19: =SUM(G19:H19) -> 0 | L19: =SUM(J19:K19) -> 0 | O19: =SUM(M19:N19) -> 0 | R19: =SUM(P19:Q19) -> 0 | U19: =SUM(S19:T19) -> 0
B20: =B19+1 -> 10 | F20: =SUM(D20:E20) -> 0 | I20: =SUM(G20:H20) -> 0 | L20: =SUM(J20:K20) -> 0 | O20: =SUM(M20:N20) -> 0 | R20: =SUM(P20:Q20) -> 0 | U20: =SUM(S20:T20) -> 0
B21: =B20+1 -> 11 | F21: =SUM(D21:E21) -> 0 | I21: =SUM(G21:H21) -> 0 | L21: =SUM(J21:K21) -> 0 | O21: =SUM(M21:N21) -> 0 | R21: =SUM(P21:Q21) -> 0 | U21: =SUM(S21:T21) -> 0
B22: =B21+1 -> 12 | F22: =SUM(D22:E22) -> 0 | I22: =SUM(G22:H22) -> 0 | L22: =SUM(J22:K22) -> 0 | O22: =SUM(M22:N22) -> 0 | R22: =SUM(P22:Q22) -> 0 | U22: =SUM(S22:T22) -> 0
B23: =B22+1 -> 13 | F23: =SUM(D23:E23) -> 0 | I23: =SUM(G23:H23) -> 0 | L23: =SUM(J23:K23) -> 0 | O23: =SUM(M23:N23) -> 0 | R23: =SUM(P23:Q23) -> 0 | U23: =SUM(S23:T23) -> 0
... B30: =B29+1 -> 20 | F30: =SUM(D30:E30) -> 0 | I30: =SUM(G30:H30) -> 0 | L30: =SUM(J30:K30) -> 0 | O30: =SUM(M30:N30) -> 0 | R30: =SUM(P30:Q30) -> 0 | U30: =SUM(S30:T30) -> 0
C31: TOTAL | D31: =SUM(D11:D30) -> 0 | E31: =SUM(E11:E30) -> 0 | F31: =D31+E31 -> 0 | G31: =SUM(G11:G30) -> 0 | H31: =SUM(H11:H30) -> 0 | I31: =G31+H31 -> 0 | J31: =SUM(J11:J30) -> 0 | K31: =SUM(K11:K30) -> 0 | L31: =J31+K31 -> 0 | M31: =SUM(M11:M30) -> 0 | N31: =SUM(N11:N30) -> 0 | O31: =M31+N31 -> 0 | P31: =SUM(P11:P30) -> 0 | Q31: =SUM(Q11:Q30) -> 0 | R31: =P31+Q31 -> 0 | S31: =SUM(S11:S30) -> 0 | T31: =SUM(T11:T30) -> 0 | U31: =S31+T31 -> 0

Sheet Otros Gastos
B4: 2.5 OTROS GASTOS
B6: - Para cada uno de los conceptos recogidos, que superen en una cuantía del 5% a la suma total del gasto de personal, o que sumados los de un mismo proveedor o modalidad superen dicha cuantía, se cumplimentará la Ficha de ampliación del apartado 2.5.
B9: Código Otros | C9: OTROS GASTOS | D9: =Personal!F13 -> 2021 | G9: =D9+1 -> 2022 | J9: =G9+1 -> 2023 | M9: =J9+1 -> 2024 | P9: =M9+1 -> 2025 | S9: =P9+1 -> 2026
B10: Código Recurso | D10: Coste/Gasto I+D | E10: Coste/Gasto IT | F10: Coste/Gasto TOTAL | G10: Coste/Gasto I+D | H10: Coste/Gasto IT | I10: Coste/Gasto TOTAL | J10: Coste/Gasto I+D | K10: Coste/Gasto IT | L10: Coste/Gasto TOTAL | M10: Coste/Gasto I+D | N10: Coste/Gasto IT | O10: Coste/Gasto TOTAL | P10: Coste/Gasto I+D | Q10: Coste/Gasto IT | R10: Coste/Gasto TOTAL | S10: Coste/Gasto I+D | T10: Coste/Gasto IT | U10: Coste/Gasto TOTAL
B11: 1 | F11: =SUM(D11:E11) -> 0 | I11: =SUM(G11:H11) -> 0 | L11: =SUM(J11:K11) -> 0 | O11: =SUM(M11:N11) -> 0 | R11: =SUM(P11:Q11) -> 0 | U11: =SUM(S11:T11) -> 0
B12: =B11+1 -> 2 | F12: =SUM(D12:E12) -> 0 | I12: =SUM(G12:H12) -> 0 | L12: =SUM(J12:K12) -> 0 | O12: =SUM(M12:N12) -> 0 | R12: =SUM(P12:Q12) -> 0 | U12: =SUM(S12:T12) -> 0
B13: =B12+1 -> 3 | F13: =SUM(D13:E13) -> 0 | I13: =SUM(G13:H13) -> 0 | L13: =SUM(J13:K13) -> 0 | O13: =SUM(M13:N13) -> 0 | R13: =SUM(P13:Q13) -> 0 | U13: =SUM(S13:T13) -> 0
B14: =B13+1 -> 4 | F14: =SUM(D14:E14) -> 0 | I14: =SUM(G14:H14) -> 0 | L14: =SUM(J14:K14) -> 0 | O14: =SUM(M14:N14) -> 0 | R14: =SUM(P14:Q14) -> 0 | U14: =SUM(S14:T14) -> 0
B15: =B14+1 -> 5 | F15: =SUM(D15:E15) -> 0 | I15: =SUM(G15:H15) -> 0 | L15: =SUM(J15:K15) -> 0 | O15: =SUM(M15:N15) -> 0 | R15: =SUM(P15:Q15) -> 0 | U15: =SUM(S15:T15) -> 0
B16: =B15+1 -> 6 | F16: =SUM(D16:E16) -> 0 | I16: =SUM(G16:H16) -> 0 | L16: =SUM(J16:K16) -> 0 | O16: =SUM(M16:N16) -> 0 | R16: =SUM(P16:Q16) -> 0 | U16: =SUM(S16:T16) -> 0
B17: =B16+1 -> 7 | F17: =SUM(D17:E17) -> 0 | I17: =SUM(G17:H17) -> 0 | L17: =SUM(J17:K17) -> 0 | O17: =SUM(M17:N17) -> 0 | R17: =SUM(P17:Q17) -> 0 | U17: =SUM(S17:T17) -> 0
B18: =B17+1 -> 8 | F18: =SUM(D18:E18) -> 0 | I18: =SUM(G18:H18) -> 0 | L18: =SUM(J18:K18) -> 0 | O18: =SUM(M18:N18) -> 0 | R18: =SUM(P18:Q18) -> 0 | U18: =SUM(S18:T18) -> 0
B19: =B18+1 -> 9 | F19: =SUM(D19:E19) -> 0 | I19: =SUM(G19:H19) -> 0 | L19: =SUM(J19:K19) -> 0 | O19: =SUM(M19:N19) -> 0 | R19: =SUM(P19:Q19) -> 0 | U19: =SUM(S19:T19) -> 0
B20: =B19+1 -> 10 | F20: =SUM(D20:E20) -> 0 | I20: =SUM(G20:H20) -> 0 | L20: =SUM(J20:K20) -> 0 | O20: =SUM(M20:N20) -> 0 | R20: =SUM(P20:Q20) -> 0 | U20: =SUM(S20:T20) -> 0
B21: =B20+1 -> 11 | F21: =SUM(D21:E21) -> 0 | I21: =SUM(G21:H21) -> 0 | L21: =SUM(J21:K21) -> 0 | O21: =SUM(M21:N21) -> 0 | R21: =SUM(P21:Q21) -> 0 | U21: =SUM(S21:T21) -> 0
B22: =B21+1 -> 12 | F22: =SUM(D22:E22) -> 0 | I22: =SUM(G22:H22) -> 0 | L22: =SUM(J22:K22) -> 0 | O22: =SUM(M22:N22) -> 0 | R22: =SUM(P22:Q22) -> 0 | U22: =SUM(S22:T22) -> 0
B23: =B22+1 -> 13 | F23: =SUM(D23:E23) -> 0 | I23: =SUM(G23:H23) -> 0 | L23: =SUM(J23:K23) -> 0 | O23: =SUM(M23:N23) -> 0 | R23: =SUM(P23:Q23) -> 0 | U23: =SUM(S23:T23) -> 0
... B30: =B29+1 -> 20 | F30: =SUM(D30:E30) -> 0 | I30: =SUM(G30:H30) -> 0 | L30: =SUM(J30:K30) -> 0 | O30: =SUM(M30:N30) -> 0 | R30: =SUM(P30:Q30) -> 0 | U30: =SUM(S30:T30) -> 0
C31: TOTAL | D31: =SUM(D11:D30) -> 0 | E31: =SUM(E11:E30) -> 0 | F31: =D31+E31 -> 0 | G31: =SUM(G11:G30) -> 0 | H31: =SUM(H11:H30) -> 0 | I31: =G31+H31 -> 0 | J31: =SUM(J11:J30) -> 0 | K31: =SUM(K11:K30) -> 0 | L31: =J31+K31 -> 0 | M31: =SUM(M11:M30) -> 0 | N31: =SUM(N11:N30) -> 0 | O31: =M31+N31 -> 0 | P31: =SUM(P11:P30) -> 0 | Q31: =SUM(Q11:Q30) -> 0 | R31: =P31+Q31 -> 0 | S31: =SUM(S11:S30) -> 0 | T31: =SUM(T11:T30) -> 0 | U31: =S31+T31 -> 0

Sheet I+D
B4: PRESUPUESTO EN INVESTIGACIÓN Y DESARROLLO DEL PROYECTO
B7: PRESUPUESTO EN INVESTIGACIÓN Y DESARROLLO DEL PROYECTO (en Euros)
B8: EJERCICIO FISCAL | D8: =Personal!F13 -> 2021 | E8: =D8+1 -> 2022 | F8: =E8+1 -> 2023 | G8: =F8+1 -> 2024 | H8: =G8+1 -> 2025 | I8: =H8+1 -> 2026
B9: Personal aplicado a actividades de I+D+i | D9: =Personal!G35 -> 0 | E9: =Personal!L35 -> 0 | F9: =Personal!Q35 -> 0 | G9: =Personal!V35 -> 0 | H9: =Personal!AA35 -> 0 | I9: =Personal!AF35 -> 0
B10: Personal investigador cualificado de adscripción exclusiva (sólo proyectos I+D) | D10: =Personal!G36 -> 0 | E10: =Personal!L36 -> 0 | F10: =Personal!Q36 -> 0 | G10: =Personal!V36 -> 0 | H10: =Personal!AA36 -> 0 | I10: =Personal!AF36 -> 0
B11: Amortización de elementos de inmovilizado material e intangible | D11: ='El._inmovilizado (AMORTIZACIÓN)'!D32 -> 0 | E11: ='El._inmovilizado (AMORTIZACIÓN)'!G32 -> 0 | F11: ='El._inmovilizado (AMORTIZACIÓN)'!J32 -> 0 | G11: ='El._inmovilizado (AMORTIZACIÓN)'!M32 -> 0 | H11: ='El._inmovilizado (AMORTIZACIÓN)'!P32 -> 0 | I11: ='El._inmovilizado (AMORTIZACIÓN)'!S32 -> 0
B12: Material fungible | D12: =Fungibles!D31 -> 0 | E12: =Fungibles!G31 -> 0 | F12: =Fungibles!J31 -> 0 | G12: =Fungibles!M31 -> 0 | H12: =Fungibles!P31 -> 0 | I12: =Fungibles!S31 -> 0
B13: Colaboraciones Externas: Universidades, OPIs y/o CITs | D13: ='C.Externas (OPIS)'!F40 -> 0 | E13: ='C.Externas (OPIS)'!I40 -> 0 | F13: ='C.Externas (OPIS)'!L40 -> 0 | G13: ='C.Externas (OPIS)'!O40 -> 0 | H13: ='C.Externas (OPIS)'!R40 -> 0 | I13: ='C.Externas (OPIS)'!U40 -> 0
B14: Otras colaboraciones externas | D14: ='C.Externas (Otros)'!E35 -> 0 | E14: ='C.Externas (Otros)'!H35 -> 519249.72 | F14: ='C.Externas (Otros)'!K35 -> 732292.43 | G14: ='C.Externas (Otros)'!N35 -> 615333.58 | H14: ='C.Externas (Otros)'!Q35 -> 0 | I14: ='C.Externas (Otros)'!T35 -> 0
B15: Otros gastos | D15: ='Otros Gastos'!D31 -> 0 | E15: ='Otros Gastos'!G31 -> 0 | F15: ='Otros Gastos'!J31 -> 0 | G15: ='Otros Gastos'!M31 -> 0 | H15: ='Otros Gastos'!P31 -> 0 | I15: ='Otros Gastos'!S31 -> 0
B16: TOTAL COSTES / GASTOS | D16: =SUM(D9:D15) -> 0 | E16: =SUM(E9:E15) -> 519249.72 | F16: =SUM(F9:F15) -> 732292.43 | G16: =SUM(G9:G15) -> 615333.58 | H16: =SUM(H9:H15) -> 0 | I16: =SUM(I9:I15) -> 0
B18: TOTAL INVERSIÓN EN ELEMENTOS DE INMOVILIZADO MATERIAL E INTANGIBLE | D18: ='El._inmovilizado (INVERSIÓN)'!D31 -> 0 | E18: ='El._inmovilizado (INVERSIÓN)'!G31 -> 0 | F18: ='El._inmovilizado (INVERSIÓN)'!J31 -> 0 | G18: ='El._inmovilizado (INVERSIÓN)'!M31 -> 0 | H18: ='El._inmovilizado (INVERSIÓN)'!P31 -> 0 | I18: ='El._inmovilizado (INVERSIÓN)'!S31 -> 0

Sheet iT
B4: PRESUPUESTO EN INNOVACIÓN TECNOLÓGICA DEL PROYECTO
B7: PRESUPUESTO EN INNOVACIÓN TECNOLÓGICA DEL PROYECTO (en Euros)
B8: EJERCICIO FISCAL | D8: =Personal!F13 -> 2021 | E8: =D8+1 -> 2022 | F8: =E8+1 -> 2023 | G8: =F8+1 -> 2024 | H8: =G8+1 -> 2025 | I8: =H8+1 -> 2026
B9: Personal aplicado a actividades de I+D+i | D9: =Personal!I35 -> 511323 | E9: =Personal!N35 -> 572889.74 | F9: =Personal!S35 -> 615985.37 | G9: =Personal!X35 -> 717312.07 | H9: =Personal!AC35 -> 0 | I9: =Personal!AH35 -> 0
B10: Personal investigador cualificado de adscripción exclusiva (sólo proyectos I+D)
B11: Amortización de elementos de inmovilizado material e intangible | D11: ='El._inmovilizado (AMORTIZACIÓN)'!E32 -> 0 | E11: ='El._inmovilizado (AMORTIZACIÓN)'!H32 -> 0 | F11: ='El._inmovilizado (AMORTIZACIÓN)'!K32 -> 0 | G11: ='El._inmovilizado (AMORTIZACIÓN)'!N32 -> 0 | H11: ='El._inmovilizado (AMORTIZACIÓN)'!Q32 -> 0 | I11: ='El._inmovilizado (AMORTIZACIÓN)'!T32 -> 0
B12: Material fungible | D12: =Fungibles!E31 -> 0 | E12: =Fungibles!H31 -> 0 | F12: =Fungibles!K31 -> 0 | G12: =Fungibles!N31 -> 0 | H12: =Fungibles!Q31 -> 0 | I12: =Fungibles!T31 -> 0
B13: Colaboraciones Externas: Universidades, OPIs y/o CITs | D13: ='C.Externas (OPIS)'!G40 -> 0 | E13: ='C.Externas (OPIS)'!J40 -> 0 | F13: ='C.Externas (OPIS)'!M40 -> 0 | G13: ='C.Externas (OPIS)'!P40 -> 0 | H13: ='C.Externas (OPIS)'!S40 -> 0 | I13: ='C.Externas (OPIS)'!V40 -> 0
B14: Otras colaboraciones externas | D14: ='C.Externas (Otros)'!F35 -> 456666.03 | E14: ='C.Externas (Otros)'!I35 -> 519249.72 | F14: ='C.Externas (Otros)'!L35 -> 732292.43 | G14: ='C.Externas (Otros)'!O35 -> 615333.58 | H14: ='C.Externas (Otros)'!R35 -> 0 | I14: ='C.Externas (Otros)'!U35 -> 0
B15: Otros gastos | D15: ='Otros Gastos'!E31 -> 0 | E15: ='Otros Gastos'!H31 -> 0 | F15: ='Otros Gastos'!K31 -> 0 | G15: ='Otros Gastos'!N31 -> 0 | H15: ='Otros Gastos'!Q31 -> 0 | I15: ='Otros Gastos'!T31 -> 0
B16: TOTAL COSTES / GASTOS | D16: =SUM(D9:D15) -> 967989.03 | E16: =SUM(E9:E15) -> 1092139.5 | F16: =SUM(F9:F15) -> 1348277.8 | G16: =SUM(G9:G15) -> 1332645.6 | H16: =SUM(H9:H15) -> 0 | I16: =SUM(I9:I15) -> 0

Sheet TOTAL
B4: PRESUPUESTO TOTAL DEL PROYECTO
B7: PRESUPUESTO TOTAL DEL PROYECTO (en Euros)
B9: EJERCICIO FISCAL | D9: =Personal!F13 -> 2021 | E9: =D9+1 -> 2022 | F9: =E9+1 -> 2023 | G9: =F9+1 -> 2024 | H9: =G9+1 -> 2025 | I9: =H9+1 -> 2026
B10: Personal aplicado a actividades de I+D+i | D10: ='I+D'!D9+iT!D9 -> 511323 | E10: ='I+D'!E9+iT!E9 -> 572889.74 | F10: ='I+D'!F9+iT!F9 -> 615985.37 | G10: ='I+D'!G9+iT!G9 -> 717312.07 | H10: ='I+D'!H9+iT!H9 -> 0 | I10: ='I+D'!I9+iT!I9 -> 0
B11: Personal investigador cualificado de adscripción exclusiva (sólo proyectos I+D) | D11: ='I+D'!D10+iT!D10 -> 0 | E11: ='I+D'!E10+iT!E10 -> 0 | F11: ='I+D'!F10+iT!F10 -> 0 | G11: ='I+D'!G10+iT!G10 -> 0 | H11: ='I+D'!H10+iT!H10 -> 0 | I11: ='I+D'!I10+iT!I10 -> 0
B12: Amortización de elementos de inmovilizado material e intangible | D12: ='I+D'!D11+iT!D11 -> 0 | E12: ='I+D'!E11+iT!E11 -> 0 | F12: ='I+D'!F11+iT!F11 -> 0 | G12: ='I+D'!G11+iT!G11 -> 0 | H12: ='I+D'!H11+iT!H11 -> 0 | I12: ='I+D'!I11+iT!I11 -> 0
B13: Material fungible | D13: ='I+D'!D12+iT!D12 -> 0 | E13: ='I+D'!E12+iT!E12 -> 0 | F13: ='I+D'!F12+iT!F12 -> 0 | G13: ='I+D'!G12+iT!G12 -> 0 | H13: ='I+D'!H12+iT!H12 -> 0 | I13: ='I+D'!I12+iT!I12 -> 0
B14: Colaboraciones Externas: Universidades, OPIs y/o CITs | D14: ='I+D'!D13+iT!D13 -> 0 | E14: ='I+D'!E13+iT!E13 -> 0 | F14: ='I+D'!F13+iT!F13 -> 0 | G14: ='I+D'!G13+iT!G13 -> 0 | H14: ='I+D'!H13+iT!H13 -> 0 | I14: ='I+D'!I13+iT!I13 -> 0
B15: Otras colaboraciones externas | D15: ='I+D'!D14+iT!D14 -> 456666.03 | E15: ='I+D'!E14+iT!E14 -> 1038499.4 | F15: ='I+D'!F14+iT!F14 -> 1464584.9 | G15: ='I+D'!G14+iT!G14 -> 1230667.2 | H15: ='I+D'!H14+iT!H14 -> 0 | I15: ='I+D'!I14+iT!I14 -> 0
B16: Otros gastos | D16: ='I+D'!D15+iT!D15 -> 0 | E16: ='I+D'!E15+iT!E15 -> 0 | F16: ='I+D'!F15+iT!F15 -> 0 | G16: ='I+D'!G15+iT!G15 -> 0 | H16: ='I+D'!H15+iT!H15 -> 0 | I16: ='I+D'!I15+iT!I15 -> 0
B17: TOTAL COSTES / GASTOS | D17: =SUM(D10:D16) -> 967989.03 | E17: =SUM(E10:E16) -> 1611389.2 | F17: =SUM(F10:F16) -> 2080570.2 | G17: =SUM(G10:G16) -> 1947979.2 | H17: =SUM(H10:H16) -> 0 | I17: =SUM(I10:I16) -> 0
B19: TOTAL INVERSIÓN EN ELEMENTOS DE INMOVILIZADO MATERIAL E INTANGIBLE | D19: ='El._inmovilizado (INVERSIÓN)'!D31 -> 0 | E19: ='El._inmovilizado (INVERSIÓN)'!G31 -> 0 | F19: ='El._inmovilizado (INVERSIÓN)'!J31 -> 0 | G19: ='El._inmovilizado (INVERSIÓN)'!M31 -> 0 | H19: ='El._inmovilizado (INVERSIÓN)'!P31 -> 0 | I19: ='El._inmovilizado (INVERSIÓN)'!S31 -> 0

Sheet DESVIACIONES
A3: FICHA DE DESVIACIONES (sólo en caso de solicitud de informe del tipo a)
A5: ENUMERACIÓN DE LAS DESVIACIONES SUPERIORES AL 20% DEL PRESUPUESTO DEL PROYECTO:
A7: Nº | B7: CONCEPTO | C7: IDENTIFICACIÓN | D7: Presupuesto de Proyecto | G7: Efectivamente Incurrido | J7: Porcentaje
B8: (Personal, Colaboraciones, etc.) | C8: (Nombre de la persona, entidad, material, etc.) | D8: Coste/Gasto I+D | E8: Coste/Gasto IT | F8: Coste/Gasto total | G8: Coste/Gasto I+D | H8: Coste/Gasto IT | I8: Coste/Gasto total | J8: (%)
A9: 1 | B9: Personal aplicado a actividades de I+D+i | F9: =SUM(D9:E9) -> 0 | I9: =SUM(G9:H9) -> 0 | J9: =IF(F9=0,"",(I9-F9)/F9*100)
A10: 2 | B10: Personal investigador cualificado y en exclusiva a I+D | F10: =SUM(D10:E10) -> 0 | I10: =SUM(G10:H10) -> 0 | J10: =IF(F10=0,"",(I10-F10)/F10*100)
A11: 3 | B11: Amortización de elementos de inmovilizado material e Intangible | F11: =SUM(D11:E11) -> 0 | I11: =SUM(G11:H11) -> 0 | J11: =IF(F11=0,"",(I11-F11)/F11*100)
A12: 4 | B12: Material fungible | F12: =SUM(D12:E12) -> 0 | I12: =SUM(G12:H12) -> 0 | J12: =IF(F12=0,"",(I12-F12)/F12*100)
A13: 5 | B13: Colaboraciones Externas: Universidades, OPIs y/o CITs | F13: =SUM(D13:E13) -> 0 | I13: =SUM(G13:H13) -> 0 | J13: =IF(F13=0,"",(I13-F13)/F13*100)
A14: 6 | B14: Otras colaboraciones externas | F14: =SUM(D14:E14) -> 0 | I14: =SUM(G14:H14) -> 0 | J14: =IF(F14=0,"",(I14-F14)/F14*100)
A15: 7 | B15: Otros gastos | F15: =SUM(D15:E15) -> 0 | I15: =SUM(G15:H15) -> 0 | J15: =IF(F15=0,"",(I15-F15)/F15*100)
A16: TOTAL | D16: =SUM(D9:D15) -> 0 | E16: =SUM(E9:E15) -> 0 | F16: =SUM(F9:F15) -> 0 | G16: =SUM(G9:G15) -> 0 | H16: =SUM(H9:H15) -> 0 | I16: =SUM(I9:I15) -> 0 | J16: =IF(F16=0,"",(I16-F16)/F16*100)

Sheet DOC JUSTIFICATIVOS
C3: LISTADO DE LOS DOCUMENTOS JUSTIFICATIVOS DE LOS GASTOS O COSTES INCURRIDOS EN EL PROYECTO
C5: Nº | E5: NOMBRE | F5: Nº/TIPO DE DOCUMENTO | G5: FECHA | H5: TITULACIÓN | I5: IMPORTE (€)
I6: I+D | J6: IT | K6: TOTAL
C8: Personal aplicado a actividades de I+D+i
C9: 1 | E9: ALBERTO MARGAÑON MENDEZ | F9: IDC-RNT-CCRR | G9: 44561 | H9: =Personal!D15 -> Ingeniero Superior en Organización Industrial | J9: 68037.48 | K9: =I9+J9 -> 68037.48
C10: =C9+1 -> 2 | E10: ANTONIO PULIDO RUIZ | F10: IDC-RNT-CCRR | G10: 44561 | H10: =Personal!D16 -> Ingeniero de Telecomunicaciones | J10: 42547.69 | K10: =I10+J10 -> 42547.69
C11: =C10+1 -> 3 | E11: BERNARDO PEREZ DOMINGUEZ | F11: IDC-RNT-CCRR | G11: 44561 | H11: =Personal!D17 -> Ingeniero de Telecomunicaciones | J11: 63772.74 | K11: =I11+J11 -> 63772.74
C12: =C11+1 -> 4 | E12: CALOGERO AVOLA | F12: IDC-RNT-CCRR | G12: 44561 | H12: =Personal!D18 -> Ingeniería electrónica y de Comunicaciones | J12: 64169.46 | K12: =I12+J12 -> 64169.46
C13: =C12+1 -> 5 | E13: JOSE LUIS VILLARRUBIA TEJERO | F13: IDC-RNT-CCRR | G13: 44561 | H13: =Personal!D19 -> Ingeniero de Telecomunicaciones | J13: 45397.4 | K13: =I13+J13 -> 45397.4
C14: =C13+1 -> 6 | E14: JOSE RAMON ARNAU RAMIREZ | F14: IDC-RNT-CCRR | G14: 44561 | H14: =Personal!D20 -> CFGS Electrónica | J14: 52171.15 | K14: =I14+J14 -> 52171.15
C15: =C14+1 -> 7 | E15: JULIAN GODINO GUTIERREZ | F15: IDC-RNT-CCRR | G15: 44561 | H15: =Personal!D21 -> Ingeniería Informática | J15: 58631.91 | K15: =I15+J15 -> 58631.91
C16: =C15+1 -> 8 | E16: MIGUEL ANGEL FERREIRO RODRIGUEZ | F16: IDC-RNT-CCRR | G16: 44561 | H16: =Personal!D22 -> Ingeniero Superior Telecomunicación | J16: 54177.89 | K16: =I16+J16 -> 54177.89
C17: =C16+1 -> 9 | E17: SUSANA ALVAREZ GONZALEZ | F17: IDC-RNT-CCRR | G17: 44561 | H17: =Personal!D23 -> Ingeniero Técnico industrial, especialidad Eléctrica | J17: 62417.28 | K17: =I17+J17 -> 62417.28
C18: =C17+1 -> 10 | K18: =I18+J18 -> 0
C19: Total | I19: =SUM(I9:I18) -> 0 | J19: =SUM(J9:J18) -> 511323 | K19: =SUM(K9:K18) -> 511323
C21: Personal Investigador cualificado y aplicado en exclusiva a actividades de I+D
C22: 1 | K22: =I22 -> 0
C23: =C22+1 -> 2 | K23: =I23 -> 0
C24: =C23+1 -> 3 | K24: =I24 -> 0
C25: =C24+1 -> 4 | K25: =I25 -> 0
C26: =C25+1 -> 5 | K26: =I26 -> 0
C27: =C26+1 -> 6 | K27: =I27 -> 0
C28: =C27+1 -> 7 | K28: =I28 -> 0
C29: =C28+1 -> 8 | K29: =I29 -> 0
C30: =C29+1 -> 9 | K30: =I30 -> 0
C31: =C30+1 -> 10 | K31: =I31 -> 0
C32: Total | I32: =SUM(I22:I31) -> 0 | K32: =SUM(K22:K31) -> 0
C34: Nº | E34: ORIGEN/PROVEEDOR | F34: Nº DOC./FACTURA | G34: FECHA | H34: CONCEPTO | I34: IMPORTE (€)
I35: I+D | J35: IT | K35: TOTAL
C37: Amortización de elementos de inmovilizado material e intangible
C38: 1 | K38: =I38+J38 -> 0
C39: =C38+1 -> 2 | K39: =I39+J39 -> 0
C40: =C39+1 -> 3 | K40: =I40+J40 -> 0
C41: =C40+1 -> 4 | K41: =I41+J41 -> 0
C42: =C41+1 -> 5 | K42: =I42+J42 -> 0
C43: =C42+1 -> 6 | K43: =I43+J43 -> 0
C44: =C43+1 -> 7 | K44: =I44+J44 -> 0
C45: =C44+1 -> 8 | K45: =I45+J45 -> 0
C46: =C45+1 -> 9 | K46: =I46+J46 -> 0
C47: =C46+1 -> 10 | K47: =I47+J47 -> 0
...
