Workbook

Sheet Datos solicitud
B3: DATOS RELATIVOS A LA SOLICITUD DE INFORME MOTIVADO
B5: RAZÓN SOCIAL ENTIDAD: | E5: ORANGE ESPAGNE S.A.U
B7: TÍTULO DEL PROYECTO: | E7: DESARROLLO DE SISTEMA ESHOP DIGITAL MEDIANTE ARQUITECTURA AVANZADA PARA EXPERIENCIAS MULTIMARCA
B10: EJERCICIO FISCAL DE SOLICITUD (dd/mm/aaaa): | E10: FECHA INICIO: | F10: 44562 | G10: FECHA FIN: | H10: 44926
B12: AÑO DE INICIO DEL PROYECTO: | E12: 2021
B14: Nº DE EXPEDIENTE (INFORME MOTIVADO):

Sheet Instrucciones
B3: INSTRUCCIONES
B5: 1- Debe entregarse un único documento PDF que incluya, por lo menos, todas las Hojas del Formulario donde se hayan introducido datos. Las Hojas deben presentarse en el orden establecido en esta plantilla. La primera página del PDF debe ser la Hoja 'Datos solicitud' con los datos de la solicitante. No agregue al documento PDF resultante otras páginas diferentes a las expuestas en este Formulario. No es necesario que la presente Hoja con instrucciones se incluya en el PDF resultante que ha de entregarse, pero, si se muestra, debe ser escalada ajustando la hoja en una única página. Deben seguirse las instrucciones concretas marcadas en fuente roja que se exponen al inicio de algunas de las Hojas del Formulario. Las Hojas 'I+D' e 'IT' deberán ser incluidas en función de la calificación que haya sido consignada en las Hojas restantes. La Hoja 'TOTAL' debe ser incluida obligatoriamente en todos los casos. 2- Para solicitudes tipo 'A' es obligatorio incluir la Hoja con la “Ficha de desviaciones” y describir aquellas desviaciones que sean superiores al 20%. Así mismo, para solicitudes tipo 'A' es obligatorio incluir la Hoja con el Listado de documentos justificativos de los gastos correctamente cumplimentado en cada fila/celda (incluso para los Formularios "adicionales" que deben presentarse en solicitudes de AIEs). 3- En cada Hoja, deben añadirse tantas filas como se consideren necesarias. En cada fila añadida deben reproducirse las Fórmulas existentes en la Hoja para que se efectúen los cálculos automáticos. No deben realizarse modificaciones en las Fórmulas. Debe respetarse la estructura general del Formulario. No elimine las Filas que no utilice, deje en blanco las que no considere oportunas. 4- Los gastos reflejados en cada una de las Hojas deben guardar correspondencia entre sí. A su vez, los gastos mostrados en el presente Formulario deben coincidir con los 'Gastos Presentados/Presupuestados' que se muestren en el 'Informe Técnico de la EC' y en el 'Informe Técnico XSIG (XML)' que deben acompañar a su Solicitud. Es decir, deben mostrarse los valores de los gastos presentados a Certificación, no los gastos resultantes de dicha Certificación (salvo que sean idénticos). De igual forma, los gastos mostrados deben coincidir con los 'Gastos Presentados/Presupuestados' que se muestren en la Memoria Técnica/Económica. 5- Si el proyecto tiene una duración mayor de 6 anualidades, deberán entregarse dos o más Formularios. Uno que abarque las anualidades 1-6, otro 7-12, y así sucesivamente. En estos casos, en cada Formulario deberá indicarse como 'Año de Inicio' el primero de los años empleados en ese rango. En cualquier caso, no se deben añadir/eliminar columnas. 6- Los datos del Ejercicio fiscal y del Título del proyecto deben responder con exactitud a lo asociado a la solicitud de informe motivado. El Título no puede superar los 100 caracteres. 7- Debe respetarse la estructura y el formato del documento. El contenido descriptivo de cada línea de gasto ha de ser reflejado obligatoriamente en Castellano, incluyendo los campos 'Concepto' y 'Titulación' del 'Listado de los documentos justificativos...'. No se admite incluir más de 400 caracteres en cada uno de los campos del Formulario. Si se incluyen más de 400 caracteres el documento no se considerará válido. 8- En el campo 'CONCEPTO' de cada Línea de gasto (incluyendo al 'Listado de los documentos justificativos...') deberá describirse sintéticamente el gasto, sin limitarse a una mera descripción genérica como “servicios profesionales”, “materiales varios”, “gastos según pedido X”, etc.). Es decir, el contenido de cada Fila ha de ser representativo del Gasto asociado. 9- Al transformar el documento en PDF se debe asegurar que el contenido incluido en las celdas no se oculta en la transformación, ya que, en dicho caso, el documento no se considerará válido. Si es necesario se pueden separar las Filas de una tabla en diferentes páginas, pero NO se admite separar las Columnas de una misma tabla en diferentes páginas. Verifique que, para cada tabla, se muestran todas las columnas. 10- En caso de tratarse de un Formulario "adicional", en el campo "Razón social entidad", a la derecha del dato de la AIE solicitante, se debe reflejar entre paréntesis, la Razón Social de la entidad subcontratada de la que se aporta el Formulario "adicional".

Sheet Personal
B4: 2.1 PERSONAL INVESTIGADOR
B6: - Para anualidades no finalizadas en la fecha de la entrega del documento, si aún no se conocen los datos concretos de una persona, en el campo "Nombre y apellidos" se reflejará el "Perfil profesional". También aplica para solicitudes registradas por una AGRUPACIÓN DE INTERÉS ECONÓMICO (AIE), para personas participantes en el proyecto de una colaboradora de “segundo nivel” o sucesivos.
B8: - En la columna 'Excl I+D`se indicará si se trata o no de un investigador adscrito en exclusiva a I+D.
B10: - Para cada una de las personas participantes en el proyecto, se cumplimentará su correspondiente Ficha de ampliación del apartado 2.1.
B13: Código Persona | C13: Nombre y Apellidos | D13: Titulación | E13: Excl I+D (SÍ/NO) | F13: ='Datos solicitud'!E12 -> 2021 | K13: =F13+1 -> 2022 | P13: =K13+1 -> 2023 | U13: =P13+1 -> 2024 | Z13: =U13+1 -> 2025 | AE13: =Z13+1 -> 2026
F14: Horas imputadas I+D | G14: Coste/Gasto I+D | H14: Horas imputadas IT | I14: Coste/Gasto IT | J14: Coste/Gasto TOTAL | K14: Horas imputadas I+D | L14: Coste/Gasto I+D | M14: Horas imputadas IT | N14: Coste/Gasto IT | O14: Coste/Gasto TOTAL | P14: Horas imputadas I+D | Q14: Coste/Gasto I+D | R14: Horas imputadas IT | S14: Coste/Gasto IT | T14: Coste/Gasto TOTAL | U14: Horas imputadas I+D | V14: Coste/Gasto I+D | W14: Horas imputadas IT | X14: Coste/Gasto IT | Y14: Coste/Gasto TOTAL | Z14: Horas imputadas I+D | AA14: Coste/Gasto I+D | AB14: Horas imputadas IT | AC14: Coste/Gasto IT | AD14: Coste/Gasto TOTAL | AE14: Horas imputadas I+D | AF14: Coste/Gasto I+D | AG14: Horas imputadas IT | AH14: Coste/Gasto IT | AI14: Coste/Gasto TOTAL
B15: 1 | C15: CRISTINA BAYON VALTIERRA | D15: FÍSICAS | E15: NO | J15: =G15+I15 -> 0 | M15: 1446.38 | N15: 70540.24 | O15: =L15+N15 -> 70540.24 | T15: =Q15+S15 -> 0 | Y15: =V15+X15 -> 0 | AD15: =AA15+AC15 -> 0 | AI15: =AF15+AH15 -> 0
B16: =B15+1 -> 2 | C16: DAVID GARRIDO ANDRES | D16: INFORMÁTICA | E16: NO | J16: =G16+I16 -> 0 | M16: 1653 | N16: 60242.99 | O16: =L16+N16 -> 60242.99 | T16: =Q16+S16 -> 0 | Y16: =V16+X16 -> 0 | AD16: =AA16+AC16 -> 0 | AI16: =AF16+AH16 -> 0
B17: =B16+1 -> 3 | C17: MARIA LUISA SANTIAGO CHIQUERO | D17: MATEMÁTICAS | E17: NO | J17: =G17+I17 -> 0 | M17: 1446.38 | N17: 58665.38 | O17: =L17+N17 -> 58665.38 | T17: =Q17+S17 -> 0 | Y17: =V17+X17 -> 0 | AD17: =AA17+AC17 -> 0 | AI17: =AF17+AH17 -> 0
B18: =B17+1 -> 4 | C18: SILVIA VAZQUEZ INSAUSTI | D18: MATEMÁTICAS | E18: NO | J18: =G18+I18 -> 0 | M18: 1631.25 | N18: 65538.6 | O18: =L18+N18 -> 65538.6 | T18: =Q18+S18 -> 0 | Y18: =V18+X18 -> 0 | AD18: =AA18+AC18 -> 0 | AI18: =AF18+AH18 -> 0
B19: =B18+1 -> 5 | C19: TOTAL PERSONAL 2021 | E19: NO | H19: 2966.34 | I19: 95704.36 | J19: =G19+I19 -> 95704.36 | O19: =L19+N19 -> 0 | T19: =Q19+S19 -> 0 | Y19: =V19+X19 -> 0 | AD19: =AA19+AC19 -> 0 | AI19: =AF19+AH19 -> 0
B20: =B19+1 -> 6 | E20: NO | J20: =G20+I20 -> 0 | O20: =L20+N20 -> 0 | T20: =Q20+S20 -> 0 | Y20: =V20+X20 -> 0 | AD20: =AA20+AC20 -> 0 | AI20: =AF20+AH20 -> 0
B21: =B20+1 -> 7 | E21: NO | J21: =G21+I21 -> 0 | O21: =L21+N21 -> 0 | T21: =Q21+S21 -> 0 | Y21: =V21+X21 -> 0 | AD21: =AA21+AC21 -> 0 | AI21: =AF21+AH21 -> 0
B22: =B21+1 -> 8 | E22: NO | J22: =G22+I22 -> 0 | O22: =L22+N22 -> 0 | T22: =Q22+S22 -> 0 | Y22: =V22+X22 -> 0 | AD22: =AA22+AC22 -> 0 | AI22: =AF22+AH22 -> 0
B23: =B22+1 -> 9 | E23: NO | J23: =G23+I23 -> 0 | O23: =L23+N23 -> 0 | T23: =Q23+S23 -> 0 | Y23: =V23+X23 -> 0 | AD23: =AA23+AC23 -> 0 | AI23: =AF23+AH23 -> 0
B24: =B23+1 -> 10 | E24: NO | J24: =G24+I24 -> 0 | O24: =L24+N24 -> 0 | T24: =Q24+S24 -> 0 | Y24: =V24+X24 -> 0 | AD24: =AA24+AC24 -> 0 | AI24: =AF24+AH24 -> 0
B25: =B24+1 -> 11 | E25: NO | J25: =G25+I25 -> 0 | O25: =L25+N25 -> 0 | T25: =Q25+S25 -> 0 | Y25: =V25+X25 -> 0 | AD25: =AA25+AC25 -> 0 | AI25: =AF25+AH25 -> 0
B26: =B25+1 -> 12 | E26: NO | J26: =G26+I26 -> 0 | O26: =L26+N26 -> 0 | T26: =Q26+S26 -> 0 | Y26: =V26+X26 -> 0 | AD26: =AA26+AC26 -> 0 | AI26: =AF26+AH26 -> 0
B27: =B26+1 -> 13 | E27: NO | J27: =G27+I27 -> 0 | O27: =L27+N27 -> 0 | T27: =Q27+S27 -> 0 | Y27: =V27+X27 -> 0 | AD27: =AA27+AC27 -> 0 | AI27: =AF27+AH27 -> 0
B28: =B27+1 -> 14 | E28: NO | J28: =G28+I28 -> 0 | O28: =L28+N28 -> 0 | T28: =Q28+S28 -> 0 | Y28: =V28+X28 -> 0 | AD28: =AA28+AC28 -> 0 | AI28: =AF28+AH28 -> 0
B29: =B28+1 -> 15 | E29: NO | J29: =G29+I29 -> 0 | O29: =L29+N29 -> 0 | T29: =Q29+S29 -> 0 | Y29: =V29+X29 -> 0 | AD29: =AA29+AC29 -> 0 | AI29: =AF29+AH29 -> 0
B30: =B29+1 -> 16 | E30: NO | J30: =G30+I30 -> 0 | O30: =L30+N30 -> 0 | T30: =Q30+S30 -> 0 | Y30: =V30+X30 -> 0 | AD30: =AA30+AC30 -> 0 | AI30: =AF30+AH30 -> 0
B31: =B30+1 -> 17 | E31: NO | J31: =G31+I31 -> 0 | O31: =L31+N31 -> 0 | T31: =Q31+S31 -> 0 | Y31: =V31+X31 -> 0 | AD31: =AA31+AC31 -> 0 | AI31: =AF31+AH31 -> 0
... B34: =B33+1 -> 20 | E34: NO | J34: =G34+I34 -> 0 | O34: =L34+N34 -> 0 | T34: =Q34+S34 -> 0 | Y34: =V34+X34 -> 0 | AD34: =AA34+AC34 -> 0 | AI34: =AF34+AH34 -> 0
D35: TOTAL personal NO ADSCRITO EN EXCLUSIVA a Actividades de I+D | F35: =SUMIF($E15:$E34,"<>SÍ",F15:F34) -> 0 | G35: =SUMIF($E15:$E34,"<>SÍ",G15:G34) -> 0 | H35: =SUMIF($E15:$E34,"<>SÍ",H15:H34) -> 2966.34 | I35: =SUMIF($E15:$E34,"<>SÍ",I15:I34) -> 95704.36 | J35: =G35+I35 -> 95704.36 | K35: =SUMIF($E15:$E34,"<>SÍ",K15:K34) -> 0 | L35: =SUMIF($E15:$E34,"<>SÍ",L15:L34) -> 0 | M35: =SUMIF($E15:$E34,"<>SÍ",M15:M34) -> 6177.01 | N35: =SUMIF($E15:$E34,"<>SÍ",N15:N34) -> 254987.21 | O35: =L35+N35 -> 254987.21 | P35: =SUMIF($E15:$E34,"<>SÍ",P15:P34) -> 0 | Q35: =SUMIF($E15:$E34,"<>SÍ",Q15:Q34) -> 0 | R35: =SUMIF($E15:$E34,"<>SÍ",R15:R34) -> 0 | S35: =SUMIF($E15:$E34,"<>SÍ",S15:S34) -> 0 | T35: =Q35+S35 -> 0 | U35: =SUMIF($E15:$E34,"<>SÍ",U15:U34) -> 0 | V35: =SUMIF($E15:$E34,"<>SÍ",V15:V34) -> 0 | W35: =SUMIF($E15:$E34,"<>SÍ",W15:W34) -> 0 | X35: =SUMIF($E15:$E34,"<>SÍ",X15:X34) -> 0 | Y35: =V35+X35 -> 0 | Z35: =SUMIF($E15:$E34,"<>SÍ",Z15:Z34) -> 0 | AA35: =SUMIF($E15:$E34,"<>SÍ",AA15:AA34) -> 0 | AB35: =SUMIF($E15:$E34,"<>SÍ",AB15:AB34) -> 0 | AC35: =SUMIF($E15:$E34,"<>SÍ",AC15:AC34) -> 0 | AD35: =AA35+AC35 -> 0 | AE35: =SUMIF($E15:$E34,"<>SÍ",AE15:AE34) -> 0 | AF35: =SUMIF($E15:$E34,"<>SÍ",AF15:AF34) -> 0 | AG35: =SUMIF($E15:$E34,"<>SÍ",AG15:AG34) -> 0 | AH35: =SUMIF($E15:$E34,"<>SÍ",AH15:AH34) -> 0 | AI35: =AF35+AH35 -> 0
D36: TOTAL personal ADSCRITO EN EXCLUSIVA a Actividades de I+D | F36: =SUMIF($E15:$E34,"SÍ",F15:F34) -> 0 | G36: =SUMIF($E15:$E34,"SÍ",G15:G34) -> 0 | J36: =G36 -> 0 | K36: =SUMIF($E15:$E34,"SÍ",K15:K34) -> 0 | L36: =SUMIF($E15:$E34,"SÍ",L15:L34) -> 0 | O36: =L36 -> 0 | P36: =SUMIF($E15:$E34,"SÍ",P15:P34) -> 0 | Q36: =SUMIF($E15:$E34,"SÍ",Q15:Q34) -> 0 | T36: =Q36 -> 0 | U36: =SUMIF($E15:$E34,"SÍ",U15:U34) -> 0 | V36: =SUMIF($E15:$E34,"SÍ",V15:V34) -> 0 | Y36: =V36 -> 0 | Z36: =SUMIF($E15:$E34,"SÍ",Z15:Z34) -> 0 | AA36: =SUMIF($E15:$E34,"SÍ",AA15:AA34) -> 0 | AD36: =AA36 -> 0 | AE36: =SUMIF($E15:$E34,"SÍ",AE15:AE34) -> 0 | AF36: =SUMIF($E15:$E34,"SÍ",AF15:AF34) -> 0 | AI36: =AF36 -> 0
D37: TOTAL PERSONAL | F37: =F35+F36 -> 0 | G37: =G35+G36 -> 0 | H37: =H35 -> 2966.34 | I37: =I35 -> 95704.36 | J37: =G37+I37 -> 95704.36 | K37: =K35+K36 -> 0 | L37: =L35+L36 -> 0 | M37: =M35 -> 6177.01 | N37: =N35 -> 254987.21 | O37: =L37+N37 -> 254987.21 | P37: =P35+P36 -> 0 | Q37: =Q35+Q36 -> 0 | R37: =R35 -> 0 | S37: =S35 -> 0 | T37: =Q37+S37 -> 0 | U37: =U35+U36 -> 0 | V37: =V35+V36 -> 0 | W37: =W35 -> 0 | X37: =X35 -> 0 | Y37: =V37+X37 -> 0 | Z37: =Z35+Z36 -> 0 | AA37: =AA35+AA36 -> 0 | AB37: =AB35 -> 0 | AC37: =AC35 -> 0 | AD37: =AA37+AC37 -> 0 | AE37: =AE35+AE36 -> 0 | AF37: =AF35+AF36 -> 0 | AG37: =AG35 -> 0 | AH37: =AH35 -> 0 | AI37: =AF37+AH37 -> 0

Sheet C.Externas (OPIS)
B4: 2.2 COLABORACIONES EXTERNAS
B5: 2.2.1 Universidades, Organismos Públicos de Investigación y Centros de Innovación y Tecnología (reconocidos y registrados como tales)
B7: - Para anualidades no finalizadas en la fecha de la entrega del documento, si aún no se conocen los datos específicos de la entidad colaboradora, en el campo "Razón social" se reflejarán los trabajos/actividades principales que va a acometer.
B9: - Es obligatorio indicar la 'Tipología' de la colaboración (UNI, OPI o CIT).
B11: - Por cada una de las entidades colaboradoras, se cumplimentará/n su/s correspondiente/s Ficha/s de ampliación del apartado 2.2 y el resto de Fichas "adicionales" cuando proceda.
B14: Código Colaboración | C14: Razón Social de Entidad Colaboradora | D14: NIF | E14: Tipo | F14: =Personal!F13 -> 2021 | I14: =F14+1 -> 2022 | L14: =I14+1 -> 2023 | O14: =L14+1 -> 2024 | R14: =O14+1 -> 2025 | U14: =R14+1 -> 2026
B15: Código Recurso | C15: Nombre | F15: Coste/Gasto I+D | G15: Coste/Gasto IT | H15: Coste/Gasto TOTAL | I15: Coste/Gasto I+D | J15: Coste/Gasto IT | K15: Coste/Gasto TOTAL | L15: Coste/Gasto I+D | M15: Coste/Gasto IT | N15: Coste/Gasto TOTAL | O15: Coste/Gasto I+D | P15: Coste/Gasto IT | Q15: Coste/Gasto TOTAL | R15: Coste/Gasto I+D | S15: Coste/Gasto IT | T15: Coste/Gasto TOTAL | U15: Coste/Gasto I+D | V15: Coste/Gasto IT | W15: Coste/Gasto TOTAL
B16: 1 | H16: =SUM(F16:G16) -> 0 | K16: =SUM(I16:J16) -> 0 | N16: =SUM(L16:M16) -> 0 | Q16: =SUM(O16:P16) -> 0 | T16: =SUM(R16:S16) -> 0 | W16: =U16+V16 -> 0
B17: =B16+1 -> 2 | H17: =SUM(F17:G17) -> 0 | K17: =SUM(I17:J17) -> 0 | N17: =SUM(L17:M17) -> 0 | Q17: =SUM(O17:P17) -> 0 | T17: =SUM(R17:S17) -> 0 | W17: =U17+V17 -> 0
B18: =B17+1 -> 3 | H18: =SUM(F18:G18) -> 0 | K18: =SUM(I18:J18) -> 0 | N18: =SUM(L18:M18) -> 0 | Q18: =SUM(O18:P18) -> 0 | T18: =SUM(R18:S18) -> 0 | W18: =U18+V18 -> 0
B19: =B18+1 -> 4 | H19: =SUM(F19:G19) -> 0 | K19: =SUM(I19:J19) -> 0 | N19: =SUM(L19:M19) -> 0 | Q19: =SUM(O19:P19) -> 0 | T19: =SUM(R19:S19) -> 0 | W19: =U19+V19 -> 0
B20: =B19+1 -> 5 | H20: =SUM(F20:G20) -> 0 | K20: =SUM(I20:J20) -> 0 | N20: =SUM(L20:M20) -> 0 | Q20: =SUM(O20:P20) -> 0 | T20: =SUM(R20:S20) -> 0 | W20: =U20+V20 -> 0
B21: =B20+1 -> 6 | H21: =SUM(F21:G21) -> 0 | K21: =SUM(I21:J21) -> 0 | N21: =SUM(L21:M21) -> 0 | Q21: =SUM(O21:P21) -> 0 | T21: =SUM(R21:S21) -> 0 | W21: =U21+V21 -> 0
B22: =B21+1 -> 7 | H22: =SUM(F22:G22) -> 0 | K22: =SUM(I22:J22) -> 0 | N22: =SUM(L22:M22) -> 0 | Q22: =SUM(O22:P22) -> 0 | T22: =SUM(R22:S22) -> 0 | W22: =U22+V22 -> 0
B23: =B22+1 -> 8 | H23: =SUM(F23:G23) -> 0 | K23: =SUM(I23:J23) -> 0 | N23: =SUM(L23:M23) -> 0 | Q23: =SUM(O23:P23) -> 0 | T23: =SUM(R23:S23) -> 0 | W23: =U23+V23 -> 0
B24: =B23+1 -> 9 | H24: =SUM(F24:G24) -> 0 | K24: =SUM(I24:J24) -> 0 | N24: =SUM(L24:M24) -> 0 | Q24: =SUM(O24:P24) -> 0 | T24: =SUM(R24:S24) -> 0 | W24: =U24+V24 -> 0
B25: =B24+1 -> 10 | H25: =SUM(F25:G25) -> 0 | K25: =SUM(I25:J25) -> 0 | N25: =SUM(L25:M25) -> 0 | Q25: =SUM(O25:P25) -> 0 | T25: =SUM(R25:S25) -> 0 | W25: =U25+V25 -> 0
B26: =B25+1 -> 11 | H26: =SUM(F26:G26) -> 0 | K26: =SUM(I26:J26) -> 0 | N26: =SUM(L26:M26) -> 0 | Q26: =SUM(O26:P26) -> 0 | T26: =SUM(R26:S26) -> 0 | W26: =U26+V26 -> 0
B27: =B26+1 -> 12 | H27: =SUM(F27:G27) -> 0 | K27: =SUM(I27:J27) -> 0 | N27: =SUM(L27:M27) -> 0 | Q27: =SUM(O27:P27) -> 0 | T27: =SUM(R27:S27) -> 0 | W27: =U27+V27 -> 0
B28: =B27+1 -> 13 | H28: =SUM(F28:G28) -> 0 | K28: =SUM(I28:J28) -> 0 | N28: =SUM(L28:M28) -> 0 | Q28: =SUM(O28:P28) -> 0 | T28: =SUM(R28:S28) -> 0 | W28: =U28+V28 -> 0
... B35: =B34+1 -> 20 | H35: =SUM(F35:G35) -> 0 | K35: =SUM(I35:J35) -> 0 | N35: =SUM(L35:M35) -> 0 | Q35: =SUM(O35:P35) -> 0 | T35: =SUM(R35:S35) -> 0 | W35: =U35+V35 -> 0
C36: TOTAL COLABORACIONES EXTERNAS contratadas / encargadas a UNIVERSIDADES | E36: UNI | F36: =SUMIF($E$16:$E$35,$E36,F$16:F$35) -> 0 | G36: =SUMIF($E$16:$E$35,$E36,G$16:G$35) -> 0 | H36: =SUM(F36:G36) -> 0 | I36: =SUMIF($E$16:$E$35,$E36,I$16:I$35) -> 0 | J36: =SUMIF($E$16:$E$35,$E36,J$16:J$35) -> 0 | K36: =SUM(I36:J36) -> 0 | L36: =SUMIF($E$16:$E$35,$E36,L$16:L$35) -> 0 | M36: =SUMIF($E$16:$E$35,$E36,M$16:M$35) -> 0 | N36: =SUM(L36:M36) -> 0 | O36: =SUMIF($E$16:$E$35,$E36,O$16:O$35) -> 0 | P36: =SUMIF($E$16:$E$35,$E36,P$16:P$35) -> 0 | Q36: =SUM(O36:P36) -> 0 | R36: =SUMIF($E$16:$E$35,$E36,R$16:R$35) -> 0 | S36: =SUMIF($E$16:$E$35,$E36,S$16:S$35) -> 0 | T36: =SUM(R36:S36) -> 0 | U36: =SUMIF($E$16:$E$35,$E36,U$16:U$35) -> 0 | V36: =SUMIF($E$16:$E$35,$E36,V$16:V$35) -> 0 | W36: =SUM(U36:V36) -> 0
C37: TOTAL COLABORACIONES EXTERNAS contratadas / encargadas a ORGANISMOS PÚBLICOS DE INVESTIGACIÓN | E37: OPI | F37: =SUMIF($E$16:$E$35,$E37,F$16:F$35) -> 0 | G37: =SUMIF($E$16:$E$35,$E37,G$16:G$35) -> 0 | H37: =SUM(F37:G37) -> 0 | I37: =SUMIF($E$16:$E$35,$E37,I$16:I$35) -> 0 | J37: =SUMIF($E$16:$E$35,$E37,J$16:J$35) -> 0 | K37: =SUM(I37:J37) -> 0 | L37: =SUMIF($E$16:$E$35,$E37,L$16:L$35) -> 0 | M37: =SUMIF($E$16:$E$35,$E37,M$16:M$35) -> 0 | N37: =SUM(L37:M37) -> 0 | O37: =SUMIF($E$16:$E$35,$E37,O$16:O$35) -> 0 | P37: =SUMIF($E$16:$E$35,$E37,P$16:P$35) -> 0 | Q37: =SUM(O37:P37) -> 0 | R37: =SUMIF($E$16:$E$35,$E37,R$16:R$35) -> 0 | S37: =SUMIF($E$16:$E$35,$E37,S$16:S$35) -> 0 | T37: =SUM(R37:S37) -> 0 | U37: =SUMIF($E$16:$E$35,$E37,U$16:U$35) -> 0 | V37: =SUMIF($E$16:$E$35,$E37,V$16:V$35) -> 0 | W37: =SUM(U37:V37) -> 0
C38: TOTAL COLABORACIONES EXTERNAS contratadas / encargadas a CENTROS DE INNOVACIÓN Y TECNOLOGÍA | E38: CIT | F38: =SUMIF($E$16:$E$35,$E38,F$16:F$35) -> 0 | G38: =SUMIF($E$16:$E$35,$E38,G$16:G$35) -> 0 | H38: =SUM(F38:G38) -> 0 | I38: =SUMIF($E$16:$E$35,$E38,I$16:I$35) -> 0 | J38: =SUMIF($E$16:$E$35,$E38,J$16:J$35) -> 0 | K38: =SUM(I38:J38) -> 0 | L38: =SUMIF($E$16:$E$35,$E38,L$16:L$35) -> 0 | M38: =SUMIF($E$16:$E$35,$E38,M$16:M$35) -> 0 | N38: =SUM(L38:M38) -> 0 | O38: =SUMIF($E$16:$E$35,$E38,O$16:O$35) -> 0 | P38: =SUMIF($E$16:$E$35,$E38,P$16:P$35) -> 0 | Q38: =SUM(O38:P38) -> 0 | R38: =SUMIF($E$16:$E$35,$E38,R$16:R$35) -> 0 | S38: =SUMIF($E$16:$E$35,$E38,S$16:S$35) -> 0 | T38: =SUM(R38:S38) -> 0 | U38: =SUMIF($E$16:$E$35,$E38,U$16:U$35) -> 0 | V38: =SUMIF($E$16:$E$35,$E38,V$16:V$35) -> 0 | W38: =SUM(U38:V38) -> 0
C39: TOTAL COL. EXTERNAS CONTRATADAS /ENCARGADAS A UNIVERSIDADES, OPIs y CCTT | F39: =F36+F37+F38 -> 0 | G39: =G36+G37+G38 -> 0 | H39: =F39+G39 -> 0 | I39: =I36+I37+I38 -> 0 | J39: =J36+J37+J38 -> 0 | K39: =I39+J39 -> 0 | L39: =L36+L37+L38 -> 0 | M39: =M36+M37+M38 -> 0 | N39: =L39+M39 -> 0 | O39: =O36+O37+O38 -> 0 | P39: =P36+P37+P38 -> 0 | Q39: =O39+P39 -> 0 | R39: =R36+R37+R38 -> 0 | S39: =S36+S37+S38 -> 0 | T39: =R39+S39 -> 0 | U39: =U36+U37+U38 -> 0 | V39: =V36+V37+V38 -> 0 | W39: =U39+V39 -> 0

Sheet C.Externas (Otros)
B4: 2.2 COLABORACIONES EXTERNAS
B5: 2.2.2 Otros (Empresas Privadas, Asociaciones, etc.)
B7: - Para anualidades no finalizadas en la fecha de la entrega del documento, si aún no se conocen los datos específicos de la entidad colaboradora, en el campo "Razón social" se reflejarán los trabajos/actividades principales que va a acometer.
B9: - Por cada una de las entidades de colaboración, se cumplimentará/n su/s correspondiente/s ficha/s de ampliación del apartado 2.2 y el resto de Fichas "adicionales" cuando proceda.
B12: Código Colaboración | C12: Razón Social de Entidad Colaboradora | D12: NIF | E12: =Personal!F13 -> 2021 | H12: =E12+1 -> 2022 | K12: =H12+1 -> 2023 | N12: =K12+1 -> 2024 | Q12: =N12+1 -> 2025 | T12: =Q12+1 -> 2026
B13: Código Recurso | C13: Nombre | E13: Coste/Gasto I+D | F13: Coste/Gasto IT | G13: Coste/Gasto TOTAL | H13: Coste/Gasto I+D | I13: Coste/Gasto IT | J13: Coste/Gasto TOTAL | K13: Coste/Gasto I+D | L13: Coste/Gasto IT | M13: Coste/Gasto TOTAL | N13: Coste/Gasto I+D | O13: Coste/Gasto IT | P13: Coste/Gasto TOTAL | Q13: Coste/Gasto I+D | R13: Coste/Gasto IT | S13: Coste/Gasto TOTAL | T13: Coste/Gasto I+D | U13: Coste/Gasto IT | V13: Coste/Gasto TOTAL
B14: 1 | C14: ALTRAN INNOVACION, S.L.U. | D14: B80428972 | G14: =E14+F14 -> 0 | I14: 335355.24 | J14: =SUM(H14:I14) -> 335355.24 | M14: =SUM(K14:L14) -> 0 | P14: =SUM(N14:O14) -> 0 | S14: =SUM(Q14:R14) -> 0 | V14: =SUM(T14:U14) -> 0
B15: =B14+1 -> 2 | C15: D-MOBILELAB SPAIN SA | D15: A82303017 | G15: =E15+F15 -> 0 | I15: 38355.26 | J15: =SUM(H15:I15) -> 38355.26 | M15: =SUM(K15:L15) -> 0 | P15: =SUM(N15:O15) -> 0 | S15: =SUM(Q15:R15) -> 0 | V15: =SUM(T15:U15) -> 0
B16: =B15+1 -> 3 | C16: INDRA SOLUCIONES TECNOLOGIAS DE LA INFORMACIÓN, S.L.U. | D16: B88018098 | G16: =E16+F16 -> 0 | I16: 215000 | J16: =SUM(H16:I16) -> 215000 | M16: =SUM(K16:L16) -> 0 | P16: =SUM(N16:O16) -> 0 | S16: =SUM(Q16:R16) -> 0 | V16: =SUM(T16:U16) -> 0
B17: =B16+1 -> 4 | C17: METODOS Y TECNOLOGIA DE SISTEMAS Y PROCESOS, S.L. | D17: B81758344 | G17: =E17+F17 -> 0 | I17: 515360.51 | J17: =SUM(H17:I17) -> 515360.51 | M17: =SUM(K17:L17) -> 0 | P17: =SUM(N17:O17) -> 0 | S17: =SUM(Q17:R17) -> 0 | V17: =SUM(T17:U17) -> 0
B18: =B17+1 -> 5 | C18: NTT DATA SPAIN SL | D18: B82387770 | G18: =E18+F18 -> 0 | I18: 91403.39 | J18: =SUM(H18:I18) -> 91403.39 | M18: =SUM(K18:L18) -> 0 | P18: =SUM(N18:O18) -> 0 | S18: =SUM(Q18:R18) -> 0 | V18: =SUM(T18:U18) -> 0
B19: =B18+1 -> 6 | C19: SALESFORCE SYSTEMS SPAIN, S.L. | D19: B84495449 | G19: =E19+F19 -> 0 | I19: 97360 | J19: =SUM(H19:I19) -> 97360 | M19: =SUM(K19:L19) -> 0 | P19: =SUM(N19:O19) -> 0 | S19: =SUM(Q19:R19) -> 0 | V19: =SUM(T19:U19) -> 0
B20: =B19+1 -> 7 | C20: TOTAL COLABORACIONES 2021 | F20: 256004.37 | G20: =E20+F20 -> 256004.37 | J20: =SUM(H20:I20) -> 0 | M20: =SUM(K20:L20) -> 0 | P20: =SUM(N20:O20) -> 0 | S20: =SUM(Q20:R20) -> 0 | V20: =SUM(T20:U20) -> 0
B21: =B20+1 -> 8 | G21: =E21+F21 -> 0 | J21: =SUM(H21:I21) -> 0 | M21: =SUM(K21:L21) -> 0 | P21: =SUM(N21:O21) -> 0 | S21: =SUM(Q21:R21) -> 0 | V21: =SUM(T21:U21) -> 0
B22: =B21+1 -> 9 | G22: =E22+F22 -> 0 | J22: =SUM(H22:I22) -> 0 | M22: =SUM(K22:L22) -> 0 | P22: =SUM(N22:O22) -> 0 | S22: =SUM(Q22:R22) -> 0 | V22: =SUM(T22:U22) -> 0
B23: =B22+1 -> 10 | G23: =E23+F23 -> 0 | J23: =SUM(H23:I23) -> 0 | M23: =SUM(K23:L23) -> 0 | P23: =SUM(N23:O23) -> 0 | S23: =SUM(Q23:R23) -> 0 | V23: =SUM(T23:U23) -> 0
B24: =B23+1 -> 11 | G24: =E24+F24 -> 0 | J24: =SUM(H24:I24) -> 0 | M24: =SUM(K24:L24) -> 0 | P24: =SUM(N24:O24) -> 0 | S24: =SUM(Q24:R24) -> 0 | V24: =SUM(T24:U24) -> 0
B25: =B24+1 -> 12 | G25: =E25+F25 -> 0 | J25: =SUM(H25:I25) -> 0 | M25: =SUM(K25:L25) -> 0 | P25: =SUM(N25:O25) -> 0 | S25: =SUM(Q25:R25) -> 0 | V25: =SUM(T25:U25) -> 0
B26: =B25+1 -> 13 | G26: =E26+F26 -> 0 | J26: =SUM(H26:I26) -> 0 | M26: =SUM(K26:L26) -> 0 | P26: =SUM(N26:O26) -> 0 | S26: =SUM(Q26:R26) -> 0 | V26: =SUM(T26:U26) -> 0
B27: =B26+1 -> 14 | G27: =E27+F27 -> 0 | J27: =SUM(H27:I27) -> 0 | M27: =SUM(K27:L27) -> 0 | P27: =SUM(N27:O27) -> 0 | S27: =SUM(Q27:R27) -> 0 | V27: =SUM(T27:U27) -> 0
B28: =B27+1 -> 15 | G28: =E28+F28 -> 0 | J28: =SUM(H28:I28) -> 0 | M28: =SUM(K28:L28) -> 0 | P28: =SUM(N28:O28) -> 0 | S28: =SUM(Q28:R28) -> 0 | V28: =SUM(T28:U28) -> 0
B29: =B28+1 -> 16 | G29: =E29+F29 -> 0 | J29: =SUM(H29:I29) -> 0 | M29: =SUM(K29:L29) -> 0 | P29: =SUM(N29:O29) -> 0 | S29: =SUM(Q29:R29) -> 0 | V29: =SUM(T29:U29) -> 0
B30: =B29+1 -> 17 | G30: =E30+F30 -> 0 | J30: =SUM(H30:I30) -> 0 | M30: =SUM(K30:L30) -> 0 | P30: =SUM(N30:O30) -> 0 | S30: =SUM(Q30:R30) -> 0 | V30: =SUM(T30:U30) -> 0
B31: =B30+1 -> 18 | G31: =E31+F31 -> 0 | J31: =SUM(H31:I31) -> 0 | M31: =SUM(K31:L31) -> 0 | P31: =SUM(N31:O31) -> 0 | S31: =SUM(Q31:R31) -> 0 | V31: =SUM(T31:U31) -> 0
B32: =B31+1 -> 19 | G32: =E32+F32 -> 0 | J32: =SUM(H32:I32) -> 0 | M32: =SUM(K32:L32) -> 0 | P32: =SUM(N32:O32) -> 0 | S32: =SUM(Q32:R32) -> 0 | V32: =SUM(T32:U32) -> 0
B33: =B32+1 -> 20 | G33: =E33+F33 -> 0 | J33: =SUM(H33:I33) -> 0 | M33: =SUM(K33:L33) -> 0 | P33: =SUM(N33:O33) -> 0 | S33: =SUM(Q33:R33) -> 0 | V33: =SUM(T33:U33) -> 0
C34: TOTAL COLABORACIONES EXTERNAS | E34: =SUM(E14:E33) -> 0 | F34: =SUM(F14:F33) -> 256004.37 | G34: =E34+F34 -> 256004.37 | H34: =SUM(H14:H33) -> 0 | I34: =SUM(I14:I33) -> 1292834.4 | J34: =SUM(J14:J33) -> 1292834.4 | K34: =SUM(K14:K33) -> 0 | L34: =SUM(L14:L33) -> 0 | M34: =SUM(M14:M33) -> 0 | N34: =SUM(N14:N33) -> 0 | O34: =SUM(O14:O33) -> 0 | ... V34: =SUM(V14:V33) -> 0

Sheet El._inmovilizado (AMORTIZACIÓN)
B4: 2.3 AMORTIZACIÓN DE ELEMENTOS DE INMOVILIZADO MATERIAL E INTANGIBLE
B6: - Para anualidades no finalizadas en la fecha de la entrega del documento, si aún no se conocen los datos específicos de un elemento de inmovilizado, en el campo "Amortización" se reflejarán los trabajos/actividades principales para los que va a ser empleado.
B8: - Por cada uno de los elementos de inmovilizado, se cumplimentará su correspondiente Ficha de ampliación del apartado 2.3.
B11: Código Elemento | C11: Amortización de Elementos de Inmovilizado Material e Intangible (Concepto específico detallado) | D11: =Personal!F13 -> 2021 | G11: =D11+1 -> 2022 | J11: =G11+1 -> 2023 | M11: =J11+1 -> 2024 | P11: =M11+1 -> 2025 | S11: =P11+1 -> 2026
B12: Código Recurso | D12: Coste/Gasto I+D | E12: Coste/Gasto IT | F12: Coste/Gasto TOTAL | G12: Coste/Gasto I+D | H12: Coste/Gasto IT | I12: Coste/Gasto TOTAL | J12: Coste/Gasto I+D | K12: Coste/Gasto IT | L12: Coste/Gasto TOTAL | M12: Coste/Gasto I+D | N12: Coste/Gasto IT | O12: Coste/Gasto TOTAL | P12: Coste/Gasto I+D | Q12: Coste/Gasto IT | R12: Coste/Gasto TOTAL | S12: Coste/Gasto I+D | T12: Coste/Gasto IT | U12: Coste/Gasto TOTAL
B13: 1 | F13: =SUM(D13:E13) -> 0 | I13: =SUM(G13:H13) -> 0 | L13: =SUM(J13:K13) -> 0 | O13: =SUM(M13:N13) -> 0 | R13: =SUM(P13:Q13) -> 0 | U13: =SUM(S13:T13) -> 0
B14: =B13+1 -> 2 | F14: =SUM(D14:E14) -> 0 | I14: =SUM(G14:H14) -> 0 | L14: =SUM(J14:K14) -> 0 | O14: =SUM(M14:N14) -> 0 | R14: =SUM(P14:Q14) -> 0 | U14: =SUM(S14:T14) -> 0
B15: =B14+1 -> 3 | F15: =SUM(D15:E15) -> 0 | I15: =SUM(G15:H15) -> 0 | L15: =SUM(J15:K15) -> 0 | O15: =SUM(M15:N15) -> 0 | R15: =SUM(P15:Q15) -> 0 | U15: =SUM(S15:T15) -> 0
B16: =B15+1 -> 4 | F16: =SUM(D16:E16) -> 0 | I16: =SUM(G16:H16) -> 0 | L16: =SUM(J16:K16) -> 0 | O16: =SUM(M16:N16) -> 0 | R16: =SUM(P16:Q16) -> 0 | U16: =SUM(S16:T16) -> 0
B17: =B16+1 -> 5 | F17: =SUM(D17:E17) -> 0 | I17: =SUM(G17:H17) -> 0 | L17: =SUM(J17:K17) -> 0 | O17: =SUM(M17:N17) -> 0 | R17: =SUM(P17:Q17) -> 0 | U17: =SUM(S17:T17) -> 0
B18: =B17+1 -> 6 | F18: =SUM(D18:E18) -> 0 | I18: =SUM(G18:H18) -> 0 | L18: =SUM(J18:K18) -> 0 | O18: =SUM(M18:N18) -> 0 | R18: =SUM(P18:Q18) -> 0 | U18: =SUM(S18:T18) -> 0
B19: =B18+1 -> 7 | F19: =SUM(D19:E19) -> 0 | I19: =SUM(G19:H19) -> 0 | L19: =SUM(J19:K19) -> 0 | O19: =SUM(M19:N19) -> 0 | R19: =SUM(P19:Q19) -> 0 | U19: =SUM(S19:T19) -> 0
B20: =B19+1 -> 8 | F20: =SUM(D20:E20) -> 0 | I20: =SUM(G20:H20) -> 0 | L20: =SUM(J20:K20) -> 0 | O20: =SUM(M20:N20) -> 0 | R20: =SUM(P20:Q20) -> 0 | U20: =SUM(S20:T20) -> 0
B21: =B20+1 -> 9 | F21: =SUM(D21:E21) -> 0 | I21: =SUM(G21:H21) -> 0 | L21: =SUM(J21:K21) -> 0 | O21: =SUM(M21:N21) -> 0 | R21: =SUM(P21:Q21) -> 0 | U21: =SUM(S21:T21) -> 0
B22: =B21+1 -> 10 | F22: =SUM(D22:E22) -> 0 | I22: =SUM(G22:H22) -> 0 | L22: =SUM(J22:K22) -> 0 | O22: =SUM(M22:N22) -> 0 | R22: =SUM(P22:Q22) -> 0 | U22: =SUM(S22:T22) -> 0
B23: =B22+1 -> 11 | F23: =SUM(D23:E23) -> 0 | I23: =SUM(G23:H23) -> 0 | L23: =SUM(J23:K23) -> 0 | O23: =SUM(M23:N23) -> 0 | R23: =SUM(P23:Q23) -> 0 | U23: =SUM(S23:T23) -> 0
B24: =B23+1 -> 12 | F24: =SUM(D24:E24) -> 0 | I24: =SUM(G24:H24) -> 0 | L24: =SUM(J24:K24) -> 0 | O24: =SUM(M24:N24) -> 0 | R24: =SUM(P24:Q24) -> 0 | U24: =SUM(S24:T24) -> 0
B25: =B24+1 -> 13 | F25: =SUM(D25:E25) -> 0 | I25: =SUM(G25:H25) -> 0 | L25: =SUM(J25:K25) -> 0 | O25: =SUM(M25:N25) -> 0 | R25: =SUM(P25:Q25) -> 0 | U25: =SUM(S25:T25) -> 0
... B32: =B31+1 -> 20 | F32: =SUM(D32:E32) -> 0 | I32: =SUM(G32:H32) -> 0 | L32: =SUM(J32:K32) -> 0 | O32: =SUM(M32:N32) -> 0 | R32: =SUM(P32:Q32) -> 0 | U32: =SUM(S32:T32) -> 0
C33: TOTAL | D33: =SUM(D13:D32) -> 0 | E33: =SUM(E13:E32) -> 0 | F33: =D33+E33 -> 0 | G33: =SUM(G13:G32) -> 0 | H33: =SUM(H13:H32) -> 0 | I33: =G33+H33 -> 0 | J33: =SUM(J13:J32) -> 0 | K33: =SUM(K13:K32) -> 0 | L33: =J33+K33 -> 0 | M33: =SUM(M13:M32) -> 0 | N33: =SUM(N13:N32) -> 0 | O33: =M33+N33 -> 0 | P33: =SUM(P13:P32) -> 0 | Q33: =SUM(Q13:Q32) -> 0 | R33: =P33+Q33 -> 0 | S33: =SUM(S13:S32) -> 0 | T33: =SUM(T13:T32) -> 0 | U33: =S33+T33 -> 0

Sheet El._inmovilizado (INVERSIÓN)
B4: 2.3 INVERSIÓN EN ELEMENTOS DE INMOVILIZADO MATERIAL E INTANGIBLE
B6: - Para anualidades no finalizadas en la fecha de la entrega del documento, si aún no se conocen los datos específicos de un elemento de inmovilizado, en el campo "Inversión" se reflejarán los trabajos/actividades principales para los que va a ser empleado.
B8: - Por cada uno de los elementos de inmovilizado, se cumplimentará su correspondiente Ficha de ampliación del apartado 2.3.
B11: Código Elemento | C11: Inversión en Elementos de Inmovilizado Material e Intangible (Concepto específico detallado) | D11: =Personal!F13 -> 2021 | G11: =D11+1 -> 2022 | J11: =G11+1 -> 2023 | M11: =J11+1 -> 2024 | P11: =M11+1 -> 2025 | S11: =P11+1 -> 2026
B12: Código Recurso | D12: Coste/Gasto I+D | E12: Coste/Gasto IT | F12: Coste/Gasto TOTAL | G12: Coste/Gasto I+D | H12: Coste/Gasto IT | I12: Coste/Gasto TOTAL | J12: Coste/Gasto I+D | K12: Coste/Gasto IT | L12: Coste/Gasto TOTAL | M12: Coste/Gasto I+D | N12: Coste/Gasto IT | O12: Coste/Gasto TOTAL | P12: Coste/Gasto I+D | Q12: Coste/Gasto IT | R12: Coste/Gasto TOTAL | S12: Coste/Gasto I+D | T12: Coste/Gasto IT | U12: Coste/Gasto TOTAL
B13: 1 | F13: =SUM(D13:E13) -> 0 | I13: =SUM(G13:H13) -> 0 | L13: =SUM(J13:K13) -> 0 | O13: =SUM(M13:N13) -> 0 | R13: =SUM(P13:Q13) -> 0 | U13: =SUM(S13:T13) -> 0
B14: =B13+1 -> 2 | F14: =SUM(D14:E14) -> 0 | I14: =SUM(G14:H14) -> 0 | L14: =SUM(J14:K14) -> 0 | O14: =SUM(M14:N14) -> 0 | R14: =SUM(P14:Q14) -> 0 | U14: =SUM(S14:T14) -> 0
B15: =B14+1 -> 3 | F15: =SUM(D15:E15) -> 0 | I15: =SUM(G15:H15) -> 0 | L15: =SUM(J15:K15) -> 0 | O15: =SUM(M15:N15) -> 0 | R15: =SUM(P15:Q15) -> 0 | U15: =SUM(S15:T15) -> 0
B16: =B15+1 -> 4 | F16: =SUM(D16:E16) -> 0 | I16: =SUM(G16:H16) -> 0 | L16: =SUM(J16:K16) -> 0 | O16: =SUM(M16:N16) -> 0 | R16: =SUM(P16:Q16) -> 0 | U16: =SUM(S16:T16) -> 0
B17: =B16+1 -> 5 | F17: =SUM(D17:E17) -> 0 | I17: =SUM(G17:H17) -> 0 | L17: =SUM(J17:K17) -> 0 | O17: =SUM(M17:N17) -> 0 | R17: =SUM(P17:Q17) -> 0 | U17: =SUM(S17:T17) -> 0
B18: =B17+1 -> 6 | F18: =SUM(D18:E18) -> 0 | I18: =SUM(G18:H18) -> 0 | L18: =SUM(J18:K18) -> 0 | O18: =SUM(M18:N18) -> 0 | R18: =SUM(P18:Q18) -> 0 | U18: =SUM(S18:T18) -> 0
B19: =B18+1 -> 7 | F19: =SUM(D19:E19) -> 0 | I19: =SUM(G19:H19) -> 0 | L19: =SUM(J19:K19) -> 0 | O19: =SUM(M19:N19) -> 0 | R19: =SUM(P19:Q19) -> 0 | U19: =SUM(S19:T19) -> 0
B20: =B19+1 -> 8 | F20: =SUM(D20:E20) -> 0 | I20: =SUM(G20:H20) -> 0 | L20: =SUM(J20:K20) -> 0 | O20: =SUM(M20:N20) -> 0 | R20: =SUM(P20:Q20) -> 0 | U20: =SUM(S20:T20) -> 0
B21: =B20+1 -> 9 | F21: =SUM(D21:E21) -> 0 | I21: =SUM(G21:H21) -> 0 | L21: =SUM(J21:K21) -> 0 | O21: =SUM(M21:N21) -> 0 | R21: =SUM(P21:Q21) -> 0 | U21: =SUM(S21:T21) -> 0
B22: =B21+1 -> 10 | F22: =SUM(D22:E22) -> 0 | I22: =SUM(G22:H22) -> 0 | L22: =SUM(J22:K22) -> 0 | O22: =SUM(M22:N22) -> 0 | R22: =SUM(P22:Q22) -> 0 | U22: =SUM(S22:T22) -> 0
B23: =B22+1 -> 11 | F23: =SUM(D23:E23) -> 0 | I23: =SUM(G23:H23) -> 0 | L23: =SUM(J23:K23) -> 0 | O23: =SUM(M23:N23) -> 0 | R23: =SUM(P23:Q23) -> 0 | U23: =SUM(S23:T23) -> 0
B24: =B23+1 -> 12 | F24: =SUM(D24:E24) -> 0 | I24: =SUM(G24:H24) -> 0 | L24: =SUM(J24:K24) -> 0 | O24: =SUM(M24:N24) -> 0 | R24: =SUM(P24:Q24) -> 0 | U24: =SUM(S24:T24) -> 0
B25: =B24+1 -> 13 | F25: =SUM(D25:E25) -> 0 | I25: =SUM(G25:H25) -> 0 | L25: =SUM(J25:K25) -> 0 | O25: =SUM(M25:N25) -> 0 | R25: =SUM(P25:Q25) -> 0 | U25: =SUM(S25:T25) -> 0
... B32: =B31+1 -> 20 | F32: =SUM(D32:E32) -> 0 | I32: =SUM(G32:H32) -> 0 | L32: =SUM(J32:K32) -> 0 | O32: =SUM(M32:N32) -> 0 | R32: =SUM(P32:Q32) -> 0 | U32: =SUM(S32:T32) -> 0
C33: TOTAL | D33: =SUM(D13:D32) -> 0 | F33: =D33+E33 -> 0 | G33: =SUM(G13:G32) -> 0 | I33: =G33+H33 -> 0 | J33: =SUM(J13:J32) -> 0 | L33: =J33+K33 -> 0 | M33: =SUM(M13:M32) -> 0 | O33: =M33+N33 -> 0 | P33: =SUM(P13:P32) -> 0 | R33: =P33+Q33 -> 0 | S33: =SUM(S13:S32) -> 0 | U33: =S33+T33 -> 0

Sheet Fungibles
B4: 2.4 MATERIAL FUNGIBLE
B6: - Para anualidades no finalizadas en la fecha de la entrega del documento, si aún no se conocen los datos específicos de un material, en el campo "Material fungible" se reflejarán los trabajos/actividades principales para los que va a ser empleado.
B8: - Por cada una de las partidas correspondientes a un mismo proveedor o un concepto, cuya suma sea superior a 30.000 €, se cumplimentará/n su/s correspondiente/s Ficha/s de ampliación del apartado 2.4.
B11: Código Fungible | C11: Material Fungible (Concepto específico detallado) | D11: =Personal!F13 -> 2021 | G11: =D11+1 -> 2022 | J11: =G11+1 -> 2023 | M11: =J11+1 -> 2024 | P11: =M11+1 -> 2025 | S11: =P11+1 -> 2026
D12: Coste/Gasto I+D | E12: Coste/Gasto IT | F12: Coste/Gasto TOTAL | G12: Coste/Gasto I+D | H12: Coste/Gasto IT | I12: Coste/Gasto TOTAL | J12: Coste/Gasto I+D | K12: Coste/Gasto IT | L12: Coste/Gasto TOTAL | M12: Coste/Gasto I+D | N12: Coste/Gasto IT | O12: Coste/Gasto TOTAL | P12: Coste/Gasto I+D | Q12: Coste/Gasto IT | R12: Coste/Gasto TOTAL | S12: Coste/Gasto I+D | T12: Coste/Gasto IT | U12: Coste/Gasto TOTAL
B13: 1 | F13: =SUM(D13:E13) -> 0 | I13: =SUM(G13:H13) -> 0 | L13: =SUM(J13:K13) -> 0 | O13: =SUM(M13:N13) -> 0 | R13: =SUM(P13:Q13) -> 0 | U13: =SUM(S13:T13) -> 0
B14: =B13+1 -> 2 | F14: =SUM(D14:E14) -> 0 | I14: =SUM(G14:H14) -> 0 | L14: =SUM(J14:K14) -> 0 | O14: =SUM(M14:N14) -> 0 | R14: =SUM(P14:Q14) -> 0 | U14: =SUM(S14:T14) -> 0
B15: =B14+1 -> 3 | F15: =SUM(D15:E15) -> 0 | I15: =SUM(G15:H15) -> 0 | L15: =SUM(J15:K15) -> 0 | O15: =SUM(M15:N15) -> 0 | R15: =SUM(P15:Q15) -> 0 | U15: =SUM(S15:T15) -> 0
B16: =B15+1 -> 4 | F16: =SUM(D16:E16) -> 0 | I16: =SUM(G16:H16) -> 0 | L16: =SUM(J16:K16) -> 0 | O16: =SUM(M16:N16) -> 0 | R16: =SUM(P16:Q16) -> 0 | U16: =SUM(S16:T16) -> 0
B17: =B16+1 -> 5 | F17: =SUM(D17:E17) -> 0 | I17: =SUM(G17:H17) -> 0 | L17: =SUM(J17:K17) -> 0 | O17: =SUM(M17:N17) -> 0 | R17: =SUM(P17:Q17) -> 0 | U17: =SUM(S17:T17) -> 0
B18: =B17+1 -> 6 | F18: =SUM(D18:E18) -> 0 | I18: =SUM(G18:H18) -> 0 | L18: =SUM(J18:K18) -> 0 | O18: =SUM(M18:N18) -> 0 | R18: =SUM(P18:Q18) -> 0 | U18: =SUM(S18:T18) -> 0
B19: =B18+1 -> 7 | F19: =SUM(D19:E19) -> 0 | I19: =SUM(G19:H19) -> 0 | L19: =SUM(J19:K19) -> 0 | O19: =SUM(M19:N19) -> 0 | R19: =SUM(P19:Q19) -> 0 | U19: =SUM(S19:T19) -> 0
B20: =B19+1 -> 8 | F20: =SUM(D20:E20) -> 0 | I20: =SUM(G20:H20) -> 0 | L20: =SUM(J20:K20) -> 0 | O20: =SUM(M20:N20) -> 0 | R20: =SUM(P20:Q20) -> 0 | U20: =SUM(S20:T20) -> 0
B21: =B20+1 -> 9 | F21: =SUM(D21:E21) -> 0 | I21: =SUM(G21:H21) -> 0 | L21: =SUM(J21:K21) -> 0 | O21: =SUM(M21:N21) -> 0 | R21: =SUM(P21:Q21) -> 0 | U21: =SUM(S21:T21) -> 0
B22: =B21+1 -> 10 | F22: =SUM(D22:E22) -> 0 | I22: =SUM(G22:H22) -> 0 | L22: =SUM(J22:K22) -> 0 | O22: =SUM(M22:N22) -> 0 | R22: =SUM(P22:Q22) -> 0 | U22: =SUM(S22:T22) -> 0
B23: =B22+1 -> 11 | F23: =SUM(D23:E23) -> 0 | I23: =SUM(G23:H23) -> 0 | L23: =SUM(J23:K23) -> 0 | O23: =SUM(M23:N23) -> 0 | R23: =SUM(P23:Q23) -> 0 | U23: =SUM(S23:T23) -> 0
B24: =B23+1 -> 12 | F24: =SUM(D24:E24) -> 0 | I24: =SUM(G24:H24) -> 0 | L24: =SUM(J24:K24) -> 0 | O24: =SUM(M24:N24) -> 0 | R24: =SUM(P24:Q24) -> 0 | U24: =SUM(S24:T24) -> 0
B25: =B24+1 -> 13 | F25: =SUM(D25:E25) -> 0 | I25: =SUM(G25:H25) -> 0 | L25: =SUM(J25:K25) -> 0 | O25: =SUM(M25:N25) -> 0 | R25: =SUM(P25:Q25) -> 0 | U25: =SUM(S25:T25) -> 0
... B32: =B31+1 -> 20 | F32: =SUM(D32:E32) -> 0 | I32: =SUM(G32:H32) -> 0 | L32: =SUM(J32:K32) -> 0 | O32: =SUM(M32:N32) -> 0 | R32: =SUM(P32:Q32) -> 0 | U32: =SUM(S32:T32) -> 0
C33: TOTAL | D33: =SUM(D13:D32) -> 0 | E33: =SUM(E13:E32) -> 0 | F33: =D33+E33 -> 0 | G33: =SUM(G13:G32) -> 0 | H33: =SUM(H13:H32) -> 0 | I33: =G33+H33 -> 0 | J33: =SUM(J13:J32) -> 0 | K33: =SUM(K13:K32) -> 0 | L33: =J33+K33 -> 0 | M33: =SUM(M13:M32) -> 0 | N33: =SUM(N13:N32) -> 0 | O33: =M33+N33 -> 0 | P33: =SUM(P13:P32) -> 0 | Q33: =SUM(Q13:Q32) -> 0 | R33: =P33+Q33 -> 0 | S33: =SUM(S13:S32) -> 0 | T33: =SUM(T13:T32) -> 0 | U33: =S33+T33 -> 0

Sheet Otros Gastos
B4: 2.5 OTROS GASTOS
B6: - Para anualidades no finalizadas en la fecha de la entrega del documento, si aún no se conocen los datos específicos de un elemento considerado como “otros gastos”, en el campo "Otros gastos" se reflejarán los trabajos/actividades principales para los que va a ser empleado.
B8: - Dentro de la partida de “Otros gastos” solo se pueden incluir aquellos conceptos que por su naturaleza NO puedan ser encuadrados en ninguna de las partidas restantes habilitadas. No es admisible consignar en esta partida costes de conceptos que puedan ser atribuibles a otras partidas.
B10: - Para cada uno de los conceptos recogidos, que superen en una cuantía del 5% a la suma total del gasto de personal, o que sumados los de un mismo proveedor o modalidad superen dicha cuantía, se cumplimentará la Ficha de ampliación del apartado 2.5.
B13: Código Otros | C13: Otros Gastos (Concepto específico detallado) | D13: =Personal!F13 -> 2021 | G13: =D13+1 -> 2022 | J13: =G13+1 -> 2023 | M13: =J13+1 -> 2024 | P13: =M13+1 -> 2025 | S13: =P13+1 -> 2026
B14: Código Recurso | D14: Coste/Gasto I+D | E14: Coste/Gasto IT | F14: Coste/Gasto TOTAL | G14: Coste/Gasto I+D | H14: Coste/Gasto IT | I14: Coste/Gasto TOTAL | J14: Coste/Gasto I+D | K14: Coste/Gasto IT | L14: Coste/Gasto TOTAL | M14: Coste/Gasto I+D | N14: Coste/Gasto IT | O14: Coste/Gasto TOTAL | P14: Coste/Gasto I+D | Q14: Coste/Gasto IT | R14: Coste/Gasto TOTAL | S14: Coste/Gasto I+D | T14: Coste/Gasto IT | U14: Coste/Gasto TOTAL
B15: 1 | F15: =SUM(D15:E15) -> 0 | I15: =SUM(G15:H15) -> 0 | L15: =SUM(J15:K15) -> 0 | O15: =SUM(M15:N15) -> 0 | R15: =SUM(P15:Q15) -> 0 | U15: =SUM(S15:T15) -> 0
B16: =B15+1 -> 2 | F16: =SUM(D16:E16) -> 0 | I16: =SUM(G16:H16) -> 0 | L16: =SUM(J16:K16) -> 0 | O16: =SUM(M16:N16) -> 0 | R16: =SUM(P16:Q16) -> 0 | U16: =SUM(S16:T16) -> 0
B17: =B16+1 -> 3 | F17: =SUM(D17:E17) -> 0 | I17: =SUM(G17:H17) -> 0 | L17: =SUM(J17:K17) -> 0 | O17: =SUM(M17:N17) -> 0 | R17: =SUM(P17:Q17) -> 0 | U17: =SUM(S17:T17) -> 0
B18: =B17+1 -> 4 | F18: =SUM(D18:E18) -> 0 | I18: =SUM(G18:H18) -> 0 | L18: =SUM(J18:K18) -> 0 | O18: =SUM(M18:N18) -> 0 | R18: =SUM(P18:Q18) -> 0 | U18: =SUM(S18:T18) -> 0
B19: =B18+1 -> 5 | F19: =SUM(D19:E19) -> 0 | I19: =SUM(G19:H19) -> 0 | L19: =SUM(J19:K19) -> 0 | O19: =SUM(M19:N19) -> 0 | R19: =SUM(P19:Q19) -> 0 | U19: =SUM(S19:T19) -> 0
B20: =B19+1 -> 6 | F20: =SUM(D20:E20) -> 0 | I20: =SUM(G20:H20) -> 0 | L20: =SUM(J20:K20) -> 0 | O20: =SUM(M20:N20) -> 0 | R20: =SUM(P20:Q20) -> 0 | U20: =SUM(S20:T20) -> 0
B21: =B20+1 -> 7 | F21: =SUM(D21:E21) -> 0 | I21: =SUM(G21:H21) -> 0 | L21: =SUM(J21:K21) -> 0 | O21: =SUM(M21:N21) -> 0 | R21: =SUM(P21:Q21) -> 0 | U21: =SUM(S21:T21) -> 0
B22: =B21+1 -> 8 | F22: =SUM(D22:E22) -> 0 | I22: =SUM(G22:H22) -> 0 | L22: =SUM(J22:K22) -> 0 | O22: =SUM(M22:N22) -> 0 | R22: =SUM(P22:Q22) -> 0 | U22: =SUM(S22:T22) -> 0
B23: =B22+1 -> 9 | F23: =SUM(D23:E23) -> 0 | I23: =SUM(G23:H23) -> 0 | L23: =SUM(J23:K23) -> 0 | O23: =SUM(M23:N23) -> 0 | R23: =SUM(P23:Q23) -> 0 | U23: =SUM(S23:T23) -> 0
B24: =B23+1 -> 10 | F24: =SUM(D24:E24) -> 0 | I24: =SUM(G24:H24) -> 0 | L24: =SUM(J24:K24) -> 0 | O24: =SUM(M24:N24) -> 0 | R24: =SUM(P24:Q24) -> 0 | U24: =SUM(S24:T24) -> 0
B25: =B24+1 -> 11 | F25: =SUM(D25:E25) -> 0 | I25: =SUM(G25:H25) -> 0 | L25: =SUM(J25:K25) -> 0 | O25: =SUM(M25:N25) -> 0 | R25: =SUM(P25:Q25) -> 0 | U25: =SUM(S25:T25) -> 0
B26: =B25+1 -> 12 | F26: =SUM(D26:E26) -> 0 | I26: =SUM(G26:H26) -> 0 | L26: =SUM(J26:K26) -> 0 | O26: =SUM(M26:N26) -> 0 | R26: =SUM(P26:Q26) -> 0 | U26: =SUM(S26:T26) -> 0
B27: =B26+1 -> 13 | F27: =SUM(D27:E27) -> 0 | I27: =SUM(G27:H27) -> 0 | L27: =SUM(J27:K27) -> 0 | O27: =SUM(M27:N27) -> 0 | R27: =SUM(P27:Q27) -> 0 | U27: =SUM(S27:T27) -> 0
... B34: =B33+1 -> 20 | F34: =SUM(D34:E34) -> 0 | I34: =SUM(G34:H34) -> 0 | L34: =SUM(J34:K34) -> 0 | O34: =SUM(M34:N34) -> 0 | R34: =SUM(P34:Q34) -> 0 | U34: =SUM(S34:T34) -> 0
C35: TOTAL | D35: =SUM(D15:D34) -> 0 | E35: =SUM(E15:E34) -> 0 | F35: =D35+E35 -> 0 | G35: =SUM(G15:G34) -> 0 | H35: =SUM(H15:H34) -> 0 | I35: =G35+H35 -> 0 | J35: =SUM(J15:J34) -> 0 | K35: =SUM(K15:K34) -> 0 | L35: =J35+K35 -> 0 | M35: =SUM(M15:M34) -> 0 | N35: =SUM(N15:N34) -> 0 | O35: =M35+N35 -> 0 | P35: =SUM(P15:P34) -> 0 | Q35: =SUM(Q15:Q34) -> 0 | R35: =P35+Q35 -> 0 | S35: =SUM(S15:S34) -> 0 | T35: =SUM(T15:T34) -> 0 | U35: =S35+T35 -> 0

Sheet I+D
B4: PRESUPUESTO EN INVESTIGACIÓN Y DESARROLLO DEL PROYECTO
B7: PRESUPUESTO EN INVESTIGACIÓN Y DESARROLLO DEL PROYECTO (en Euros)
B8: EJERCICIO FISCAL | D8: =Personal!F13 -> 2021 | E8: =D8+1 -> 2022 | F8: =E8+1 -> 2023 | G8: =F8+1 -> 2024 | H8: =G8+1 -> 2025 | I8: =H8+1 -> 2026
B9: Personal aplicado a actividades de I+D+i | D9: =Personal!G35 -> 0 | E9: =Personal!L35 -> 0 | F9: =Personal!Q35 -> 0 | G9: =Personal!V35 -> 0 | H9: =Personal!AA35 -> 0 | I9: =Personal!AF35 -> 0
B10: Personal investigador cualificado de adscripción exclusiva (sólo proyectos I+D) | D10: =Personal!G36 -> 0 | E10: =Personal!L36 -> 0 | F10: =Personal!Q36 -> 0 | G10: =Personal!V36 -> 0 | H10: =Personal!AA36 -> 0 | I10: =Personal!AF36 -> 0
B11: Amortización de elementos de inmovilizado material e intangible | D11: ='El._inmovilizado (AMORTIZACIÓN)'!D33 -> 0 | E11: ='El._inmovilizado (AMORTIZACIÓN)'!G33 -> 0 | F11: ='El._inmovilizado (AMORTIZACIÓN)'!J33 -> 0 | G11: ='El._inmovilizado (AMORTIZACIÓN)'!M33 -> 0 | H11: ='El._inmovilizado (AMORTIZACIÓN)'!P33 -> 0 | I11: ='El._inmovilizado (AMORTIZACIÓN)'!S33 -> 0
B12: Material fungible | D12: =Fungibles!D33 -> 0 | E12: =Fungibles!G33 -> 0 | F12: =Fungibles!J33 -> 0 | G12: =Fungibles!M33 -> 0 | H12: =Fungibles!P33 -> 0 | I12: =Fungibles!S33 -> 0
B13: Colaboraciones Externas: Universidades, OPIs y/o CITs | D13: ='C.Externas (OPIS)'!F39 -> 0 | E13: ='C.Externas (OPIS)'!I39 -> 0 | F13: ='C.Externas (OPIS)'!L39 -> 0 | G13: ='C.Externas (OPIS)'!O39 -> 0 | H13: ='C.Externas (OPIS)'!R39 -> 0 | I13: ='C.Externas (OPIS)'!U39 -> 0
B14: Otras colaboraciones externas | D14: ='C.Externas (Otros)'!E34 -> 0 | E14: ='C.Externas (Otros)'!H34 -> 0 | F14: ='C.Externas (Otros)'!K34 -> 0 | G14: ='C.Externas (Otros)'!N34 -> 0 | H14: ='C.Externas (Otros)'!Q34 -> 0 | I14: ='C.Externas (Otros)'!T34 -> 0
B15: Otros gastos | D15: ='Otros Gastos'!D35 -> 0 | E15: ='Otros Gastos'!G35 -> 0 | F15: ='Otros Gastos'!J35 -> 0 | G15: ='Otros Gastos'!M35 -> 0 | H15: ='Otros Gastos'!P35 -> 0 | I15: ='Otros Gastos'!S35 -> 0
B16: TOTAL COSTES / GASTOS | D16: =SUM(D9:D15) -> 0 | E16: =SUM(E9:E15) -> 0 | F16: =SUM(F9:F15) -> 0 | G16: =SUM(G9:G15) -> 0 | H16: =SUM(H9:H15) -> 0 | I16: =SUM(I9:I15) -> 0
B18: TOTAL INVERSIÓN EN ELEMENTOS DE INMOVILIZADO MATERIAL E INTANGIBLE | D18: ='El._inmovilizado (INVERSIÓN)'!D33 -> 0 | E18: ='El._inmovilizado (INVERSIÓN)'!G33 -> 0 | F18: ='El._inmovilizado (INVERSIÓN)'!J33 -> 0 | G18: ='El._inmovilizado (INVERSIÓN)'!M33 -> 0 | H18: ='El._inmovilizado (INVERSIÓN)'!P33 -> 0 | I18: ='El._inmovilizado (INVERSIÓN)'!S33 -> 0

Sheet iT
B4: PRESUPUESTO EN INNOVACIÓN TECNOLÓGICA DEL PROYECTO
B7: PRESUPUESTO EN INNOVACIÓN TECNOLÓGICA DEL PROYECTO (en Euros)
B8: EJERCICIO FISCAL | D8: =Personal!F13 -> 2021 | E8: =D8+1 -> 2022 | F8: =E8+1 -> 2023 | G8: =F8+1 -> 2024 | H8: =G8+1 -> 2025 | I8: =H8+1 -> 2026
B9: Personal aplicado a actividades de I+D+i | D9: =Personal!I35 -> 95704.36 | E9: =Personal!N35 -> 254987.21 | F9: =Personal!S35 -> 0 | G9: =Personal!X35 -> 0 | H9: =Personal!AC35 -> 0 | I9: =Personal!AH35 -> 0
B10: Personal investigador cualificado de adscripción exclusiva (sólo proyectos I+D)
B11: Amortización de elementos de inmovilizado material e intangible | D11: ='El._inmovilizado (AMORTIZACIÓN)'!E33 -> 0 | E11: ='El._inmovilizado (AMORTIZACIÓN)'!H33 -> 0 | F11: ='El._inmovilizado (AMORTIZACIÓN)'!K33 -> 0 | G11: ='El._inmovilizado (AMORTIZACIÓN)'!N33 -> 0 | H11: ='El._inmovilizado (AMORTIZACIÓN)'!Q33 -> 0 | I11: ='El._inmovilizado (AMORTIZACIÓN)'!T33 -> 0
B12: Material fungible | D12: =Fungibles!E33 -> 0 | E12: =Fungibles!H33 -> 0 | F12: =Fungibles!K33 -> 0 | G12: =Fungibles!N33 -> 0 | H12: =Fungibles!Q33 -> 0 | I12: =Fungibles!T33 -> 0
B13: Colaboraciones Externas: Universidades, OPIs y/o CITs | D13: ='C.Externas (OPIS)'!G39 -> 0 | E13: ='C.Externas (OPIS)'!J39 -> 0 | F13: ='C.Externas (OPIS)'!M39 -> 0 | G13: ='C.Externas (OPIS)'!P39 -> 0 | H13: ='C.Externas (OPIS)'!S39 -> 0 | I13: ='C.Externas (OPIS)'!V39 -> 0
B14: Otras colaboraciones externas | D14: ='C.Externas (Otros)'!F34 -> 256004.37 | E14: ='C.Externas (Otros)'!I34 -> 1292834.4 | F14: ='C.Externas (Otros)'!L34 -> 0 | G14: ='C.Externas (Otros)'!O34 -> 0 | H14: ='C.Externas (Otros)'!R34 -> 0 | I14: ='C.Externas (Otros)'!U34 -> 0
B15: Otros gastos | D15: ='Otros Gastos'!E35 -> 0 | E15: ='Otros Gastos'!H35 -> 0 | F15: ='Otros Gastos'!K35 -> 0 | G15: ='Otros Gastos'!N35 -> 0 | H15: ='Otros Gastos'!Q35 -> 0 | I15: ='Otros Gastos'!T35 -> 0
B16: TOTAL COSTES / GASTOS | D16: =SUM(D9:D15) -> 351708.73 | E16: =SUM(E9:E15) -> 1547821.6 | F16: =SUM(F9:F15) -> 0 | G16: =SUM(G9:G15) -> 0 | H16: =SUM(H9:H15) -> 0 | I16: =SUM(I9:I15) -> 0

Sheet TOTAL
B4: PRESUPUESTO TOTAL DEL PROYECTO
B7: PRESUPUESTO TOTAL DEL PROYECTO (en Euros)
B9: EJERCICIO FISCAL | D9: =Personal!F13 -> 2021 | E9: =D9+1 -> 2022 | F9: =E9+1 -> 2023 | G9: =F9+1 -> 2024 | H9: =G9+1 -> 2025 | I9: =H9+1 -> 2026
B10: Personal aplicado a actividades de I+D+i | D10: ='I+D'!D9+iT!D9 -> 95704.36 | E10: ='I+D'!E9+iT!E9 -> 254987.21 | F10: ='I+D'!F9+iT!F9 -> 0 | G10: ='I+D'!G9+iT!G9 -> 0 | H10: ='I+D'!H9+iT!H9 -> 0 | I10: ='I+D'!I9+iT!I9 -> 0
B11: Personal investigador cualificado de adscripción exclusiva (sólo proyectos I+D) | D11: ='I+D'!D10+iT!D10 -> 0 | E11: ='I+D'!E10+iT!E10 -> 0 | F11: ='I+D'!F10+iT!F10 -> 0 | G11: ='I+D'!G10+iT!G10 -> 0 | H11: ='I+D'!H10+iT!H10 -> 0 | I11: ='I+D'!I10+iT!I10 -> 0
B12: Amortización de elementos de inmovilizado material e intangible | D12: ='I+D'!D11+iT!D11 -> 0 | E12: ='I+D'!E11+iT!E11 -> 0 | F12: ='I+D'!F11+iT!F11 -> 0 | G12: ='I+D'!G11+iT!G11 -> 0 | H12: ='I+D'!H11+iT!H11 -> 0 | I12: ='I+D'!I11+iT!I11 -> 0
B13: Material fungible | D13: ='I+D'!D12+iT!D12 -> 0 | E13: ='I+D'!E12+iT!E12 -> 0 | F13: ='I+D'!F12+iT!F12 -> 0 | G13: ='I+D'!G12+iT!G12 -> 0 | H13: ='I+D'!H12+iT!H12 -> 0 | I13: ='I+D'!I12+iT!I12 -> 0
B14: Colaboraciones Externas: Universidades, OPIs y/o CITs | D14: ='I+D'!D13+iT!D13 -> 0 | E14: ='I+D'!E13+iT!E13 -> 0 | F14: ='I+D'!F13+iT!F13 -> 0 | G14: ='I+D'!G13+iT!G13 -> 0 | H14: ='I+D'!H13+iT!H13 -> 0 | I14: ='I+D'!I13+iT!I13 -> 0
B15: Otras colaboraciones externas | D15: ='I+D'!D14+iT!D14 -> 256004.37 | E15: ='I+D'!E14+iT!E14 -> 1292834.4 | F15: ='I+D'!F14+iT!F14 -> 0 | G15: ='I+D'!G14+iT!G14 -> 0 | H15: ='I+D'!H14+iT!H14 -> 0 | I15: ='I+D'!I14+iT!I14 -> 0
B16: Otros gastos | D16: ='I+D'!D15+iT!D15 -> 0 | E16: ='I+D'!E15+iT!E15 -> 0 | F16: ='I+D'!F15+iT!F15 -> 0 | G16: ='I+D'!G15+iT!G15 -> 0 | H16: ='I+D'!H15+iT!H15 -> 0 | I16: ='I+D'!I15+iT!I15 -> 0
B17: TOTAL COSTES / GASTOS | D17: =SUM(D10:D16) -> 351708.73 | E17: =SUM(E10:E16) -> 1547821.6 | F17: =SUM(F10:F16) -> 0 | G17: =SUM(G10:G16) -> 0 | H17: =SUM(H10:H16) -> 0 | I17: =SUM(I10:I16) -> 0
B19: TOTAL INVERSIÓN EN ELEMENTOS DE INMOVILIZADO MATERIAL E INTANGIBLE | D19: ='El._inmovilizado (INVERSIÓN)'!D33 -> 0 | E19: ='El._inmovilizado (INVERSIÓN)'!G33 -> 0 | F19: ='El._inmovilizado (INVERSIÓN)'!J33 -> 0 | G19: ='El._inmovilizado (INVERSIÓN)'!M33 -> 0 | H19: ='El._inmovilizado (INVERSIÓN)'!P33 -> 0 | I19: ='El._inmovilizado (INVERSIÓN)'!S33 -> 0

Sheet DESVIACIONES
A3: FICHA DE DESVIACIONES (sólo en caso de solicitud de informe del tipo a)
A5: ENUMERACIÓN DE LAS DESVIACIONES SUPERIORES AL 20% DEL PRESUPUESTO DEL PROYECTO:
A7: Nº | B7: CONCEPTO | C7: IDENTIFICACIÓN | D7: Presupuesto de Proyecto | G7: Efectivamente Incurrido | J7: Porcentaje
B8: (Personal, Colaboraciones, etc.) | C8: (Nombre de la persona, entidad, material, etc.) | D8: Coste/Gasto I+D | E8: Coste/Gasto IT | F8: Coste/Gasto total | G8: Coste/Gasto I+D | H8: Coste/Gasto IT | I8: Coste/Gasto total | J8: (%)
A9: 1 | B9: Personal aplicado a actividades de I+D+i | F9: =SUM(D9:E9) -> 0 | I9: =SUM(G9:H9) -> 0 | J9: =IF(F9=0,"",(I9-F9)/F9*100)
A10: 2 | B10: Personal investigador cualificado y en exclusiva a I+D | F10: =SUM(D10:E10) -> 0 | I10: =SUM(G10:H10) -> 0 | J10: =IF(F10=0,"",(I10-F10)/F10*100)
A11: 3 | B11: Amortización de elementos de inmovilizado material e Intangible | F11: =SUM(D11:E11) -> 0 | I11: =SUM(G11:H11) -> 0 | J11: =IF(F11=0,"",(I11-F11)/F11*100)
A12: 4 | B12: Material fungible | F12: =SUM(D12:E12) -> 0 | I12: =SUM(G12:H12) -> 0 | J12: =IF(F12=0,"",(I12-F12)/F12*100)
A13: 5 | B13: Colaboraciones Externas: Universidades, OPIs y/o CITs | F13: =SUM(D13:E13) -> 0 | I13: =SUM(G13:H13) -> 0 | J13: =IF(F13=0,"",(I13-F13)/F13*100)
A14: 6 | B14: Otras colaboraciones externas | F14: =SUM(D14:E14) -> 0 | I14: =SUM(G14:H14) -> 0 | J14: =IF(F14=0,"",(I14-F14)/F14*100)
A15: 7 | B15: Otros gastos | F15: =SUM(D15:E15) -> 0 | I15: =SUM(G15:H15) -> 0 | J15: =IF(F15=0,"",(I15-F15)/F15*100)
A16: TOTAL | D16: =SUM(D9:D15) -> 0 | E16: =SUM(E9:E15) -> 0 | F16: =SUM(F9:F15) -> 0 | G16: =SUM(G9:G15) -> 0 | H16: =SUM(H9:H15) -> 0 | I16: =SUM(I9:I15) -> 0 | J16: =IF(F16=0,"",(I16-F16)/F16*100)

Sheet DOC JUSTIFICATIVOS
C3: LISTADO DE LOS DOCUMENTOS JUSTIFICATIVOS DE LOS GASTOS O COSTES INCURRIDOS EN EL PROYECTO
C5: Nº | E5: NOMBRE | F5: Nº/TIPO DE DOCUMENTO | G5: FECHA | H5: TITULACIÓN | I5: IMPORTE (€)
I6: I+D | J6: IT | K6: TOTAL
C8: Personal aplicado a actividades de I+D+i
C9: 1 | E9: CRISTINA BAYON VALTIERRA | F9: IDC-RNT-CCRR | G9: 44926 | H9: FÍSICAS | J9: 70540.24 | K9: =I9+J9 -> 70540.24
C10: =C9+1 -> 2 | E10: DAVID GARRIDO ANDRES | F10: IDC-RNT-CCRR | G10: 44926 | H10: INFORMÁTICA | J10: 60242.99 | K10: =I10+J10 -> 60242.99
C11: =C10+1 -> 3 | E11: MARIA LUISA SANTIAGO CHIQUERO | F11: IDC-RNT-CCRR | G11: 44926 | H11: MATEMÁTICAS | J11: 58665.38 | K11: =I11+J11 -> 58665.38
C12: =C11+1 -> 4 | E12: SILVIA VAZQUEZ INSAUSTI | F12: IDC-RNT-CCRR | G12: 44926 | H12: MATEMÁTICAS | J12: 65538.6 | K12: =I12+J12 -> 65538.6
C13: =C12+1 -> 5 | K13: =I13+J13 -> 0
C14: =C13+1 -> 6 | K14: =I14+J14 -> 0
C15: =C14+1 -> 7 | K15: =I15+J15 -> 0
C16: =C15+1 -> 8 | K16: =I16+J16 -> 0
C17: =C16+1 -> 9 | K17: =I17+J17 -> 0
C18: =C17+1 -> 10 | K18: =I18+J18 -> 0
C19: Total | I19: =SUM(I9:I18) -> 0 | J19: =SUM(J9:J18) -> 254987.21 | K19: =SUM(K9:K18) -> 254987.21
C21: Personal Investigador cualificado y aplicado en exclusiva a actividades de I+D
C22: 1 | K22: =I22 -> 0
C23: =C22+1 -> 2 | K23: =I23 -> 0
C24: =C23+1 -> 3 | K24: =I24 -> 0
C25: =C24+1 -> 4 | K25: =I25 -> 0
C26: =C25+1 -> 5 | K26: =I26 -> 0
C27: =C26+1 -> 6 | K27: =I27 -> 0
C28: =C27+1 -> 7 | K28: =I28 -> 0
C29: =C28+1 -> 8 | K29: =I29 -> 0
C30: =C29+1 -> 9 | K30: =I30 -> 0
C31: =C30+1 -> 10 | K31: =I31 -> 0
C32: Total | I32: =SUM(I22:I31) -> 0 | K32: =SUM(K22:K31) -> 0
C34: Nº | E34: ORIGEN/PROVEEDOR | F34: Nº DOC./FACTURA | G34: FECHA | H34: CONCEPTO | I34: IMPORTE (€)
I35: I+D | J35: IT | K35: TOTAL
C37: Amortización de elementos de inmovilizado material e intangible
C38: 1 | K38: =I38+J38 -> 0
C39: =C38+1 -> 2 | K39: =I39+J39 -> 0
C40: =C39+1 -> 3 | K40: =I40+J40 -> 0
C41: =C40+1 -> 4 | K41: =I41+J41 -> 0
C42: =C41+1 -> 5 | K42: =I42+J42 -> 0
C43: =C42+1 -> 6 | K43: =I43+J43 -> 0
C44: =C43+1 -> 7 | K44: =I44+J44 -> 0
C45: =C44+1 -> 8 | K45: =I45+J45 -> 0
C46: =C45+1 -> 9 | K46: =I46+J46 -> 0
C47: =C46+1 -> 10 | K47: =I47+J47 -> 0
...
